[2016-11-13 19:24:23] DEBUG [django.db.backends:89] (0.017) 
            SELECT name, type FROM sqlite_master
            WHERE type in ('table', 'view') AND NOT name='sqlite_sequence'
            ORDER BY name; args=None
[2016-11-13 19:24:23] DEBUG [django.db.backends:89] (0.000) SELECT "django_migrations"."app", "django_migrations"."name" FROM "django_migrations"; args=()
[2016-11-13 19:24:25] WARNING [django.request:182] Not Found: /
[2016-11-13 19:24:25] DEBUG [django.template:927] Exception while resolving variable 'name' in template 'unknown'.
Traceback (most recent call last):
  File "C:\Python\Python35\lib\site-packages\django\core\handlers\base.py", line 134, in get_response
    resolver_match = resolver.resolve(request.path_info)
  File "C:\Python\Python35\lib\site-packages\django\core\urlresolvers.py", line 404, in resolve
    raise Resolver404({'tried': tried, 'path': new_path})
django.core.urlresolvers.Resolver404: {'tried': [[<RegexURLResolver <RegexURLPattern list> (admin:admin) ^admin/>], [<RegexURLResolver <module 'django.contrib.admindocs.urls' from 'C:\\Python\\Python35\\lib\\site-packages\\django\\contrib\\admindocs\\urls.py'> (None:None) ^admin/doc/>], [<RegexURLResolver <module 'rest_framework.urls' from 'C:\\Python\\Python35\\lib\\site-packages\\rest_framework\\urls.py'> (rest_framework:rest_framework) ^api-auth/>], [<RegexURLResolver <module 'oauth2_provider.urls' from 'C:\\Python\\Python35\\lib\\site-packages\\oauth2_provider\\urls.py'> (None:oauth2_provider) ^o/>], [<RegexURLResolver <module 'ioteca_service_apps.auths_api.urls' from 'F:\\taller\\initial_ioteca\\ioteca_service\\ioteca_service_apps\\auths_api\\urls.py'> (None:None) ^api/auths/>], [<RegexURLResolver <module 'ioteca_service_apps.catalogo_api.urls' from 'F:\\taller\\initial_ioteca\\ioteca_service\\ioteca_service_apps\\catalogo_api\\urls.py'> (None:None) ^api/catalogo/>], [<RegexURLResolver <module 'ioteca_service_apps.eventos_api.urls' from 'F:\\taller\\initial_ioteca\\ioteca_service\\ioteca_service_apps\\eventos_api\\urls.py'> (None:None) ^api/eventos/>]], 'path': ''}

During handling of the above exception, another exception occurred:

Traceback (most recent call last):
  File "C:\Python\Python35\lib\site-packages\django\template\base.py", line 883, in _resolve_lookup
    current = current[bit]
TypeError: 'RegexURLResolver' object is not subscriptable

During handling of the above exception, another exception occurred:

Traceback (most recent call last):
  File "C:\Python\Python35\lib\site-packages\django\template\base.py", line 891, in _resolve_lookup
    current = getattr(current, bit)
AttributeError: 'RegexURLResolver' object has no attribute 'name'

During handling of the above exception, another exception occurred:

Traceback (most recent call last):
  File "C:\Python\Python35\lib\site-packages\django\template\base.py", line 898, in _resolve_lookup
    current = current[int(bit)]
ValueError: invalid literal for int() with base 10: 'name'

During handling of the above exception, another exception occurred:

Traceback (most recent call last):
  File "C:\Python\Python35\lib\site-packages\django\template\base.py", line 905, in _resolve_lookup
    (bit, current))  # missing attribute
django.template.base.VariableDoesNotExist: Failed lookup for key [name] in '<RegexURLResolver <RegexURLPattern list> (admin:admin) ^admin/>'
[2016-11-13 19:24:25] DEBUG [django.template:927] Exception while resolving variable 'name' in template 'unknown'.
Traceback (most recent call last):
  File "C:\Python\Python35\lib\site-packages\django\core\handlers\base.py", line 134, in get_response
    resolver_match = resolver.resolve(request.path_info)
  File "C:\Python\Python35\lib\site-packages\django\core\urlresolvers.py", line 404, in resolve
    raise Resolver404({'tried': tried, 'path': new_path})
django.core.urlresolvers.Resolver404: {'tried': [[<RegexURLResolver <RegexURLPattern list> (admin:admin) ^admin/>], [<RegexURLResolver <module 'django.contrib.admindocs.urls' from 'C:\\Python\\Python35\\lib\\site-packages\\django\\contrib\\admindocs\\urls.py'> (None:None) ^admin/doc/>], [<RegexURLResolver <module 'rest_framework.urls' from 'C:\\Python\\Python35\\lib\\site-packages\\rest_framework\\urls.py'> (rest_framework:rest_framework) ^api-auth/>], [<RegexURLResolver <module 'oauth2_provider.urls' from 'C:\\Python\\Python35\\lib\\site-packages\\oauth2_provider\\urls.py'> (None:oauth2_provider) ^o/>], [<RegexURLResolver <module 'ioteca_service_apps.auths_api.urls' from 'F:\\taller\\initial_ioteca\\ioteca_service\\ioteca_service_apps\\auths_api\\urls.py'> (None:None) ^api/auths/>], [<RegexURLResolver <module 'ioteca_service_apps.catalogo_api.urls' from 'F:\\taller\\initial_ioteca\\ioteca_service\\ioteca_service_apps\\catalogo_api\\urls.py'> (None:None) ^api/catalogo/>], [<RegexURLResolver <module 'ioteca_service_apps.eventos_api.urls' from 'F:\\taller\\initial_ioteca\\ioteca_service\\ioteca_service_apps\\eventos_api\\urls.py'> (None:None) ^api/eventos/>]], 'path': ''}

During handling of the above exception, another exception occurred:

Traceback (most recent call last):
  File "C:\Python\Python35\lib\site-packages\django\template\base.py", line 883, in _resolve_lookup
    current = current[bit]
TypeError: 'RegexURLResolver' object is not subscriptable

During handling of the above exception, another exception occurred:

Traceback (most recent call last):
  File "C:\Python\Python35\lib\site-packages\django\template\base.py", line 891, in _resolve_lookup
    current = getattr(current, bit)
AttributeError: 'RegexURLResolver' object has no attribute 'name'

During handling of the above exception, another exception occurred:

Traceback (most recent call last):
  File "C:\Python\Python35\lib\site-packages\django\template\base.py", line 898, in _resolve_lookup
    current = current[int(bit)]
ValueError: invalid literal for int() with base 10: 'name'

During handling of the above exception, another exception occurred:

Traceback (most recent call last):
  File "C:\Python\Python35\lib\site-packages\django\template\base.py", line 905, in _resolve_lookup
    (bit, current))  # missing attribute
django.template.base.VariableDoesNotExist: Failed lookup for key [name] in "<RegexURLResolver <module 'django.contrib.admindocs.urls' from 'C:\\\\Python\\\\Python35\\\\lib\\\\site-packages\\\\django\\\\contrib\\\\admindocs\\\\urls.py'> (None:None) ^admin/doc/>"
[2016-11-13 19:24:25] DEBUG [django.template:927] Exception while resolving variable 'name' in template 'unknown'.
Traceback (most recent call last):
  File "C:\Python\Python35\lib\site-packages\django\core\handlers\base.py", line 134, in get_response
    resolver_match = resolver.resolve(request.path_info)
  File "C:\Python\Python35\lib\site-packages\django\core\urlresolvers.py", line 404, in resolve
    raise Resolver404({'tried': tried, 'path': new_path})
django.core.urlresolvers.Resolver404: {'tried': [[<RegexURLResolver <RegexURLPattern list> (admin:admin) ^admin/>], [<RegexURLResolver <module 'django.contrib.admindocs.urls' from 'C:\\Python\\Python35\\lib\\site-packages\\django\\contrib\\admindocs\\urls.py'> (None:None) ^admin/doc/>], [<RegexURLResolver <module 'rest_framework.urls' from 'C:\\Python\\Python35\\lib\\site-packages\\rest_framework\\urls.py'> (rest_framework:rest_framework) ^api-auth/>], [<RegexURLResolver <module 'oauth2_provider.urls' from 'C:\\Python\\Python35\\lib\\site-packages\\oauth2_provider\\urls.py'> (None:oauth2_provider) ^o/>], [<RegexURLResolver <module 'ioteca_service_apps.auths_api.urls' from 'F:\\taller\\initial_ioteca\\ioteca_service\\ioteca_service_apps\\auths_api\\urls.py'> (None:None) ^api/auths/>], [<RegexURLResolver <module 'ioteca_service_apps.catalogo_api.urls' from 'F:\\taller\\initial_ioteca\\ioteca_service\\ioteca_service_apps\\catalogo_api\\urls.py'> (None:None) ^api/catalogo/>], [<RegexURLResolver <module 'ioteca_service_apps.eventos_api.urls' from 'F:\\taller\\initial_ioteca\\ioteca_service\\ioteca_service_apps\\eventos_api\\urls.py'> (None:None) ^api/eventos/>]], 'path': ''}

During handling of the above exception, another exception occurred:

Traceback (most recent call last):
  File "C:\Python\Python35\lib\site-packages\django\template\base.py", line 883, in _resolve_lookup
    current = current[bit]
TypeError: 'RegexURLResolver' object is not subscriptable

During handling of the above exception, another exception occurred:

Traceback (most recent call last):
  File "C:\Python\Python35\lib\site-packages\django\template\base.py", line 891, in _resolve_lookup
    current = getattr(current, bit)
AttributeError: 'RegexURLResolver' object has no attribute 'name'

During handling of the above exception, another exception occurred:

Traceback (most recent call last):
  File "C:\Python\Python35\lib\site-packages\django\template\base.py", line 898, in _resolve_lookup
    current = current[int(bit)]
ValueError: invalid literal for int() with base 10: 'name'

During handling of the above exception, another exception occurred:

Traceback (most recent call last):
  File "C:\Python\Python35\lib\site-packages\django\template\base.py", line 905, in _resolve_lookup
    (bit, current))  # missing attribute
django.template.base.VariableDoesNotExist: Failed lookup for key [name] in "<RegexURLResolver <module 'rest_framework.urls' from 'C:\\\\Python\\\\Python35\\\\lib\\\\site-packages\\\\rest_framework\\\\urls.py'> (rest_framework:rest_framework) ^api-auth/>"
[2016-11-13 19:24:25] DEBUG [django.template:927] Exception while resolving variable 'name' in template 'unknown'.
Traceback (most recent call last):
  File "C:\Python\Python35\lib\site-packages\django\core\handlers\base.py", line 134, in get_response
    resolver_match = resolver.resolve(request.path_info)
  File "C:\Python\Python35\lib\site-packages\django\core\urlresolvers.py", line 404, in resolve
    raise Resolver404({'tried': tried, 'path': new_path})
django.core.urlresolvers.Resolver404: {'tried': [[<RegexURLResolver <RegexURLPattern list> (admin:admin) ^admin/>], [<RegexURLResolver <module 'django.contrib.admindocs.urls' from 'C:\\Python\\Python35\\lib\\site-packages\\django\\contrib\\admindocs\\urls.py'> (None:None) ^admin/doc/>], [<RegexURLResolver <module 'rest_framework.urls' from 'C:\\Python\\Python35\\lib\\site-packages\\rest_framework\\urls.py'> (rest_framework:rest_framework) ^api-auth/>], [<RegexURLResolver <module 'oauth2_provider.urls' from 'C:\\Python\\Python35\\lib\\site-packages\\oauth2_provider\\urls.py'> (None:oauth2_provider) ^o/>], [<RegexURLResolver <module 'ioteca_service_apps.auths_api.urls' from 'F:\\taller\\initial_ioteca\\ioteca_service\\ioteca_service_apps\\auths_api\\urls.py'> (None:None) ^api/auths/>], [<RegexURLResolver <module 'ioteca_service_apps.catalogo_api.urls' from 'F:\\taller\\initial_ioteca\\ioteca_service\\ioteca_service_apps\\catalogo_api\\urls.py'> (None:None) ^api/catalogo/>], [<RegexURLResolver <module 'ioteca_service_apps.eventos_api.urls' from 'F:\\taller\\initial_ioteca\\ioteca_service\\ioteca_service_apps\\eventos_api\\urls.py'> (None:None) ^api/eventos/>]], 'path': ''}

During handling of the above exception, another exception occurred:

Traceback (most recent call last):
  File "C:\Python\Python35\lib\site-packages\django\template\base.py", line 883, in _resolve_lookup
    current = current[bit]
TypeError: 'RegexURLResolver' object is not subscriptable

During handling of the above exception, another exception occurred:

Traceback (most recent call last):
  File "C:\Python\Python35\lib\site-packages\django\template\base.py", line 891, in _resolve_lookup
    current = getattr(current, bit)
AttributeError: 'RegexURLResolver' object has no attribute 'name'

During handling of the above exception, another exception occurred:

Traceback (most recent call last):
  File "C:\Python\Python35\lib\site-packages\django\template\base.py", line 898, in _resolve_lookup
    current = current[int(bit)]
ValueError: invalid literal for int() with base 10: 'name'

During handling of the above exception, another exception occurred:

Traceback (most recent call last):
  File "C:\Python\Python35\lib\site-packages\django\template\base.py", line 905, in _resolve_lookup
    (bit, current))  # missing attribute
django.template.base.VariableDoesNotExist: Failed lookup for key [name] in "<RegexURLResolver <module 'oauth2_provider.urls' from 'C:\\\\Python\\\\Python35\\\\lib\\\\site-packages\\\\oauth2_provider\\\\urls.py'> (None:oauth2_provider) ^o/>"
[2016-11-13 19:24:25] DEBUG [django.template:927] Exception while resolving variable 'name' in template 'unknown'.
Traceback (most recent call last):
  File "C:\Python\Python35\lib\site-packages\django\core\handlers\base.py", line 134, in get_response
    resolver_match = resolver.resolve(request.path_info)
  File "C:\Python\Python35\lib\site-packages\django\core\urlresolvers.py", line 404, in resolve
    raise Resolver404({'tried': tried, 'path': new_path})
django.core.urlresolvers.Resolver404: {'tried': [[<RegexURLResolver <RegexURLPattern list> (admin:admin) ^admin/>], [<RegexURLResolver <module 'django.contrib.admindocs.urls' from 'C:\\Python\\Python35\\lib\\site-packages\\django\\contrib\\admindocs\\urls.py'> (None:None) ^admin/doc/>], [<RegexURLResolver <module 'rest_framework.urls' from 'C:\\Python\\Python35\\lib\\site-packages\\rest_framework\\urls.py'> (rest_framework:rest_framework) ^api-auth/>], [<RegexURLResolver <module 'oauth2_provider.urls' from 'C:\\Python\\Python35\\lib\\site-packages\\oauth2_provider\\urls.py'> (None:oauth2_provider) ^o/>], [<RegexURLResolver <module 'ioteca_service_apps.auths_api.urls' from 'F:\\taller\\initial_ioteca\\ioteca_service\\ioteca_service_apps\\auths_api\\urls.py'> (None:None) ^api/auths/>], [<RegexURLResolver <module 'ioteca_service_apps.catalogo_api.urls' from 'F:\\taller\\initial_ioteca\\ioteca_service\\ioteca_service_apps\\catalogo_api\\urls.py'> (None:None) ^api/catalogo/>], [<RegexURLResolver <module 'ioteca_service_apps.eventos_api.urls' from 'F:\\taller\\initial_ioteca\\ioteca_service\\ioteca_service_apps\\eventos_api\\urls.py'> (None:None) ^api/eventos/>]], 'path': ''}

During handling of the above exception, another exception occurred:

Traceback (most recent call last):
  File "C:\Python\Python35\lib\site-packages\django\template\base.py", line 883, in _resolve_lookup
    current = current[bit]
TypeError: 'RegexURLResolver' object is not subscriptable

During handling of the above exception, another exception occurred:

Traceback (most recent call last):
  File "C:\Python\Python35\lib\site-packages\django\template\base.py", line 891, in _resolve_lookup
    current = getattr(current, bit)
AttributeError: 'RegexURLResolver' object has no attribute 'name'

During handling of the above exception, another exception occurred:

Traceback (most recent call last):
  File "C:\Python\Python35\lib\site-packages\django\template\base.py", line 898, in _resolve_lookup
    current = current[int(bit)]
ValueError: invalid literal for int() with base 10: 'name'

During handling of the above exception, another exception occurred:

Traceback (most recent call last):
  File "C:\Python\Python35\lib\site-packages\django\template\base.py", line 905, in _resolve_lookup
    (bit, current))  # missing attribute
django.template.base.VariableDoesNotExist: Failed lookup for key [name] in "<RegexURLResolver <module 'ioteca_service_apps.auths_api.urls' from 'F:\\\\taller\\\\initial_ioteca\\\\ioteca_service\\\\ioteca_service_apps\\\\auths_api\\\\urls.py'> (None:None) ^api/auths/>"
[2016-11-13 19:24:25] DEBUG [django.template:927] Exception while resolving variable 'name' in template 'unknown'.
Traceback (most recent call last):
  File "C:\Python\Python35\lib\site-packages\django\core\handlers\base.py", line 134, in get_response
    resolver_match = resolver.resolve(request.path_info)
  File "C:\Python\Python35\lib\site-packages\django\core\urlresolvers.py", line 404, in resolve
    raise Resolver404({'tried': tried, 'path': new_path})
django.core.urlresolvers.Resolver404: {'tried': [[<RegexURLResolver <RegexURLPattern list> (admin:admin) ^admin/>], [<RegexURLResolver <module 'django.contrib.admindocs.urls' from 'C:\\Python\\Python35\\lib\\site-packages\\django\\contrib\\admindocs\\urls.py'> (None:None) ^admin/doc/>], [<RegexURLResolver <module 'rest_framework.urls' from 'C:\\Python\\Python35\\lib\\site-packages\\rest_framework\\urls.py'> (rest_framework:rest_framework) ^api-auth/>], [<RegexURLResolver <module 'oauth2_provider.urls' from 'C:\\Python\\Python35\\lib\\site-packages\\oauth2_provider\\urls.py'> (None:oauth2_provider) ^o/>], [<RegexURLResolver <module 'ioteca_service_apps.auths_api.urls' from 'F:\\taller\\initial_ioteca\\ioteca_service\\ioteca_service_apps\\auths_api\\urls.py'> (None:None) ^api/auths/>], [<RegexURLResolver <module 'ioteca_service_apps.catalogo_api.urls' from 'F:\\taller\\initial_ioteca\\ioteca_service\\ioteca_service_apps\\catalogo_api\\urls.py'> (None:None) ^api/catalogo/>], [<RegexURLResolver <module 'ioteca_service_apps.eventos_api.urls' from 'F:\\taller\\initial_ioteca\\ioteca_service\\ioteca_service_apps\\eventos_api\\urls.py'> (None:None) ^api/eventos/>]], 'path': ''}

During handling of the above exception, another exception occurred:

Traceback (most recent call last):
  File "C:\Python\Python35\lib\site-packages\django\template\base.py", line 883, in _resolve_lookup
    current = current[bit]
TypeError: 'RegexURLResolver' object is not subscriptable

During handling of the above exception, another exception occurred:

Traceback (most recent call last):
  File "C:\Python\Python35\lib\site-packages\django\template\base.py", line 891, in _resolve_lookup
    current = getattr(current, bit)
AttributeError: 'RegexURLResolver' object has no attribute 'name'

During handling of the above exception, another exception occurred:

Traceback (most recent call last):
  File "C:\Python\Python35\lib\site-packages\django\template\base.py", line 898, in _resolve_lookup
    current = current[int(bit)]
ValueError: invalid literal for int() with base 10: 'name'

During handling of the above exception, another exception occurred:

Traceback (most recent call last):
  File "C:\Python\Python35\lib\site-packages\django\template\base.py", line 905, in _resolve_lookup
    (bit, current))  # missing attribute
django.template.base.VariableDoesNotExist: Failed lookup for key [name] in "<RegexURLResolver <module 'ioteca_service_apps.catalogo_api.urls' from 'F:\\\\taller\\\\initial_ioteca\\\\ioteca_service\\\\ioteca_service_apps\\\\catalogo_api\\\\urls.py'> (None:None) ^api/catalogo/>"
[2016-11-13 19:24:25] DEBUG [django.template:927] Exception while resolving variable 'name' in template 'unknown'.
Traceback (most recent call last):
  File "C:\Python\Python35\lib\site-packages\django\core\handlers\base.py", line 134, in get_response
    resolver_match = resolver.resolve(request.path_info)
  File "C:\Python\Python35\lib\site-packages\django\core\urlresolvers.py", line 404, in resolve
    raise Resolver404({'tried': tried, 'path': new_path})
django.core.urlresolvers.Resolver404: {'tried': [[<RegexURLResolver <RegexURLPattern list> (admin:admin) ^admin/>], [<RegexURLResolver <module 'django.contrib.admindocs.urls' from 'C:\\Python\\Python35\\lib\\site-packages\\django\\contrib\\admindocs\\urls.py'> (None:None) ^admin/doc/>], [<RegexURLResolver <module 'rest_framework.urls' from 'C:\\Python\\Python35\\lib\\site-packages\\rest_framework\\urls.py'> (rest_framework:rest_framework) ^api-auth/>], [<RegexURLResolver <module 'oauth2_provider.urls' from 'C:\\Python\\Python35\\lib\\site-packages\\oauth2_provider\\urls.py'> (None:oauth2_provider) ^o/>], [<RegexURLResolver <module 'ioteca_service_apps.auths_api.urls' from 'F:\\taller\\initial_ioteca\\ioteca_service\\ioteca_service_apps\\auths_api\\urls.py'> (None:None) ^api/auths/>], [<RegexURLResolver <module 'ioteca_service_apps.catalogo_api.urls' from 'F:\\taller\\initial_ioteca\\ioteca_service\\ioteca_service_apps\\catalogo_api\\urls.py'> (None:None) ^api/catalogo/>], [<RegexURLResolver <module 'ioteca_service_apps.eventos_api.urls' from 'F:\\taller\\initial_ioteca\\ioteca_service\\ioteca_service_apps\\eventos_api\\urls.py'> (None:None) ^api/eventos/>]], 'path': ''}

During handling of the above exception, another exception occurred:

Traceback (most recent call last):
  File "C:\Python\Python35\lib\site-packages\django\template\base.py", line 883, in _resolve_lookup
    current = current[bit]
TypeError: 'RegexURLResolver' object is not subscriptable

During handling of the above exception, another exception occurred:

Traceback (most recent call last):
  File "C:\Python\Python35\lib\site-packages\django\template\base.py", line 891, in _resolve_lookup
    current = getattr(current, bit)
AttributeError: 'RegexURLResolver' object has no attribute 'name'

During handling of the above exception, another exception occurred:

Traceback (most recent call last):
  File "C:\Python\Python35\lib\site-packages\django\template\base.py", line 898, in _resolve_lookup
    current = current[int(bit)]
ValueError: invalid literal for int() with base 10: 'name'

During handling of the above exception, another exception occurred:

Traceback (most recent call last):
  File "C:\Python\Python35\lib\site-packages\django\template\base.py", line 905, in _resolve_lookup
    (bit, current))  # missing attribute
django.template.base.VariableDoesNotExist: Failed lookup for key [name] in "<RegexURLResolver <module 'ioteca_service_apps.eventos_api.urls' from 'F:\\\\taller\\\\initial_ioteca\\\\ioteca_service\\\\ioteca_service_apps\\\\eventos_api\\\\urls.py'> (None:None) ^api/eventos/>"
[2016-11-13 19:24:26] WARNING [django.request:182] Not Found: /favicon.ico
[2016-11-13 19:24:26] DEBUG [django.template:927] Exception while resolving variable 'name' in template 'unknown'.
Traceback (most recent call last):
  File "C:\Python\Python35\lib\site-packages\django\core\handlers\base.py", line 134, in get_response
    resolver_match = resolver.resolve(request.path_info)
  File "C:\Python\Python35\lib\site-packages\django\core\urlresolvers.py", line 404, in resolve
    raise Resolver404({'tried': tried, 'path': new_path})
django.core.urlresolvers.Resolver404: {'tried': [[<RegexURLResolver <RegexURLPattern list> (admin:admin) ^admin/>], [<RegexURLResolver <module 'django.contrib.admindocs.urls' from 'C:\\Python\\Python35\\lib\\site-packages\\django\\contrib\\admindocs\\urls.py'> (None:None) ^admin/doc/>], [<RegexURLResolver <module 'rest_framework.urls' from 'C:\\Python\\Python35\\lib\\site-packages\\rest_framework\\urls.py'> (rest_framework:rest_framework) ^api-auth/>], [<RegexURLResolver <module 'oauth2_provider.urls' from 'C:\\Python\\Python35\\lib\\site-packages\\oauth2_provider\\urls.py'> (None:oauth2_provider) ^o/>], [<RegexURLResolver <module 'ioteca_service_apps.auths_api.urls' from 'F:\\taller\\initial_ioteca\\ioteca_service\\ioteca_service_apps\\auths_api\\urls.py'> (None:None) ^api/auths/>], [<RegexURLResolver <module 'ioteca_service_apps.catalogo_api.urls' from 'F:\\taller\\initial_ioteca\\ioteca_service\\ioteca_service_apps\\catalogo_api\\urls.py'> (None:None) ^api/catalogo/>], [<RegexURLResolver <module 'ioteca_service_apps.eventos_api.urls' from 'F:\\taller\\initial_ioteca\\ioteca_service\\ioteca_service_apps\\eventos_api\\urls.py'> (None:None) ^api/eventos/>]], 'path': 'favicon.ico'}

During handling of the above exception, another exception occurred:

Traceback (most recent call last):
  File "C:\Python\Python35\lib\site-packages\django\template\base.py", line 883, in _resolve_lookup
    current = current[bit]
TypeError: 'RegexURLResolver' object is not subscriptable

During handling of the above exception, another exception occurred:

Traceback (most recent call last):
  File "C:\Python\Python35\lib\site-packages\django\template\base.py", line 891, in _resolve_lookup
    current = getattr(current, bit)
AttributeError: 'RegexURLResolver' object has no attribute 'name'

During handling of the above exception, another exception occurred:

Traceback (most recent call last):
  File "C:\Python\Python35\lib\site-packages\django\template\base.py", line 898, in _resolve_lookup
    current = current[int(bit)]
ValueError: invalid literal for int() with base 10: 'name'

During handling of the above exception, another exception occurred:

Traceback (most recent call last):
  File "C:\Python\Python35\lib\site-packages\django\template\base.py", line 905, in _resolve_lookup
    (bit, current))  # missing attribute
django.template.base.VariableDoesNotExist: Failed lookup for key [name] in '<RegexURLResolver <RegexURLPattern list> (admin:admin) ^admin/>'
[2016-11-13 19:24:26] DEBUG [django.template:927] Exception while resolving variable 'name' in template 'unknown'.
Traceback (most recent call last):
  File "C:\Python\Python35\lib\site-packages\django\core\handlers\base.py", line 134, in get_response
    resolver_match = resolver.resolve(request.path_info)
  File "C:\Python\Python35\lib\site-packages\django\core\urlresolvers.py", line 404, in resolve
    raise Resolver404({'tried': tried, 'path': new_path})
django.core.urlresolvers.Resolver404: {'tried': [[<RegexURLResolver <RegexURLPattern list> (admin:admin) ^admin/>], [<RegexURLResolver <module 'django.contrib.admindocs.urls' from 'C:\\Python\\Python35\\lib\\site-packages\\django\\contrib\\admindocs\\urls.py'> (None:None) ^admin/doc/>], [<RegexURLResolver <module 'rest_framework.urls' from 'C:\\Python\\Python35\\lib\\site-packages\\rest_framework\\urls.py'> (rest_framework:rest_framework) ^api-auth/>], [<RegexURLResolver <module 'oauth2_provider.urls' from 'C:\\Python\\Python35\\lib\\site-packages\\oauth2_provider\\urls.py'> (None:oauth2_provider) ^o/>], [<RegexURLResolver <module 'ioteca_service_apps.auths_api.urls' from 'F:\\taller\\initial_ioteca\\ioteca_service\\ioteca_service_apps\\auths_api\\urls.py'> (None:None) ^api/auths/>], [<RegexURLResolver <module 'ioteca_service_apps.catalogo_api.urls' from 'F:\\taller\\initial_ioteca\\ioteca_service\\ioteca_service_apps\\catalogo_api\\urls.py'> (None:None) ^api/catalogo/>], [<RegexURLResolver <module 'ioteca_service_apps.eventos_api.urls' from 'F:\\taller\\initial_ioteca\\ioteca_service\\ioteca_service_apps\\eventos_api\\urls.py'> (None:None) ^api/eventos/>]], 'path': 'favicon.ico'}

During handling of the above exception, another exception occurred:

Traceback (most recent call last):
  File "C:\Python\Python35\lib\site-packages\django\template\base.py", line 883, in _resolve_lookup
    current = current[bit]
TypeError: 'RegexURLResolver' object is not subscriptable

During handling of the above exception, another exception occurred:

Traceback (most recent call last):
  File "C:\Python\Python35\lib\site-packages\django\template\base.py", line 891, in _resolve_lookup
    current = getattr(current, bit)
AttributeError: 'RegexURLResolver' object has no attribute 'name'

During handling of the above exception, another exception occurred:

Traceback (most recent call last):
  File "C:\Python\Python35\lib\site-packages\django\template\base.py", line 898, in _resolve_lookup
    current = current[int(bit)]
ValueError: invalid literal for int() with base 10: 'name'

During handling of the above exception, another exception occurred:

Traceback (most recent call last):
  File "C:\Python\Python35\lib\site-packages\django\template\base.py", line 905, in _resolve_lookup
    (bit, current))  # missing attribute
django.template.base.VariableDoesNotExist: Failed lookup for key [name] in "<RegexURLResolver <module 'django.contrib.admindocs.urls' from 'C:\\\\Python\\\\Python35\\\\lib\\\\site-packages\\\\django\\\\contrib\\\\admindocs\\\\urls.py'> (None:None) ^admin/doc/>"
[2016-11-13 19:24:26] DEBUG [django.template:927] Exception while resolving variable 'name' in template 'unknown'.
Traceback (most recent call last):
  File "C:\Python\Python35\lib\site-packages\django\core\handlers\base.py", line 134, in get_response
    resolver_match = resolver.resolve(request.path_info)
  File "C:\Python\Python35\lib\site-packages\django\core\urlresolvers.py", line 404, in resolve
    raise Resolver404({'tried': tried, 'path': new_path})
django.core.urlresolvers.Resolver404: {'tried': [[<RegexURLResolver <RegexURLPattern list> (admin:admin) ^admin/>], [<RegexURLResolver <module 'django.contrib.admindocs.urls' from 'C:\\Python\\Python35\\lib\\site-packages\\django\\contrib\\admindocs\\urls.py'> (None:None) ^admin/doc/>], [<RegexURLResolver <module 'rest_framework.urls' from 'C:\\Python\\Python35\\lib\\site-packages\\rest_framework\\urls.py'> (rest_framework:rest_framework) ^api-auth/>], [<RegexURLResolver <module 'oauth2_provider.urls' from 'C:\\Python\\Python35\\lib\\site-packages\\oauth2_provider\\urls.py'> (None:oauth2_provider) ^o/>], [<RegexURLResolver <module 'ioteca_service_apps.auths_api.urls' from 'F:\\taller\\initial_ioteca\\ioteca_service\\ioteca_service_apps\\auths_api\\urls.py'> (None:None) ^api/auths/>], [<RegexURLResolver <module 'ioteca_service_apps.catalogo_api.urls' from 'F:\\taller\\initial_ioteca\\ioteca_service\\ioteca_service_apps\\catalogo_api\\urls.py'> (None:None) ^api/catalogo/>], [<RegexURLResolver <module 'ioteca_service_apps.eventos_api.urls' from 'F:\\taller\\initial_ioteca\\ioteca_service\\ioteca_service_apps\\eventos_api\\urls.py'> (None:None) ^api/eventos/>]], 'path': 'favicon.ico'}

During handling of the above exception, another exception occurred:

Traceback (most recent call last):
  File "C:\Python\Python35\lib\site-packages\django\template\base.py", line 883, in _resolve_lookup
    current = current[bit]
TypeError: 'RegexURLResolver' object is not subscriptable

During handling of the above exception, another exception occurred:

Traceback (most recent call last):
  File "C:\Python\Python35\lib\site-packages\django\template\base.py", line 891, in _resolve_lookup
    current = getattr(current, bit)
AttributeError: 'RegexURLResolver' object has no attribute 'name'

During handling of the above exception, another exception occurred:

Traceback (most recent call last):
  File "C:\Python\Python35\lib\site-packages\django\template\base.py", line 898, in _resolve_lookup
    current = current[int(bit)]
ValueError: invalid literal for int() with base 10: 'name'

During handling of the above exception, another exception occurred:

Traceback (most recent call last):
  File "C:\Python\Python35\lib\site-packages\django\template\base.py", line 905, in _resolve_lookup
    (bit, current))  # missing attribute
django.template.base.VariableDoesNotExist: Failed lookup for key [name] in "<RegexURLResolver <module 'rest_framework.urls' from 'C:\\\\Python\\\\Python35\\\\lib\\\\site-packages\\\\rest_framework\\\\urls.py'> (rest_framework:rest_framework) ^api-auth/>"
[2016-11-13 19:24:26] DEBUG [django.template:927] Exception while resolving variable 'name' in template 'unknown'.
Traceback (most recent call last):
  File "C:\Python\Python35\lib\site-packages\django\core\handlers\base.py", line 134, in get_response
    resolver_match = resolver.resolve(request.path_info)
  File "C:\Python\Python35\lib\site-packages\django\core\urlresolvers.py", line 404, in resolve
    raise Resolver404({'tried': tried, 'path': new_path})
django.core.urlresolvers.Resolver404: {'tried': [[<RegexURLResolver <RegexURLPattern list> (admin:admin) ^admin/>], [<RegexURLResolver <module 'django.contrib.admindocs.urls' from 'C:\\Python\\Python35\\lib\\site-packages\\django\\contrib\\admindocs\\urls.py'> (None:None) ^admin/doc/>], [<RegexURLResolver <module 'rest_framework.urls' from 'C:\\Python\\Python35\\lib\\site-packages\\rest_framework\\urls.py'> (rest_framework:rest_framework) ^api-auth/>], [<RegexURLResolver <module 'oauth2_provider.urls' from 'C:\\Python\\Python35\\lib\\site-packages\\oauth2_provider\\urls.py'> (None:oauth2_provider) ^o/>], [<RegexURLResolver <module 'ioteca_service_apps.auths_api.urls' from 'F:\\taller\\initial_ioteca\\ioteca_service\\ioteca_service_apps\\auths_api\\urls.py'> (None:None) ^api/auths/>], [<RegexURLResolver <module 'ioteca_service_apps.catalogo_api.urls' from 'F:\\taller\\initial_ioteca\\ioteca_service\\ioteca_service_apps\\catalogo_api\\urls.py'> (None:None) ^api/catalogo/>], [<RegexURLResolver <module 'ioteca_service_apps.eventos_api.urls' from 'F:\\taller\\initial_ioteca\\ioteca_service\\ioteca_service_apps\\eventos_api\\urls.py'> (None:None) ^api/eventos/>]], 'path': 'favicon.ico'}

During handling of the above exception, another exception occurred:

Traceback (most recent call last):
  File "C:\Python\Python35\lib\site-packages\django\template\base.py", line 883, in _resolve_lookup
    current = current[bit]
TypeError: 'RegexURLResolver' object is not subscriptable

During handling of the above exception, another exception occurred:

Traceback (most recent call last):
  File "C:\Python\Python35\lib\site-packages\django\template\base.py", line 891, in _resolve_lookup
    current = getattr(current, bit)
AttributeError: 'RegexURLResolver' object has no attribute 'name'

During handling of the above exception, another exception occurred:

Traceback (most recent call last):
  File "C:\Python\Python35\lib\site-packages\django\template\base.py", line 898, in _resolve_lookup
    current = current[int(bit)]
ValueError: invalid literal for int() with base 10: 'name'

During handling of the above exception, another exception occurred:

Traceback (most recent call last):
  File "C:\Python\Python35\lib\site-packages\django\template\base.py", line 905, in _resolve_lookup
    (bit, current))  # missing attribute
django.template.base.VariableDoesNotExist: Failed lookup for key [name] in "<RegexURLResolver <module 'oauth2_provider.urls' from 'C:\\\\Python\\\\Python35\\\\lib\\\\site-packages\\\\oauth2_provider\\\\urls.py'> (None:oauth2_provider) ^o/>"
[2016-11-13 19:24:26] DEBUG [django.template:927] Exception while resolving variable 'name' in template 'unknown'.
Traceback (most recent call last):
  File "C:\Python\Python35\lib\site-packages\django\core\handlers\base.py", line 134, in get_response
    resolver_match = resolver.resolve(request.path_info)
  File "C:\Python\Python35\lib\site-packages\django\core\urlresolvers.py", line 404, in resolve
    raise Resolver404({'tried': tried, 'path': new_path})
django.core.urlresolvers.Resolver404: {'tried': [[<RegexURLResolver <RegexURLPattern list> (admin:admin) ^admin/>], [<RegexURLResolver <module 'django.contrib.admindocs.urls' from 'C:\\Python\\Python35\\lib\\site-packages\\django\\contrib\\admindocs\\urls.py'> (None:None) ^admin/doc/>], [<RegexURLResolver <module 'rest_framework.urls' from 'C:\\Python\\Python35\\lib\\site-packages\\rest_framework\\urls.py'> (rest_framework:rest_framework) ^api-auth/>], [<RegexURLResolver <module 'oauth2_provider.urls' from 'C:\\Python\\Python35\\lib\\site-packages\\oauth2_provider\\urls.py'> (None:oauth2_provider) ^o/>], [<RegexURLResolver <module 'ioteca_service_apps.auths_api.urls' from 'F:\\taller\\initial_ioteca\\ioteca_service\\ioteca_service_apps\\auths_api\\urls.py'> (None:None) ^api/auths/>], [<RegexURLResolver <module 'ioteca_service_apps.catalogo_api.urls' from 'F:\\taller\\initial_ioteca\\ioteca_service\\ioteca_service_apps\\catalogo_api\\urls.py'> (None:None) ^api/catalogo/>], [<RegexURLResolver <module 'ioteca_service_apps.eventos_api.urls' from 'F:\\taller\\initial_ioteca\\ioteca_service\\ioteca_service_apps\\eventos_api\\urls.py'> (None:None) ^api/eventos/>]], 'path': 'favicon.ico'}

During handling of the above exception, another exception occurred:

Traceback (most recent call last):
  File "C:\Python\Python35\lib\site-packages\django\template\base.py", line 883, in _resolve_lookup
    current = current[bit]
TypeError: 'RegexURLResolver' object is not subscriptable

During handling of the above exception, another exception occurred:

Traceback (most recent call last):
  File "C:\Python\Python35\lib\site-packages\django\template\base.py", line 891, in _resolve_lookup
    current = getattr(current, bit)
AttributeError: 'RegexURLResolver' object has no attribute 'name'

During handling of the above exception, another exception occurred:

Traceback (most recent call last):
  File "C:\Python\Python35\lib\site-packages\django\template\base.py", line 898, in _resolve_lookup
    current = current[int(bit)]
ValueError: invalid literal for int() with base 10: 'name'

During handling of the above exception, another exception occurred:

Traceback (most recent call last):
  File "C:\Python\Python35\lib\site-packages\django\template\base.py", line 905, in _resolve_lookup
    (bit, current))  # missing attribute
django.template.base.VariableDoesNotExist: Failed lookup for key [name] in "<RegexURLResolver <module 'ioteca_service_apps.auths_api.urls' from 'F:\\\\taller\\\\initial_ioteca\\\\ioteca_service\\\\ioteca_service_apps\\\\auths_api\\\\urls.py'> (None:None) ^api/auths/>"
[2016-11-13 19:24:26] DEBUG [django.template:927] Exception while resolving variable 'name' in template 'unknown'.
Traceback (most recent call last):
  File "C:\Python\Python35\lib\site-packages\django\core\handlers\base.py", line 134, in get_response
    resolver_match = resolver.resolve(request.path_info)
  File "C:\Python\Python35\lib\site-packages\django\core\urlresolvers.py", line 404, in resolve
    raise Resolver404({'tried': tried, 'path': new_path})
django.core.urlresolvers.Resolver404: {'tried': [[<RegexURLResolver <RegexURLPattern list> (admin:admin) ^admin/>], [<RegexURLResolver <module 'django.contrib.admindocs.urls' from 'C:\\Python\\Python35\\lib\\site-packages\\django\\contrib\\admindocs\\urls.py'> (None:None) ^admin/doc/>], [<RegexURLResolver <module 'rest_framework.urls' from 'C:\\Python\\Python35\\lib\\site-packages\\rest_framework\\urls.py'> (rest_framework:rest_framework) ^api-auth/>], [<RegexURLResolver <module 'oauth2_provider.urls' from 'C:\\Python\\Python35\\lib\\site-packages\\oauth2_provider\\urls.py'> (None:oauth2_provider) ^o/>], [<RegexURLResolver <module 'ioteca_service_apps.auths_api.urls' from 'F:\\taller\\initial_ioteca\\ioteca_service\\ioteca_service_apps\\auths_api\\urls.py'> (None:None) ^api/auths/>], [<RegexURLResolver <module 'ioteca_service_apps.catalogo_api.urls' from 'F:\\taller\\initial_ioteca\\ioteca_service\\ioteca_service_apps\\catalogo_api\\urls.py'> (None:None) ^api/catalogo/>], [<RegexURLResolver <module 'ioteca_service_apps.eventos_api.urls' from 'F:\\taller\\initial_ioteca\\ioteca_service\\ioteca_service_apps\\eventos_api\\urls.py'> (None:None) ^api/eventos/>]], 'path': 'favicon.ico'}

During handling of the above exception, another exception occurred:

Traceback (most recent call last):
  File "C:\Python\Python35\lib\site-packages\django\template\base.py", line 883, in _resolve_lookup
    current = current[bit]
TypeError: 'RegexURLResolver' object is not subscriptable

During handling of the above exception, another exception occurred:

Traceback (most recent call last):
  File "C:\Python\Python35\lib\site-packages\django\template\base.py", line 891, in _resolve_lookup
    current = getattr(current, bit)
AttributeError: 'RegexURLResolver' object has no attribute 'name'

During handling of the above exception, another exception occurred:

Traceback (most recent call last):
  File "C:\Python\Python35\lib\site-packages\django\template\base.py", line 898, in _resolve_lookup
    current = current[int(bit)]
ValueError: invalid literal for int() with base 10: 'name'

During handling of the above exception, another exception occurred:

Traceback (most recent call last):
  File "C:\Python\Python35\lib\site-packages\django\template\base.py", line 905, in _resolve_lookup
    (bit, current))  # missing attribute
django.template.base.VariableDoesNotExist: Failed lookup for key [name] in "<RegexURLResolver <module 'ioteca_service_apps.catalogo_api.urls' from 'F:\\\\taller\\\\initial_ioteca\\\\ioteca_service\\\\ioteca_service_apps\\\\catalogo_api\\\\urls.py'> (None:None) ^api/catalogo/>"
[2016-11-13 19:24:26] DEBUG [django.template:927] Exception while resolving variable 'name' in template 'unknown'.
Traceback (most recent call last):
  File "C:\Python\Python35\lib\site-packages\django\core\handlers\base.py", line 134, in get_response
    resolver_match = resolver.resolve(request.path_info)
  File "C:\Python\Python35\lib\site-packages\django\core\urlresolvers.py", line 404, in resolve
    raise Resolver404({'tried': tried, 'path': new_path})
django.core.urlresolvers.Resolver404: {'tried': [[<RegexURLResolver <RegexURLPattern list> (admin:admin) ^admin/>], [<RegexURLResolver <module 'django.contrib.admindocs.urls' from 'C:\\Python\\Python35\\lib\\site-packages\\django\\contrib\\admindocs\\urls.py'> (None:None) ^admin/doc/>], [<RegexURLResolver <module 'rest_framework.urls' from 'C:\\Python\\Python35\\lib\\site-packages\\rest_framework\\urls.py'> (rest_framework:rest_framework) ^api-auth/>], [<RegexURLResolver <module 'oauth2_provider.urls' from 'C:\\Python\\Python35\\lib\\site-packages\\oauth2_provider\\urls.py'> (None:oauth2_provider) ^o/>], [<RegexURLResolver <module 'ioteca_service_apps.auths_api.urls' from 'F:\\taller\\initial_ioteca\\ioteca_service\\ioteca_service_apps\\auths_api\\urls.py'> (None:None) ^api/auths/>], [<RegexURLResolver <module 'ioteca_service_apps.catalogo_api.urls' from 'F:\\taller\\initial_ioteca\\ioteca_service\\ioteca_service_apps\\catalogo_api\\urls.py'> (None:None) ^api/catalogo/>], [<RegexURLResolver <module 'ioteca_service_apps.eventos_api.urls' from 'F:\\taller\\initial_ioteca\\ioteca_service\\ioteca_service_apps\\eventos_api\\urls.py'> (None:None) ^api/eventos/>]], 'path': 'favicon.ico'}

During handling of the above exception, another exception occurred:

Traceback (most recent call last):
  File "C:\Python\Python35\lib\site-packages\django\template\base.py", line 883, in _resolve_lookup
    current = current[bit]
TypeError: 'RegexURLResolver' object is not subscriptable

During handling of the above exception, another exception occurred:

Traceback (most recent call last):
  File "C:\Python\Python35\lib\site-packages\django\template\base.py", line 891, in _resolve_lookup
    current = getattr(current, bit)
AttributeError: 'RegexURLResolver' object has no attribute 'name'

During handling of the above exception, another exception occurred:

Traceback (most recent call last):
  File "C:\Python\Python35\lib\site-packages\django\template\base.py", line 898, in _resolve_lookup
    current = current[int(bit)]
ValueError: invalid literal for int() with base 10: 'name'

During handling of the above exception, another exception occurred:

Traceback (most recent call last):
  File "C:\Python\Python35\lib\site-packages\django\template\base.py", line 905, in _resolve_lookup
    (bit, current))  # missing attribute
django.template.base.VariableDoesNotExist: Failed lookup for key [name] in "<RegexURLResolver <module 'ioteca_service_apps.eventos_api.urls' from 'F:\\\\taller\\\\initial_ioteca\\\\ioteca_service\\\\ioteca_service_apps\\\\eventos_api\\\\urls.py'> (None:None) ^api/eventos/>"
[2016-11-13 19:24:30] DEBUG [django.template:927] Exception while resolving variable 'is_popup' in template 'admin/login.html'.
Traceback (most recent call last):
  File "C:\Python\Python35\lib\site-packages\django\template\base.py", line 883, in _resolve_lookup
    current = current[bit]
  File "C:\Python\Python35\lib\site-packages\django\template\context.py", line 77, in __getitem__
    raise KeyError(key)
KeyError: 'is_popup'

During handling of the above exception, another exception occurred:

Traceback (most recent call last):
  File "C:\Python\Python35\lib\site-packages\django\template\base.py", line 889, in _resolve_lookup
    if isinstance(current, BaseContext) and getattr(type(current), bit):
AttributeError: type object 'RequestContext' has no attribute 'is_popup'

During handling of the above exception, another exception occurred:

Traceback (most recent call last):
  File "C:\Python\Python35\lib\site-packages\django\template\base.py", line 898, in _resolve_lookup
    current = current[int(bit)]
ValueError: invalid literal for int() with base 10: 'is_popup'

During handling of the above exception, another exception occurred:

Traceback (most recent call last):
  File "C:\Python\Python35\lib\site-packages\django\template\base.py", line 905, in _resolve_lookup
    (bit, current))  # missing attribute
django.template.base.VariableDoesNotExist: Failed lookup for key [is_popup] in "[{'False': False, 'True': True, 'None': None}, {'user': <SimpleLazyObject: <django.contrib.auth.models.AnonymousUser object at 0x000002323D733FD0>>, 'DEFAULT_MESSAGE_LEVELS': {'ERROR': 40, 'INFO': 20, 'SUCCESS': 25, 'WARNING': 30, 'DEBUG': 10}, 'perms': <django.contrib.auth.context_processors.PermWrapper object at 0x000002323D75F898>, 'messages': <django.contrib.messages.storage.fallback.FallbackStorage object at 0x000002323D748048>, 'request': <WSGIRequest: GET '/admin/login/?next=/admin/'>, 'csrf_token': <SimpleLazyObject: <function csrf.<locals>._get_val at 0x000002323D631840>>}, {}, {'site_url': '/', 'available_apps': [], 'app_path': '/admin/login/?next=/admin/', 'site_header': <django.utils.functional.lazy.<locals>.__proxy__ object at 0x000002323C444DA0>, 'title': 'Log in', 'form': <AdminAuthenticationForm bound=False, valid=Unknown, fields=(username;password)>, 'next': '/admin/', 'LANGUAGE_BIDI': False, 'has_permission': False, 'site': <django.contrib.sites.requests.RequestSite object at 0x000002323D748358>, 'site_name': 'localhost:9000', 'site_title': <django.utils.functional.lazy.<locals>.__proxy__ object at 0x000002323C444CF8>, 'LANGUAGE_CODE': 'en-us'}]"
[2016-11-13 19:24:30] DEBUG [django.template:927] Exception while resolving variable 'is_popup' in template 'admin/login.html'.
Traceback (most recent call last):
  File "C:\Python\Python35\lib\site-packages\django\template\base.py", line 883, in _resolve_lookup
    current = current[bit]
  File "C:\Python\Python35\lib\site-packages\django\template\context.py", line 77, in __getitem__
    raise KeyError(key)
KeyError: 'is_popup'

During handling of the above exception, another exception occurred:

Traceback (most recent call last):
  File "C:\Python\Python35\lib\site-packages\django\template\base.py", line 889, in _resolve_lookup
    if isinstance(current, BaseContext) and getattr(type(current), bit):
AttributeError: type object 'RequestContext' has no attribute 'is_popup'

During handling of the above exception, another exception occurred:

Traceback (most recent call last):
  File "C:\Python\Python35\lib\site-packages\django\template\base.py", line 898, in _resolve_lookup
    current = current[int(bit)]
ValueError: invalid literal for int() with base 10: 'is_popup'

During handling of the above exception, another exception occurred:

Traceback (most recent call last):
  File "C:\Python\Python35\lib\site-packages\django\template\base.py", line 905, in _resolve_lookup
    (bit, current))  # missing attribute
django.template.base.VariableDoesNotExist: Failed lookup for key [is_popup] in "[{'False': False, 'True': True, 'None': None}, {'user': <SimpleLazyObject: <django.contrib.auth.models.AnonymousUser object at 0x000002323D733FD0>>, 'DEFAULT_MESSAGE_LEVELS': {'ERROR': 40, 'INFO': 20, 'SUCCESS': 25, 'WARNING': 30, 'DEBUG': 10}, 'perms': <django.contrib.auth.context_processors.PermWrapper object at 0x000002323D75F898>, 'messages': <django.contrib.messages.storage.fallback.FallbackStorage object at 0x000002323D748048>, 'request': <WSGIRequest: GET '/admin/login/?next=/admin/'>, 'csrf_token': <SimpleLazyObject: <function csrf.<locals>._get_val at 0x000002323D631840>>}, {}, {'site_url': '/', 'available_apps': [], 'app_path': '/admin/login/?next=/admin/', 'site_header': <django.utils.functional.lazy.<locals>.__proxy__ object at 0x000002323C444DA0>, 'title': 'Log in', 'form': <AdminAuthenticationForm bound=False, valid=Unknown, fields=(username;password)>, 'next': '/admin/', 'LANGUAGE_BIDI': False, 'has_permission': False, 'site': <django.contrib.sites.requests.RequestSite object at 0x000002323D748358>, 'site_name': 'localhost:9000', 'site_title': <django.utils.functional.lazy.<locals>.__proxy__ object at 0x000002323C444CF8>, 'LANGUAGE_CODE': 'en-us'}]"
[2016-11-13 19:24:32] DEBUG [django.db.backends:89] (0.058) SELECT "auths_user"."password", "auths_user"."last_login", "auths_user"."is_superuser", "auths_user"."username", "auths_user"."first_name", "auths_user"."last_name", "auths_user"."email", "auths_user"."is_staff", "auths_user"."is_active", "auths_user"."date_joined", "auths_user"."id", "auths_user"."last_hierarchy_id", "auths_user"."last_module_id", "auths_user"."person_id", "auths_user"."updated_at", "auths_user"."registered_by" FROM "auths_user" WHERE "auths_user"."username" = 'admin'; args=('admin',)
[2016-11-13 19:24:33] DEBUG [django.db.backends:89] (0.042) SELECT (1) AS "a" FROM "django_session" WHERE "django_session"."session_key" = 'n332ybb6udcm6hpyhr4roha4unb4emla' LIMIT 1; args=('n332ybb6udcm6hpyhr4roha4unb4emla',)
[2016-11-13 19:24:33] DEBUG [django.db.backends:89] (0.000) BEGIN; args=None
[2016-11-13 19:24:33] DEBUG [django.db.backends:89] (0.002) INSERT INTO "django_session" ("session_key", "session_data", "expire_date") SELECT 'n332ybb6udcm6hpyhr4roha4unb4emla', 'MWM0OGIyODQ4NzI4MzRhZjAyMjIxNmY1YzZlNzUwYmUzNTU2OWFjMTp7fQ==', '2016-11-28 00:24:33.285865'; args=('n332ybb6udcm6hpyhr4roha4unb4emla', 'MWM0OGIyODQ4NzI4MzRhZjAyMjIxNmY1YzZlNzUwYmUzNTU2OWFjMTp7fQ==', '2016-11-28 00:24:33.285865')
[2016-11-13 19:24:33] DEBUG [django.db.backends:89] (0.001) SELECT "django_session"."session_key", "django_session"."session_data", "django_session"."expire_date" FROM "django_session" WHERE "django_session"."session_key" = 'n332ybb6udcm6hpyhr4roha4unb4emla'; args=('n332ybb6udcm6hpyhr4roha4unb4emla',)
[2016-11-13 19:24:33] DEBUG [django.db.backends:89] (0.000) BEGIN; args=None
[2016-11-13 19:24:33] DEBUG [django.db.backends:89] (0.000) DELETE FROM "django_session" WHERE "django_session"."session_key" IN ('n332ybb6udcm6hpyhr4roha4unb4emla'); args=('n332ybb6udcm6hpyhr4roha4unb4emla',)
[2016-11-13 19:24:33] DEBUG [django.db.backends:89] (0.000) BEGIN; args=None
[2016-11-13 19:24:33] DEBUG [django.db.backends:89] (0.001) UPDATE "auths_user" SET "last_login" = '2016-11-14 00:24:33.666632' WHERE "auths_user"."id" = '98c929be19fb4598b30233dd1ddbfcfd'; args=('2016-11-14 00:24:33.666632', '98c929be19fb4598b30233dd1ddbfcfd')
[2016-11-13 19:24:33] DEBUG [django.db.backends:89] (0.000) BEGIN; args=None
[2016-11-13 19:24:33] DEBUG [django.db.backends:89] (0.000) UPDATE "django_session" SET "session_data" = 'Y2YzY2ExNWNmMGEwMWM3Mzc2ZGJhZjBiMzM1NDY0ODgzYmQwZjEzZjp7Il9hdXRoX3VzZXJfaWQiOiI5OGM5MjliZS0xOWZiLTQ1OTgtYjMwMi0zM2RkMWRkYmZjZmQiLCJfYXV0aF91c2VyX2JhY2tlbmQiOiJkamFuZ28uY29udHJpYi5hdXRoLmJhY2tlbmRzLk1vZGVsQmFja2VuZCIsIl9hdXRoX3VzZXJfaGFzaCI6Ijg3ZmM3NWRhMjRkYWVjMjdmMGUxMTc5ODYxMzYyYzFhMDliZWI2YTEifQ==', "expire_date" = '2016-11-28 00:24:33.819253' WHERE "django_session"."session_key" = 'n332ybb6udcm6hpyhr4roha4unb4emla'; args=('Y2YzY2ExNWNmMGEwMWM3Mzc2ZGJhZjBiMzM1NDY0ODgzYmQwZjEzZjp7Il9hdXRoX3VzZXJfaWQiOiI5OGM5MjliZS0xOWZiLTQ1OTgtYjMwMi0zM2RkMWRkYmZjZmQiLCJfYXV0aF91c2VyX2JhY2tlbmQiOiJkamFuZ28uY29udHJpYi5hdXRoLmJhY2tlbmRzLk1vZGVsQmFja2VuZCIsIl9hdXRoX3VzZXJfaGFzaCI6Ijg3ZmM3NWRhMjRkYWVjMjdmMGUxMTc5ODYxMzYyYzFhMDliZWI2YTEifQ==', '2016-11-28 00:24:33.819253', 'n332ybb6udcm6hpyhr4roha4unb4emla')
[2016-11-13 19:24:33] DEBUG [django.db.backends:89] (0.000) INSERT INTO "django_session" ("session_key", "session_data", "expire_date") SELECT 'n332ybb6udcm6hpyhr4roha4unb4emla', 'Y2YzY2ExNWNmMGEwMWM3Mzc2ZGJhZjBiMzM1NDY0ODgzYmQwZjEzZjp7Il9hdXRoX3VzZXJfaWQiOiI5OGM5MjliZS0xOWZiLTQ1OTgtYjMwMi0zM2RkMWRkYmZjZmQiLCJfYXV0aF91c2VyX2JhY2tlbmQiOiJkamFuZ28uY29udHJpYi5hdXRoLmJhY2tlbmRzLk1vZGVsQmFja2VuZCIsIl9hdXRoX3VzZXJfaGFzaCI6Ijg3ZmM3NWRhMjRkYWVjMjdmMGUxMTc5ODYxMzYyYzFhMDliZWI2YTEifQ==', '2016-11-28 00:24:33.819253'; args=('n332ybb6udcm6hpyhr4roha4unb4emla', 'Y2YzY2ExNWNmMGEwMWM3Mzc2ZGJhZjBiMzM1NDY0ODgzYmQwZjEzZjp7Il9hdXRoX3VzZXJfaWQiOiI5OGM5MjliZS0xOWZiLTQ1OTgtYjMwMi0zM2RkMWRkYmZjZmQiLCJfYXV0aF91c2VyX2JhY2tlbmQiOiJkamFuZ28uY29udHJpYi5hdXRoLmJhY2tlbmRzLk1vZGVsQmFja2VuZCIsIl9hdXRoX3VzZXJfaGFzaCI6Ijg3ZmM3NWRhMjRkYWVjMjdmMGUxMTc5ODYxMzYyYzFhMDliZWI2YTEifQ==', '2016-11-28 00:24:33.819253')
[2016-11-13 19:24:34] DEBUG [django.db.backends:89] (0.001) SELECT "django_session"."session_key", "django_session"."session_data", "django_session"."expire_date" FROM "django_session" WHERE ("django_session"."expire_date" > '2016-11-14 00:24:34.261483' AND "django_session"."session_key" = 'n332ybb6udcm6hpyhr4roha4unb4emla'); args=('2016-11-14 00:24:34.261483', 'n332ybb6udcm6hpyhr4roha4unb4emla')
[2016-11-13 19:24:34] DEBUG [django.db.backends:89] (0.000) SELECT "auths_user"."password", "auths_user"."last_login", "auths_user"."is_superuser", "auths_user"."username", "auths_user"."first_name", "auths_user"."last_name", "auths_user"."email", "auths_user"."is_staff", "auths_user"."is_active", "auths_user"."date_joined", "auths_user"."id", "auths_user"."last_hierarchy_id", "auths_user"."last_module_id", "auths_user"."person_id", "auths_user"."updated_at", "auths_user"."registered_by" FROM "auths_user" WHERE "auths_user"."id" = '98c929be19fb4598b30233dd1ddbfcfd'; args=('98c929be19fb4598b30233dd1ddbfcfd',)
[2016-11-13 19:24:34] DEBUG [django.template:927] Exception while resolving variable 'is_popup' in template 'admin/index.html'.
Traceback (most recent call last):
  File "C:\Python\Python35\lib\site-packages\django\template\base.py", line 883, in _resolve_lookup
    current = current[bit]
  File "C:\Python\Python35\lib\site-packages\django\template\context.py", line 77, in __getitem__
    raise KeyError(key)
KeyError: 'is_popup'

During handling of the above exception, another exception occurred:

Traceback (most recent call last):
  File "C:\Python\Python35\lib\site-packages\django\template\base.py", line 889, in _resolve_lookup
    if isinstance(current, BaseContext) and getattr(type(current), bit):
AttributeError: type object 'RequestContext' has no attribute 'is_popup'

During handling of the above exception, another exception occurred:

Traceback (most recent call last):
  File "C:\Python\Python35\lib\site-packages\django\template\base.py", line 898, in _resolve_lookup
    current = current[int(bit)]
ValueError: invalid literal for int() with base 10: 'is_popup'

During handling of the above exception, another exception occurred:

Traceback (most recent call last):
  File "C:\Python\Python35\lib\site-packages\django\template\base.py", line 905, in _resolve_lookup
    (bit, current))  # missing attribute
django.template.base.VariableDoesNotExist: Failed lookup for key [is_popup] in "[{'False': False, 'True': True, 'None': None}, {'user': <SimpleLazyObject: <User: admin>>, 'DEFAULT_MESSAGE_LEVELS': {'ERROR': 40, 'INFO': 20, 'SUCCESS': 25, 'WARNING': 30, 'DEBUG': 10}, 'perms': <django.contrib.auth.context_processors.PermWrapper object at 0x000002323D779E80>, 'messages': <django.contrib.messages.storage.fallback.FallbackStorage object at 0x000002323D7A0978>, 'request': <WSGIRequest: GET '/admin/'>, 'csrf_token': <SimpleLazyObject: <function csrf.<locals>._get_val at 0x000002323D796D08>>}, {}, {'site_url': '/', 'LANGUAGE_BIDI': False, 'available_apps': [{'models': [{'add_url': '/admin/asociacion/lote/add/', 'object_name': 'Lote', 'admin_url': '/admin/asociacion/lote/', 'name': 'Lotes', 'perms': {'add': True, 'change': True, 'delete': True}}, {'add_url': '/admin/asociacion/manzana/add/', 'object_name': 'Manzana', 'admin_url': '/admin/asociacion/manzana/', 'name': 'Manzanas', 'perms': {'add': True, 'change': True, 'delete': True}}, {'add_url': '/admin/asociacion/sociolote/add/', 'object_name': 'SocioLote', 'admin_url': '/admin/asociacion/sociolote/', 'name': 'Relacion de socio a lotes', 'perms': {'add': True, 'change': True, 'delete': True}}, {'add_url': '/admin/asociacion/socio/add/', 'object_name': 'Socio', 'admin_url': '/admin/asociacion/socio/', 'name': 'Socios', 'perms': {'add': True, 'change': True, 'delete': True}}], 'name': 'Asociacion', 'has_module_perms': True, 'app_label': 'asociacion', 'app_url': '/admin/asociacion/'}, {'models': [{'add_url': '/admin/auth/group/add/', 'object_name': 'Group', 'admin_url': '/admin/auth/group/', 'name': <django.utils.functional.lazy.<locals>.__proxy__ object at 0x000002323D5D1E80>, 'perms': {'add': True, 'change': True, 'delete': True}}, {'add_url': '/admin/auth/permission/add/', 'object_name': 'Permission', 'admin_url': '/admin/auth/permission/', 'name': <django.utils.functional.lazy.<locals>.__proxy__ object at 0x000002323D78E7B8>, 'perms': {'add': True, 'change': True, 'delete': True}}], 'name': <django.utils.functional.lazy.<locals>.__proxy__ object at 0x000002323C44D9E8>, 'has_module_perms': True, 'app_label': 'auth', 'app_url': '/admin/auth/'}, {'models': [{'add_url': '/admin/auths/hierarchytype/add/', 'object_name': 'HierarchyType', 'admin_url': '/admin/auths/hierarchytype/', 'name': <django.utils.functional.lazy.<locals>.__proxy__ object at 0x000002323D78E8D0>, 'perms': {'add': True, 'change': True, 'delete': True}}, {'add_url': '/admin/auths/hierarchy/add/', 'object_name': 'Hierarchy', 'admin_url': '/admin/auths/hierarchy/', 'name': <django.utils.functional.lazy.<locals>.__proxy__ object at 0x000002323D78EBE0>, 'perms': {'add': True, 'change': True, 'delete': True}}, {'add_url': '/admin/auths/menu/add/', 'object_name': 'Menu', 'admin_url': '/admin/auths/menu/', 'name': <django.utils.functional.lazy.<locals>.__proxy__ object at 0x000002323D78ED68>, 'perms': {'add': True, 'change': True, 'delete': True}}, {'add_url': '/admin/auths/person/add/', 'object_name': 'Person', 'admin_url': '/admin/auths/person/', 'name': <django.utils.functional.lazy.<locals>.__proxy__ object at 0x000002323D78E710>, 'perms': {'add': True, 'change': True, 'delete': True}}, {'add_url': '/admin/auths/userhierarchygroup/add/', 'object_name': 'UserHierarchyGroup', 'admin_url': '/admin/auths/userhierarchygroup/', 'name': <django.utils.functional.lazy.<locals>.__proxy__ object at 0x000002323D78EBA8>, 'perms': {'add': True, 'change': True, 'delete': True}}, {'add_url': '/admin/auths/userhierarchypermission/add/', 'object_name': 'UserHierarchyPermission', 'admin_url': '/admin/auths/userhierarchypermission/', 'name': <django.utils.functional.lazy.<locals>.__proxy__ object at 0x000002323D5D1358>, 'perms': {'add': True, 'change': True, 'delete': True}}, {'add_url': '/admin/auths/user/add/', 'object_name': 'User', 'admin_url': '/admin/auths/user/', 'name': <django.utils.functional.lazy.<locals>.__proxy__ object at 0x000002323D78EB70>, 'perms': {'add': True, 'change': True, 'delete': True}}], 'name': 'Auths', 'has_module_perms': True, 'app_label': 'auths', 'app_url': '/admin/auths/'}, {'models': [{'add_url': '/admin/catalogo/autor/add/', 'object_name': 'Autor', 'admin_url': '/admin/catalogo/autor/', 'name': 'Autores', 'perms': {'add': True, 'change': True, 'delete': True}}, {'add_url': '/admin/catalogo/categoria/add/', 'object_name': 'Categoria', 'admin_url': '/admin/catalogo/categoria/', 'name': 'Categorias', 'perms': {'add': True, 'change': True, 'delete': True}}, {'add_url': '/admin/catalogo/libro/add/', 'object_name': 'Libro', 'admin_url': '/admin/catalogo/libro/', 'name': 'Libros', 'perms': {'add': True, 'change': True, 'delete': True}}], 'name': 'Catalogo', 'has_module_perms': True, 'app_label': 'catalogo', 'app_url': '/admin/catalogo/'}, {'models': [{'add_url': '/admin/contenttypes/contenttype/add/', 'object_name': 'ContentType', 'admin_url': '/admin/contenttypes/contenttype/', 'name': <django.utils.functional.lazy.<locals>.__proxy__ object at 0x000002323D78E898>, 'perms': {'add': True, 'change': True, 'delete': True}}], 'name': <django.utils.functional.lazy.<locals>.__proxy__ object at 0x000002323C455128>, 'has_module_perms': True, 'app_label': 'contenttypes', 'app_url': '/admin/contenttypes/'}, {'models': [{'add_url': '/admin/oauth2_provider/accesstoken/add/', 'object_name': 'AccessToken', 'admin_url': '/admin/oauth2_provider/accesstoken/', 'name': <django.utils.functional.lazy.<locals>.__proxy__ object at 0x000002323D78EC18>, 'perms': {'add': True, 'change': True, 'delete': True}}, {'add_url': '/admin/oauth2_provider/application/add/', 'object_name': 'Application', 'admin_url': '/admin/oauth2_provider/application/', 'name': <django.utils.functional.lazy.<locals>.__proxy__ object at 0x000002323D78EF60>, 'perms': {'add': True, 'change': True, 'delete': True}}, {'add_url': '/admin/oauth2_provider/grant/add/', 'object_name': 'Grant', 'admin_url': '/admin/oauth2_provider/grant/', 'name': <django.utils.functional.lazy.<locals>.__proxy__ object at 0x000002323D78EB00>, 'perms': {'add': True, 'change': True, 'delete': True}}, {'add_url': '/admin/oauth2_provider/refreshtoken/add/', 'object_name': 'RefreshToken', 'admin_url': '/admin/oauth2_provider/refreshtoken/', 'name': <django.utils.functional.lazy.<locals>.__proxy__ object at 0x000002323D78E860>, 'perms': {'add': True, 'change': True, 'delete': True}}], 'name': 'Django OAuth Toolkit', 'has_module_perms': True, 'app_label': 'oauth2_provider', 'app_url': '/admin/oauth2_provider/'}, {'models': [{'add_url': '/admin/eventos/asistencia/add/', 'object_name': 'Asistencia', 'admin_url': '/admin/eventos/asistencia/', 'name': 'Asistencias', 'perms': {'add': True, 'change': True, 'delete': True}}, {'add_url': '/admin/eventos/evento/add/', 'object_name': 'Evento', 'admin_url': '/admin/eventos/evento/', 'name': 'Eventos', 'perms': {'add': True, 'change': True, 'delete': True}}, {'add_url': '/admin/eventos/inasistencia/add/', 'object_name': 'Inasistencia', 'admin_url': '/admin/eventos/inasistencia/', 'name': 'Inasistencias', 'perms': {'add': True, 'change': True, 'delete': True}}], 'name': 'Eventos', 'has_module_perms': True, 'app_label': 'eventos', 'app_url': '/admin/eventos/'}, {'models': [{'add_url': '/admin/pagos/pago/add/', 'object_name': 'Pago', 'admin_url': '/admin/pagos/pago/', 'name': 'Pagos', 'perms': {'add': True, 'change': True, 'delete': True}}, {'add_url': '/admin/pagos/periodo/add/', 'object_name': 'Periodo', 'admin_url': '/admin/pagos/periodo/', 'name': 'Periodos', 'perms': {'add': True, 'change': True, 'delete': True}}], 'name': 'Pagos', 'has_module_perms': True, 'app_label': 'pagos', 'app_url': '/admin/pagos/'}], 'has_permission': True, 'title': <django.utils.functional.lazy.<locals>.__proxy__ object at 0x000002323C44D240>, 'site_header': <django.utils.functional.lazy.<locals>.__proxy__ object at 0x000002323C444DA0>, 'site_title': <django.utils.functional.lazy.<locals>.__proxy__ object at 0x000002323C444CF8>, 'LANGUAGE_CODE': 'en-us', 'app_list': [{'models': [{'add_url': '/admin/asociacion/lote/add/', 'object_name': 'Lote', 'admin_url': '/admin/asociacion/lote/', 'name': 'Lotes', 'perms': {'add': True, 'change': True, 'delete': True}}, {'add_url': '/admin/asociacion/manzana/add/', 'object_name': 'Manzana', 'admin_url': '/admin/asociacion/manzana/', 'name': 'Manzanas', 'perms': {'add': True, 'change': True, 'delete': True}}, {'add_url': '/admin/asociacion/sociolote/add/', 'object_name': 'SocioLote', 'admin_url': '/admin/asociacion/sociolote/', 'name': 'Relacion de socio a lotes', 'perms': {'add': True, 'change': True, 'delete': True}}, {'add_url': '/admin/asociacion/socio/add/', 'object_name': 'Socio', 'admin_url': '/admin/asociacion/socio/', 'name': 'Socios', 'perms': {'add': True, 'change': True, 'delete': True}}], 'name': 'Asociacion', 'has_module_perms': True, 'app_label': 'asociacion', 'app_url': '/admin/asociacion/'}, {'models': [{'add_url': '/admin/auth/group/add/', 'object_name': 'Group', 'admin_url': '/admin/auth/group/', 'name': <django.utils.functional.lazy.<locals>.__proxy__ object at 0x000002323D78EEF0>, 'perms': {'add': True, 'change': True, 'delete': True}}, {'add_url': '/admin/auth/permission/add/', 'object_name': 'Permission', 'admin_url': '/admin/auth/permission/', 'name': <django.utils.functional.lazy.<locals>.__proxy__ object at 0x000002323D7A0630>, 'perms': {'add': True, 'change': True, 'delete': True}}], 'name': <django.utils.functional.lazy.<locals>.__proxy__ object at 0x000002323C44D9E8>, 'has_module_perms': True, 'app_label': 'auth', 'app_url': '/admin/auth/'}, {'models': [{'add_url': '/admin/auths/hierarchytype/add/', 'object_name': 'HierarchyType', 'admin_url': '/admin/auths/hierarchytype/', 'name': <django.utils.functional.lazy.<locals>.__proxy__ object at 0x000002323D7A0240>, 'perms': {'add': True, 'change': True, 'delete': True}}, {'add_url': '/admin/auths/hierarchy/add/', 'object_name': 'Hierarchy', 'admin_url': '/admin/auths/hierarchy/', 'name': <django.utils.functional.lazy.<locals>.__proxy__ object at 0x000002323D7A0208>, 'perms': {'add': True, 'change': True, 'delete': True}}, {'add_url': '/admin/auths/menu/add/', 'object_name': 'Menu', 'admin_url': '/admin/auths/menu/', 'name': <django.utils.functional.lazy.<locals>.__proxy__ object at 0x000002323D7A02B0>, 'perms': {'add': True, 'change': True, 'delete': True}}, {'add_url': '/admin/auths/person/add/', 'object_name': 'Person', 'admin_url': '/admin/auths/person/', 'name': <django.utils.functional.lazy.<locals>.__proxy__ object at 0x000002323D7A03C8>, 'perms': {'add': True, 'change': True, 'delete': True}}, {'add_url': '/admin/auths/userhierarchygroup/add/', 'object_name': 'UserHierarchyGroup', 'admin_url': '/admin/auths/userhierarchygroup/', 'name': <django.utils.functional.lazy.<locals>.__proxy__ object at 0x000002323D7A0160>, 'perms': {'add': True, 'change': True, 'delete': True}}, {'add_url': '/admin/auths/userhierarchypermission/add/', 'object_name': 'UserHierarchyPermission', 'admin_url': '/admin/auths/userhierarchypermission/', 'name': <django.utils.functional.lazy.<locals>.__proxy__ object at 0x000002323D78EFD0>, 'perms': {'add': True, 'change': True, 'delete': True}}, {'add_url': '/admin/auths/user/add/', 'object_name': 'User', 'admin_url': '/admin/auths/user/', 'name': <django.utils.functional.lazy.<locals>.__proxy__ object at 0x000002323D7A06D8>, 'perms': {'add': True, 'change': True, 'delete': True}}], 'name': 'Auths', 'has_module_perms': True, 'app_label': 'auths', 'app_url': '/admin/auths/'}, {'models': [{'add_url': '/admin/catalogo/autor/add/', 'object_name': 'Autor', 'admin_url': '/admin/catalogo/autor/', 'name': 'Autores', 'perms': {'add': True, 'change': True, 'delete': True}}, {'add_url': '/admin/catalogo/categoria/add/', 'object_name': 'Categoria', 'admin_url': '/admin/catalogo/categoria/', 'name': 'Categorias', 'perms': {'add': True, 'change': True, 'delete': True}}, {'add_url': '/admin/catalogo/libro/add/', 'object_name': 'Libro', 'admin_url': '/admin/catalogo/libro/', 'name': 'Libros', 'perms': {'add': True, 'change': True, 'delete': True}}], 'name': 'Catalogo', 'has_module_perms': True, 'app_label': 'catalogo', 'app_url': '/admin/catalogo/'}, {'models': [{'add_url': '/admin/contenttypes/contenttype/add/', 'object_name': 'ContentType', 'admin_url': '/admin/contenttypes/contenttype/', 'name': <django.utils.functional.lazy.<locals>.__proxy__ object at 0x000002323D7A0438>, 'perms': {'add': True, 'change': True, 'delete': True}}], 'name': <django.utils.functional.lazy.<locals>.__proxy__ object at 0x000002323C455128>, 'has_module_perms': True, 'app_label': 'contenttypes', 'app_url': '/admin/contenttypes/'}, {'models': [{'add_url': '/admin/oauth2_provider/accesstoken/add/', 'object_name': 'AccessToken', 'admin_url': '/admin/oauth2_provider/accesstoken/', 'name': <django.utils.functional.lazy.<locals>.__proxy__ object at 0x000002323D7A0198>, 'perms': {'add': True, 'change': True, 'delete': True}}, {'add_url': '/admin/oauth2_provider/application/add/', 'object_name': 'Application', 'admin_url': '/admin/oauth2_provider/application/', 'name': <django.utils.functional.lazy.<locals>.__proxy__ object at 0x000002323D7A04E0>, 'perms': {'add': True, 'change': True, 'delete': True}}, {'add_url': '/admin/oauth2_provider/grant/add/', 'object_name': 'Grant', 'admin_url': '/admin/oauth2_provider/grant/', 'name': <django.utils.functional.lazy.<locals>.__proxy__ object at 0x000002323D7A0898>, 'perms': {'add': True, 'change': True, 'delete': True}}, {'add_url': '/admin/oauth2_provider/refreshtoken/add/', 'object_name': 'RefreshToken', 'admin_url': '/admin/oauth2_provider/refreshtoken/', 'name': <django.utils.functional.lazy.<locals>.__proxy__ object at 0x000002323D7A0400>, 'perms': {'add': True, 'change': True, 'delete': True}}], 'name': 'Django OAuth Toolkit', 'has_module_perms': True, 'app_label': 'oauth2_provider', 'app_url': '/admin/oauth2_provider/'}, {'models': [{'add_url': '/admin/eventos/asistencia/add/', 'object_name': 'Asistencia', 'admin_url': '/admin/eventos/asistencia/', 'name': 'Asistencias', 'perms': {'add': True, 'change': True, 'delete': True}}, {'add_url': '/admin/eventos/evento/add/', 'object_name': 'Evento', 'admin_url': '/admin/eventos/evento/', 'name': 'Eventos', 'perms': {'add': True, 'change': True, 'delete': True}}, {'add_url': '/admin/eventos/inasistencia/add/', 'object_name': 'Inasistencia', 'admin_url': '/admin/eventos/inasistencia/', 'name': 'Inasistencias', 'perms': {'add': True, 'change': True, 'delete': True}}], 'name': 'Eventos', 'has_module_perms': True, 'app_label': 'eventos', 'app_url': '/admin/eventos/'}, {'models': [{'add_url': '/admin/pagos/pago/add/', 'object_name': 'Pago', 'admin_url': '/admin/pagos/pago/', 'name': 'Pagos', 'perms': {'add': True, 'change': True, 'delete': True}}, {'add_url': '/admin/pagos/periodo/add/', 'object_name': 'Periodo', 'admin_url': '/admin/pagos/periodo/', 'name': 'Periodos', 'perms': {'add': True, 'change': True, 'delete': True}}], 'name': 'Pagos', 'has_module_perms': True, 'app_label': 'pagos', 'app_url': '/admin/pagos/'}]}]"
[2016-11-13 19:24:34] DEBUG [django.template:927] Exception while resolving variable 'is_popup' in template 'admin/index.html'.
Traceback (most recent call last):
  File "C:\Python\Python35\lib\site-packages\django\template\base.py", line 883, in _resolve_lookup
    current = current[bit]
  File "C:\Python\Python35\lib\site-packages\django\template\context.py", line 77, in __getitem__
    raise KeyError(key)
KeyError: 'is_popup'

During handling of the above exception, another exception occurred:

Traceback (most recent call last):
  File "C:\Python\Python35\lib\site-packages\django\template\base.py", line 889, in _resolve_lookup
    if isinstance(current, BaseContext) and getattr(type(current), bit):
AttributeError: type object 'RequestContext' has no attribute 'is_popup'

During handling of the above exception, another exception occurred:

Traceback (most recent call last):
  File "C:\Python\Python35\lib\site-packages\django\template\base.py", line 898, in _resolve_lookup
    current = current[int(bit)]
ValueError: invalid literal for int() with base 10: 'is_popup'

During handling of the above exception, another exception occurred:

Traceback (most recent call last):
  File "C:\Python\Python35\lib\site-packages\django\template\base.py", line 905, in _resolve_lookup
    (bit, current))  # missing attribute
django.template.base.VariableDoesNotExist: Failed lookup for key [is_popup] in "[{'False': False, 'True': True, 'None': None}, {'user': <SimpleLazyObject: <User: admin>>, 'DEFAULT_MESSAGE_LEVELS': {'ERROR': 40, 'INFO': 20, 'SUCCESS': 25, 'WARNING': 30, 'DEBUG': 10}, 'perms': <django.contrib.auth.context_processors.PermWrapper object at 0x000002323D779E80>, 'messages': <django.contrib.messages.storage.fallback.FallbackStorage object at 0x000002323D7A0978>, 'request': <WSGIRequest: GET '/admin/'>, 'csrf_token': <SimpleLazyObject: <function csrf.<locals>._get_val at 0x000002323D796D08>>}, {}, {'site_url': '/', 'LANGUAGE_BIDI': False, 'available_apps': [{'models': [{'add_url': '/admin/asociacion/lote/add/', 'object_name': 'Lote', 'admin_url': '/admin/asociacion/lote/', 'name': 'Lotes', 'perms': {'add': True, 'change': True, 'delete': True}}, {'add_url': '/admin/asociacion/manzana/add/', 'object_name': 'Manzana', 'admin_url': '/admin/asociacion/manzana/', 'name': 'Manzanas', 'perms': {'add': True, 'change': True, 'delete': True}}, {'add_url': '/admin/asociacion/sociolote/add/', 'object_name': 'SocioLote', 'admin_url': '/admin/asociacion/sociolote/', 'name': 'Relacion de socio a lotes', 'perms': {'add': True, 'change': True, 'delete': True}}, {'add_url': '/admin/asociacion/socio/add/', 'object_name': 'Socio', 'admin_url': '/admin/asociacion/socio/', 'name': 'Socios', 'perms': {'add': True, 'change': True, 'delete': True}}], 'name': 'Asociacion', 'has_module_perms': True, 'app_label': 'asociacion', 'app_url': '/admin/asociacion/'}, {'models': [{'add_url': '/admin/auth/group/add/', 'object_name': 'Group', 'admin_url': '/admin/auth/group/', 'name': <django.utils.functional.lazy.<locals>.__proxy__ object at 0x000002323D5D1E80>, 'perms': {'add': True, 'change': True, 'delete': True}}, {'add_url': '/admin/auth/permission/add/', 'object_name': 'Permission', 'admin_url': '/admin/auth/permission/', 'name': <django.utils.functional.lazy.<locals>.__proxy__ object at 0x000002323D78E7B8>, 'perms': {'add': True, 'change': True, 'delete': True}}], 'name': <django.utils.functional.lazy.<locals>.__proxy__ object at 0x000002323C44D9E8>, 'has_module_perms': True, 'app_label': 'auth', 'app_url': '/admin/auth/'}, {'models': [{'add_url': '/admin/auths/hierarchytype/add/', 'object_name': 'HierarchyType', 'admin_url': '/admin/auths/hierarchytype/', 'name': <django.utils.functional.lazy.<locals>.__proxy__ object at 0x000002323D78E8D0>, 'perms': {'add': True, 'change': True, 'delete': True}}, {'add_url': '/admin/auths/hierarchy/add/', 'object_name': 'Hierarchy', 'admin_url': '/admin/auths/hierarchy/', 'name': <django.utils.functional.lazy.<locals>.__proxy__ object at 0x000002323D78EBE0>, 'perms': {'add': True, 'change': True, 'delete': True}}, {'add_url': '/admin/auths/menu/add/', 'object_name': 'Menu', 'admin_url': '/admin/auths/menu/', 'name': <django.utils.functional.lazy.<locals>.__proxy__ object at 0x000002323D78ED68>, 'perms': {'add': True, 'change': True, 'delete': True}}, {'add_url': '/admin/auths/person/add/', 'object_name': 'Person', 'admin_url': '/admin/auths/person/', 'name': <django.utils.functional.lazy.<locals>.__proxy__ object at 0x000002323D78E710>, 'perms': {'add': True, 'change': True, 'delete': True}}, {'add_url': '/admin/auths/userhierarchygroup/add/', 'object_name': 'UserHierarchyGroup', 'admin_url': '/admin/auths/userhierarchygroup/', 'name': <django.utils.functional.lazy.<locals>.__proxy__ object at 0x000002323D78EBA8>, 'perms': {'add': True, 'change': True, 'delete': True}}, {'add_url': '/admin/auths/userhierarchypermission/add/', 'object_name': 'UserHierarchyPermission', 'admin_url': '/admin/auths/userhierarchypermission/', 'name': <django.utils.functional.lazy.<locals>.__proxy__ object at 0x000002323D5D1358>, 'perms': {'add': True, 'change': True, 'delete': True}}, {'add_url': '/admin/auths/user/add/', 'object_name': 'User', 'admin_url': '/admin/auths/user/', 'name': <django.utils.functional.lazy.<locals>.__proxy__ object at 0x000002323D78EB70>, 'perms': {'add': True, 'change': True, 'delete': True}}], 'name': 'Auths', 'has_module_perms': True, 'app_label': 'auths', 'app_url': '/admin/auths/'}, {'models': [{'add_url': '/admin/catalogo/autor/add/', 'object_name': 'Autor', 'admin_url': '/admin/catalogo/autor/', 'name': 'Autores', 'perms': {'add': True, 'change': True, 'delete': True}}, {'add_url': '/admin/catalogo/categoria/add/', 'object_name': 'Categoria', 'admin_url': '/admin/catalogo/categoria/', 'name': 'Categorias', 'perms': {'add': True, 'change': True, 'delete': True}}, {'add_url': '/admin/catalogo/libro/add/', 'object_name': 'Libro', 'admin_url': '/admin/catalogo/libro/', 'name': 'Libros', 'perms': {'add': True, 'change': True, 'delete': True}}], 'name': 'Catalogo', 'has_module_perms': True, 'app_label': 'catalogo', 'app_url': '/admin/catalogo/'}, {'models': [{'add_url': '/admin/contenttypes/contenttype/add/', 'object_name': 'ContentType', 'admin_url': '/admin/contenttypes/contenttype/', 'name': <django.utils.functional.lazy.<locals>.__proxy__ object at 0x000002323D78E898>, 'perms': {'add': True, 'change': True, 'delete': True}}], 'name': <django.utils.functional.lazy.<locals>.__proxy__ object at 0x000002323C455128>, 'has_module_perms': True, 'app_label': 'contenttypes', 'app_url': '/admin/contenttypes/'}, {'models': [{'add_url': '/admin/oauth2_provider/accesstoken/add/', 'object_name': 'AccessToken', 'admin_url': '/admin/oauth2_provider/accesstoken/', 'name': <django.utils.functional.lazy.<locals>.__proxy__ object at 0x000002323D78EC18>, 'perms': {'add': True, 'change': True, 'delete': True}}, {'add_url': '/admin/oauth2_provider/application/add/', 'object_name': 'Application', 'admin_url': '/admin/oauth2_provider/application/', 'name': <django.utils.functional.lazy.<locals>.__proxy__ object at 0x000002323D78EF60>, 'perms': {'add': True, 'change': True, 'delete': True}}, {'add_url': '/admin/oauth2_provider/grant/add/', 'object_name': 'Grant', 'admin_url': '/admin/oauth2_provider/grant/', 'name': <django.utils.functional.lazy.<locals>.__proxy__ object at 0x000002323D78EB00>, 'perms': {'add': True, 'change': True, 'delete': True}}, {'add_url': '/admin/oauth2_provider/refreshtoken/add/', 'object_name': 'RefreshToken', 'admin_url': '/admin/oauth2_provider/refreshtoken/', 'name': <django.utils.functional.lazy.<locals>.__proxy__ object at 0x000002323D78E860>, 'perms': {'add': True, 'change': True, 'delete': True}}], 'name': 'Django OAuth Toolkit', 'has_module_perms': True, 'app_label': 'oauth2_provider', 'app_url': '/admin/oauth2_provider/'}, {'models': [{'add_url': '/admin/eventos/asistencia/add/', 'object_name': 'Asistencia', 'admin_url': '/admin/eventos/asistencia/', 'name': 'Asistencias', 'perms': {'add': True, 'change': True, 'delete': True}}, {'add_url': '/admin/eventos/evento/add/', 'object_name': 'Evento', 'admin_url': '/admin/eventos/evento/', 'name': 'Eventos', 'perms': {'add': True, 'change': True, 'delete': True}}, {'add_url': '/admin/eventos/inasistencia/add/', 'object_name': 'Inasistencia', 'admin_url': '/admin/eventos/inasistencia/', 'name': 'Inasistencias', 'perms': {'add': True, 'change': True, 'delete': True}}], 'name': 'Eventos', 'has_module_perms': True, 'app_label': 'eventos', 'app_url': '/admin/eventos/'}, {'models': [{'add_url': '/admin/pagos/pago/add/', 'object_name': 'Pago', 'admin_url': '/admin/pagos/pago/', 'name': 'Pagos', 'perms': {'add': True, 'change': True, 'delete': True}}, {'add_url': '/admin/pagos/periodo/add/', 'object_name': 'Periodo', 'admin_url': '/admin/pagos/periodo/', 'name': 'Periodos', 'perms': {'add': True, 'change': True, 'delete': True}}], 'name': 'Pagos', 'has_module_perms': True, 'app_label': 'pagos', 'app_url': '/admin/pagos/'}], 'has_permission': True, 'title': <django.utils.functional.lazy.<locals>.__proxy__ object at 0x000002323C44D240>, 'site_header': <django.utils.functional.lazy.<locals>.__proxy__ object at 0x000002323C444DA0>, 'site_title': <django.utils.functional.lazy.<locals>.__proxy__ object at 0x000002323C444CF8>, 'LANGUAGE_CODE': 'en-us', 'app_list': [{'models': [{'add_url': '/admin/asociacion/lote/add/', 'object_name': 'Lote', 'admin_url': '/admin/asociacion/lote/', 'name': 'Lotes', 'perms': {'add': True, 'change': True, 'delete': True}}, {'add_url': '/admin/asociacion/manzana/add/', 'object_name': 'Manzana', 'admin_url': '/admin/asociacion/manzana/', 'name': 'Manzanas', 'perms': {'add': True, 'change': True, 'delete': True}}, {'add_url': '/admin/asociacion/sociolote/add/', 'object_name': 'SocioLote', 'admin_url': '/admin/asociacion/sociolote/', 'name': 'Relacion de socio a lotes', 'perms': {'add': True, 'change': True, 'delete': True}}, {'add_url': '/admin/asociacion/socio/add/', 'object_name': 'Socio', 'admin_url': '/admin/asociacion/socio/', 'name': 'Socios', 'perms': {'add': True, 'change': True, 'delete': True}}], 'name': 'Asociacion', 'has_module_perms': True, 'app_label': 'asociacion', 'app_url': '/admin/asociacion/'}, {'models': [{'add_url': '/admin/auth/group/add/', 'object_name': 'Group', 'admin_url': '/admin/auth/group/', 'name': <django.utils.functional.lazy.<locals>.__proxy__ object at 0x000002323D78EEF0>, 'perms': {'add': True, 'change': True, 'delete': True}}, {'add_url': '/admin/auth/permission/add/', 'object_name': 'Permission', 'admin_url': '/admin/auth/permission/', 'name': <django.utils.functional.lazy.<locals>.__proxy__ object at 0x000002323D7A0630>, 'perms': {'add': True, 'change': True, 'delete': True}}], 'name': <django.utils.functional.lazy.<locals>.__proxy__ object at 0x000002323C44D9E8>, 'has_module_perms': True, 'app_label': 'auth', 'app_url': '/admin/auth/'}, {'models': [{'add_url': '/admin/auths/hierarchytype/add/', 'object_name': 'HierarchyType', 'admin_url': '/admin/auths/hierarchytype/', 'name': <django.utils.functional.lazy.<locals>.__proxy__ object at 0x000002323D7A0240>, 'perms': {'add': True, 'change': True, 'delete': True}}, {'add_url': '/admin/auths/hierarchy/add/', 'object_name': 'Hierarchy', 'admin_url': '/admin/auths/hierarchy/', 'name': <django.utils.functional.lazy.<locals>.__proxy__ object at 0x000002323D7A0208>, 'perms': {'add': True, 'change': True, 'delete': True}}, {'add_url': '/admin/auths/menu/add/', 'object_name': 'Menu', 'admin_url': '/admin/auths/menu/', 'name': <django.utils.functional.lazy.<locals>.__proxy__ object at 0x000002323D7A02B0>, 'perms': {'add': True, 'change': True, 'delete': True}}, {'add_url': '/admin/auths/person/add/', 'object_name': 'Person', 'admin_url': '/admin/auths/person/', 'name': <django.utils.functional.lazy.<locals>.__proxy__ object at 0x000002323D7A03C8>, 'perms': {'add': True, 'change': True, 'delete': True}}, {'add_url': '/admin/auths/userhierarchygroup/add/', 'object_name': 'UserHierarchyGroup', 'admin_url': '/admin/auths/userhierarchygroup/', 'name': <django.utils.functional.lazy.<locals>.__proxy__ object at 0x000002323D7A0160>, 'perms': {'add': True, 'change': True, 'delete': True}}, {'add_url': '/admin/auths/userhierarchypermission/add/', 'object_name': 'UserHierarchyPermission', 'admin_url': '/admin/auths/userhierarchypermission/', 'name': <django.utils.functional.lazy.<locals>.__proxy__ object at 0x000002323D78EFD0>, 'perms': {'add': True, 'change': True, 'delete': True}}, {'add_url': '/admin/auths/user/add/', 'object_name': 'User', 'admin_url': '/admin/auths/user/', 'name': <django.utils.functional.lazy.<locals>.__proxy__ object at 0x000002323D7A06D8>, 'perms': {'add': True, 'change': True, 'delete': True}}], 'name': 'Auths', 'has_module_perms': True, 'app_label': 'auths', 'app_url': '/admin/auths/'}, {'models': [{'add_url': '/admin/catalogo/autor/add/', 'object_name': 'Autor', 'admin_url': '/admin/catalogo/autor/', 'name': 'Autores', 'perms': {'add': True, 'change': True, 'delete': True}}, {'add_url': '/admin/catalogo/categoria/add/', 'object_name': 'Categoria', 'admin_url': '/admin/catalogo/categoria/', 'name': 'Categorias', 'perms': {'add': True, 'change': True, 'delete': True}}, {'add_url': '/admin/catalogo/libro/add/', 'object_name': 'Libro', 'admin_url': '/admin/catalogo/libro/', 'name': 'Libros', 'perms': {'add': True, 'change': True, 'delete': True}}], 'name': 'Catalogo', 'has_module_perms': True, 'app_label': 'catalogo', 'app_url': '/admin/catalogo/'}, {'models': [{'add_url': '/admin/contenttypes/contenttype/add/', 'object_name': 'ContentType', 'admin_url': '/admin/contenttypes/contenttype/', 'name': <django.utils.functional.lazy.<locals>.__proxy__ object at 0x000002323D7A0438>, 'perms': {'add': True, 'change': True, 'delete': True}}], 'name': <django.utils.functional.lazy.<locals>.__proxy__ object at 0x000002323C455128>, 'has_module_perms': True, 'app_label': 'contenttypes', 'app_url': '/admin/contenttypes/'}, {'models': [{'add_url': '/admin/oauth2_provider/accesstoken/add/', 'object_name': 'AccessToken', 'admin_url': '/admin/oauth2_provider/accesstoken/', 'name': <django.utils.functional.lazy.<locals>.__proxy__ object at 0x000002323D7A0198>, 'perms': {'add': True, 'change': True, 'delete': True}}, {'add_url': '/admin/oauth2_provider/application/add/', 'object_name': 'Application', 'admin_url': '/admin/oauth2_provider/application/', 'name': <django.utils.functional.lazy.<locals>.__proxy__ object at 0x000002323D7A04E0>, 'perms': {'add': True, 'change': True, 'delete': True}}, {'add_url': '/admin/oauth2_provider/grant/add/', 'object_name': 'Grant', 'admin_url': '/admin/oauth2_provider/grant/', 'name': <django.utils.functional.lazy.<locals>.__proxy__ object at 0x000002323D7A0898>, 'perms': {'add': True, 'change': True, 'delete': True}}, {'add_url': '/admin/oauth2_provider/refreshtoken/add/', 'object_name': 'RefreshToken', 'admin_url': '/admin/oauth2_provider/refreshtoken/', 'name': <django.utils.functional.lazy.<locals>.__proxy__ object at 0x000002323D7A0400>, 'perms': {'add': True, 'change': True, 'delete': True}}], 'name': 'Django OAuth Toolkit', 'has_module_perms': True, 'app_label': 'oauth2_provider', 'app_url': '/admin/oauth2_provider/'}, {'models': [{'add_url': '/admin/eventos/asistencia/add/', 'object_name': 'Asistencia', 'admin_url': '/admin/eventos/asistencia/', 'name': 'Asistencias', 'perms': {'add': True, 'change': True, 'delete': True}}, {'add_url': '/admin/eventos/evento/add/', 'object_name': 'Evento', 'admin_url': '/admin/eventos/evento/', 'name': 'Eventos', 'perms': {'add': True, 'change': True, 'delete': True}}, {'add_url': '/admin/eventos/inasistencia/add/', 'object_name': 'Inasistencia', 'admin_url': '/admin/eventos/inasistencia/', 'name': 'Inasistencias', 'perms': {'add': True, 'change': True, 'delete': True}}], 'name': 'Eventos', 'has_module_perms': True, 'app_label': 'eventos', 'app_url': '/admin/eventos/'}, {'models': [{'add_url': '/admin/pagos/pago/add/', 'object_name': 'Pago', 'admin_url': '/admin/pagos/pago/', 'name': 'Pagos', 'perms': {'add': True, 'change': True, 'delete': True}}, {'add_url': '/admin/pagos/periodo/add/', 'object_name': 'Periodo', 'admin_url': '/admin/pagos/periodo/', 'name': 'Periodos', 'perms': {'add': True, 'change': True, 'delete': True}}], 'name': 'Pagos', 'has_module_perms': True, 'app_label': 'pagos', 'app_url': '/admin/pagos/'}]}]"
[2016-11-13 19:24:34] DEBUG [django.db.backends:89] (0.021) SELECT "django_admin_log"."id", "django_admin_log"."action_time", "django_admin_log"."user_id", "django_admin_log"."content_type_id", "django_admin_log"."object_id", "django_admin_log"."object_repr", "django_admin_log"."action_flag", "django_admin_log"."change_message", "auths_user"."password", "auths_user"."last_login", "auths_user"."is_superuser", "auths_user"."username", "auths_user"."first_name", "auths_user"."last_name", "auths_user"."email", "auths_user"."is_staff", "auths_user"."is_active", "auths_user"."date_joined", "auths_user"."id", "auths_user"."last_hierarchy_id", "auths_user"."last_module_id", "auths_user"."person_id", "auths_user"."updated_at", "auths_user"."registered_by", "django_content_type"."id", "django_content_type"."app_label", "django_content_type"."model" FROM "django_admin_log" INNER JOIN "auths_user" ON ("django_admin_log"."user_id" = "auths_user"."id") LEFT OUTER JOIN "django_content_type" ON ("django_admin_log"."content_type_id" = "django_content_type"."id") WHERE "django_admin_log"."user_id" = '98c929be19fb4598b30233dd1ddbfcfd' ORDER BY "django_admin_log"."action_time" DESC LIMIT 10; args=('98c929be19fb4598b30233dd1ddbfcfd',)
[2016-11-13 19:42:26] DEBUG [django.db.backends:89] (0.043) 
            SELECT name, type FROM sqlite_master
            WHERE type in ('table', 'view') AND NOT name='sqlite_sequence'
            ORDER BY name; args=None
[2016-11-13 19:42:26] DEBUG [django.db.backends:89] (0.001) SELECT "django_migrations"."app", "django_migrations"."name" FROM "django_migrations"; args=()
[2016-11-13 19:42:29] DEBUG [django.db.backends:89] (0.001) SELECT "oauth2_provider_application"."id", "oauth2_provider_application"."client_id", "oauth2_provider_application"."user_id", "oauth2_provider_application"."redirect_uris", "oauth2_provider_application"."client_type", "oauth2_provider_application"."authorization_grant_type", "oauth2_provider_application"."client_secret", "oauth2_provider_application"."name", "oauth2_provider_application"."skip_authorization" FROM "oauth2_provider_application" WHERE "oauth2_provider_application"."client_id" = '1mDR3zdKmNxeMHoqSJfOfX4JBwSvw93zRK2GaZ61'; args=('1mDR3zdKmNxeMHoqSJfOfX4JBwSvw93zRK2GaZ61',)
[2016-11-13 19:42:29] DEBUG [django.db.backends:89] (0.025) SELECT "auths_user"."password", "auths_user"."last_login", "auths_user"."is_superuser", "auths_user"."username", "auths_user"."first_name", "auths_user"."last_name", "auths_user"."email", "auths_user"."is_staff", "auths_user"."is_active", "auths_user"."date_joined", "auths_user"."id", "auths_user"."last_hierarchy_id", "auths_user"."last_module_id", "auths_user"."person_id", "auths_user"."updated_at", "auths_user"."registered_by" FROM "auths_user" WHERE "auths_user"."username" = 'admin'; args=('admin',)
[2016-11-13 19:42:29] DEBUG [django.db.backends:89] (0.000) BEGIN; args=None
[2016-11-13 19:42:29] DEBUG [django.db.backends:89] (0.002) INSERT INTO "oauth2_provider_accesstoken" ("user_id", "token", "application_id", "expires", "scope") VALUES ('98c929be19fb4598b30233dd1ddbfcfd', '2uxkm7mPmmY3dgfXi9BELQYb4sqPdD', 1, '2016-11-14 10:42:29.925308', 'read write'); args=['98c929be19fb4598b30233dd1ddbfcfd', '2uxkm7mPmmY3dgfXi9BELQYb4sqPdD', 1, '2016-11-14 10:42:29.925308', 'read write']
[2016-11-13 19:42:30] DEBUG [django.db.backends:89] (0.000) BEGIN; args=None
[2016-11-13 19:42:30] DEBUG [django.db.backends:89] (0.001) INSERT INTO "oauth2_provider_refreshtoken" ("user_id", "token", "application_id", "access_token_id") VALUES ('98c929be19fb4598b30233dd1ddbfcfd', 'Qve4aYEYYbSMdl55ENBaC1uHBod56e', 1, 31); args=['98c929be19fb4598b30233dd1ddbfcfd', 'Qve4aYEYYbSMdl55ENBaC1uHBod56e', 1, 31]
[2016-11-13 19:42:31] DEBUG [django.db.backends:89] (0.002) SELECT "auths_user"."password", "auths_user"."last_login", "auths_user"."is_superuser", "auths_user"."username", "auths_user"."first_name", "auths_user"."last_name", "auths_user"."email", "auths_user"."is_staff", "auths_user"."is_active", "auths_user"."date_joined", "auths_user"."id", "auths_user"."last_hierarchy_id", "auths_user"."last_module_id", "auths_user"."person_id", "auths_user"."updated_at", "auths_user"."registered_by" FROM "auths_user" WHERE "auths_user"."username" IS NULL; args=()
[2016-11-13 19:42:31] DEBUG [django.db.backends:89] (0.002) SELECT "oauth2_provider_accesstoken"."id", "oauth2_provider_accesstoken"."user_id", "oauth2_provider_accesstoken"."token", "oauth2_provider_accesstoken"."application_id", "oauth2_provider_accesstoken"."expires", "oauth2_provider_accesstoken"."scope", "auths_user"."password", "auths_user"."last_login", "auths_user"."is_superuser", "auths_user"."username", "auths_user"."first_name", "auths_user"."last_name", "auths_user"."email", "auths_user"."is_staff", "auths_user"."is_active", "auths_user"."date_joined", "auths_user"."id", "auths_user"."last_hierarchy_id", "auths_user"."last_module_id", "auths_user"."person_id", "auths_user"."updated_at", "auths_user"."registered_by", "oauth2_provider_application"."id", "oauth2_provider_application"."client_id", "oauth2_provider_application"."user_id", "oauth2_provider_application"."redirect_uris", "oauth2_provider_application"."client_type", "oauth2_provider_application"."authorization_grant_type", "oauth2_provider_application"."client_secret", "oauth2_provider_application"."name", "oauth2_provider_application"."skip_authorization" FROM "oauth2_provider_accesstoken" LEFT OUTER JOIN "auths_user" ON ("oauth2_provider_accesstoken"."user_id" = "auths_user"."id") INNER JOIN "oauth2_provider_application" ON ("oauth2_provider_accesstoken"."application_id" = "oauth2_provider_application"."id") WHERE "oauth2_provider_accesstoken"."token" = '2uxkm7mPmmY3dgfXi9BELQYb4sqPdD'; args=('2uxkm7mPmmY3dgfXi9BELQYb4sqPdD',)
[2016-11-13 19:42:31] DEBUG [django.db.backends:89] (0.000) SELECT "auth_group"."id", "auth_group"."name" FROM "auth_group" INNER JOIN "auths_user_groups" ON ("auth_group"."id" = "auths_user_groups"."group_id") WHERE "auths_user_groups"."user_id" = '98c929be19fb4598b30233dd1ddbfcfd'; args=('98c929be19fb4598b30233dd1ddbfcfd',)
[2016-11-13 19:42:31] DEBUG [django.db.backends:89] (0.001) SELECT "auth_permission"."id", "auth_permission"."name", "auth_permission"."content_type_id", "auth_permission"."codename" FROM "auth_permission" INNER JOIN "auths_user_user_permissions" ON ("auth_permission"."id" = "auths_user_user_permissions"."permission_id") INNER JOIN "django_content_type" ON ("auth_permission"."content_type_id" = "django_content_type"."id") WHERE "auths_user_user_permissions"."user_id" = '98c929be19fb4598b30233dd1ddbfcfd' ORDER BY "django_content_type"."app_label" ASC, "django_content_type"."model" ASC, "auth_permission"."codename" ASC; args=('98c929be19fb4598b30233dd1ddbfcfd',)
[2016-11-13 19:42:31] DEBUG [django.db.backends:89] (0.002) SELECT "auths_user"."password", "auths_user"."last_login", "auths_user"."is_superuser", "auths_user"."username", "auths_user"."first_name", "auths_user"."last_name", "auths_user"."email", "auths_user"."is_staff", "auths_user"."is_active", "auths_user"."date_joined", "auths_user"."id", "auths_user"."last_hierarchy_id", "auths_user"."last_module_id", "auths_user"."person_id", "auths_user"."updated_at", "auths_user"."registered_by" FROM "auths_user" WHERE "auths_user"."username" IS NULL; args=()
[2016-11-13 19:42:31] DEBUG [django.db.backends:89] (0.000) SELECT "oauth2_provider_accesstoken"."id", "oauth2_provider_accesstoken"."user_id", "oauth2_provider_accesstoken"."token", "oauth2_provider_accesstoken"."application_id", "oauth2_provider_accesstoken"."expires", "oauth2_provider_accesstoken"."scope", "auths_user"."password", "auths_user"."last_login", "auths_user"."is_superuser", "auths_user"."username", "auths_user"."first_name", "auths_user"."last_name", "auths_user"."email", "auths_user"."is_staff", "auths_user"."is_active", "auths_user"."date_joined", "auths_user"."id", "auths_user"."last_hierarchy_id", "auths_user"."last_module_id", "auths_user"."person_id", "auths_user"."updated_at", "auths_user"."registered_by", "oauth2_provider_application"."id", "oauth2_provider_application"."client_id", "oauth2_provider_application"."user_id", "oauth2_provider_application"."redirect_uris", "oauth2_provider_application"."client_type", "oauth2_provider_application"."authorization_grant_type", "oauth2_provider_application"."client_secret", "oauth2_provider_application"."name", "oauth2_provider_application"."skip_authorization" FROM "oauth2_provider_accesstoken" LEFT OUTER JOIN "auths_user" ON ("oauth2_provider_accesstoken"."user_id" = "auths_user"."id") INNER JOIN "oauth2_provider_application" ON ("oauth2_provider_accesstoken"."application_id" = "oauth2_provider_application"."id") WHERE "oauth2_provider_accesstoken"."token" = '2uxkm7mPmmY3dgfXi9BELQYb4sqPdD'; args=('2uxkm7mPmmY3dgfXi9BELQYb4sqPdD',)
[2016-11-13 19:42:31] DEBUG [django.db.backends:89] (0.010) SELECT "auths_menu"."id" FROM "auths_menu" WHERE ("auths_menu"."id" IS NOT NULL AND "auths_menu"."is_active" = 1 AND "auths_menu"."module" = 'BACKEND') ORDER BY "auths_menu"."pos" ASC; args=(True, 'BACKEND')
[2016-11-13 19:42:31] DEBUG [django.db.backends:89] (0.001) SELECT DISTINCT "auths_menu"."id", "auths_menu"."module", "auths_menu"."state", "auths_menu"."title", "auths_menu"."url", "auths_menu"."template_url", "auths_menu"."pos", "auths_menu"."icon", "auths_menu"."is_active", "auths_menu"."is_abstract", "auths_menu"."description", "auths_menu"."permission_id", "auths_menu"."parent_id", "auths_menu"."created_at", "auths_menu"."updated_at", "auths_menu"."registered_by" FROM "auths_menu" INNER JOIN "auths_menu" T2 ON ("auths_menu"."id" = T2."parent_id") WHERE ("auths_menu"."is_active" = 1 AND T2."id" IN ('b479e020c80844478293cf7e1320fa5b', '89e73f9bfbde41d3aa4e612f2a2d2d00') AND "auths_menu"."module" = 'BACKEND') ORDER BY "auths_menu"."pos" ASC; args=(True, 'b479e020c80844478293cf7e1320fa5b', '89e73f9bfbde41d3aa4e612f2a2d2d00', 'BACKEND')
[2016-11-13 19:42:31] DEBUG [django.db.backends:89] (0.000) SELECT "auths_menu"."id", "auths_menu"."module", "auths_menu"."state", "auths_menu"."title", "auths_menu"."url", "auths_menu"."template_url", "auths_menu"."pos", "auths_menu"."icon", "auths_menu"."is_active", "auths_menu"."is_abstract", "auths_menu"."description", "auths_menu"."permission_id", "auths_menu"."parent_id", "auths_menu"."created_at", "auths_menu"."updated_at", "auths_menu"."registered_by" FROM "auths_menu" WHERE ("auths_menu"."id" IS NOT NULL AND "auths_menu"."is_active" = 1 AND "auths_menu"."module" = 'BACKEND' AND "auths_menu"."parent_id" = 'b479e020c80844478293cf7e1320fa5b') ORDER BY "auths_menu"."pos" ASC; args=(True, 'BACKEND', 'b479e020c80844478293cf7e1320fa5b')
[2016-11-13 19:42:31] DEBUG [django.db.backends:89] (0.000) SELECT "auths_menu"."id", "auths_menu"."module", "auths_menu"."state", "auths_menu"."title", "auths_menu"."url", "auths_menu"."template_url", "auths_menu"."pos", "auths_menu"."icon", "auths_menu"."is_active", "auths_menu"."is_abstract", "auths_menu"."description", "auths_menu"."permission_id", "auths_menu"."parent_id", "auths_menu"."created_at", "auths_menu"."updated_at", "auths_menu"."registered_by" FROM "auths_menu" WHERE "auths_menu"."id" = 'b479e020c80844478293cf7e1320fa5b'; args=('b479e020c80844478293cf7e1320fa5b',)
[2016-11-13 19:42:31] DEBUG [django.db.backends:89] (0.005) SELECT (1) AS "a" FROM "django_session" WHERE "django_session"."session_key" = 'nxnukhwv9w5undblt19228b912k4yv34' LIMIT 1; args=('nxnukhwv9w5undblt19228b912k4yv34',)
[2016-11-13 19:42:31] DEBUG [django.db.backends:89] (0.000) BEGIN; args=None
[2016-11-13 19:42:31] DEBUG [django.db.backends:89] (0.001) INSERT INTO "django_session" ("session_key", "session_data", "expire_date") SELECT 'nxnukhwv9w5undblt19228b912k4yv34', 'ZWMyMmE2MTA1MzM3NDcxZTRmYzk5YzliZTNiYjg2ZTZkMjFlMTc0NTp7Il9zZXNzaW9uX2V4cGlyeSI6MzB9', '2016-11-14 00:43:01.819832'; args=('nxnukhwv9w5undblt19228b912k4yv34', 'ZWMyMmE2MTA1MzM3NDcxZTRmYzk5YzliZTNiYjg2ZTZkMjFlMTc0NTp7Il9zZXNzaW9uX2V4cGlyeSI6MzB9', '2016-11-14 00:43:01.819832')
[2016-11-13 19:42:37] DEBUG [django.db.backends:89] (0.001) SELECT "auths_user"."password", "auths_user"."last_login", "auths_user"."is_superuser", "auths_user"."username", "auths_user"."first_name", "auths_user"."last_name", "auths_user"."email", "auths_user"."is_staff", "auths_user"."is_active", "auths_user"."date_joined", "auths_user"."id", "auths_user"."last_hierarchy_id", "auths_user"."last_module_id", "auths_user"."person_id", "auths_user"."updated_at", "auths_user"."registered_by" FROM "auths_user" WHERE "auths_user"."username" IS NULL; args=()
[2016-11-13 19:42:37] DEBUG [django.db.backends:89] (0.000) SELECT "oauth2_provider_accesstoken"."id", "oauth2_provider_accesstoken"."user_id", "oauth2_provider_accesstoken"."token", "oauth2_provider_accesstoken"."application_id", "oauth2_provider_accesstoken"."expires", "oauth2_provider_accesstoken"."scope", "auths_user"."password", "auths_user"."last_login", "auths_user"."is_superuser", "auths_user"."username", "auths_user"."first_name", "auths_user"."last_name", "auths_user"."email", "auths_user"."is_staff", "auths_user"."is_active", "auths_user"."date_joined", "auths_user"."id", "auths_user"."last_hierarchy_id", "auths_user"."last_module_id", "auths_user"."person_id", "auths_user"."updated_at", "auths_user"."registered_by", "oauth2_provider_application"."id", "oauth2_provider_application"."client_id", "oauth2_provider_application"."user_id", "oauth2_provider_application"."redirect_uris", "oauth2_provider_application"."client_type", "oauth2_provider_application"."authorization_grant_type", "oauth2_provider_application"."client_secret", "oauth2_provider_application"."name", "oauth2_provider_application"."skip_authorization" FROM "oauth2_provider_accesstoken" LEFT OUTER JOIN "auths_user" ON ("oauth2_provider_accesstoken"."user_id" = "auths_user"."id") INNER JOIN "oauth2_provider_application" ON ("oauth2_provider_accesstoken"."application_id" = "oauth2_provider_application"."id") WHERE "oauth2_provider_accesstoken"."token" = '2uxkm7mPmmY3dgfXi9BELQYb4sqPdD'; args=('2uxkm7mPmmY3dgfXi9BELQYb4sqPdD',)
[2016-11-13 19:42:37] DEBUG [django.db.backends:89] (0.052) SELECT "catalogo_categoria"."id", "catalogo_categoria"."nombre", "catalogo_categoria"."codigo", "catalogo_categoria"."estado" FROM "catalogo_categoria" WHERE ("catalogo_categoria"."codigo" LIKE '%%' ESCAPE '\' OR "catalogo_categoria"."nombre" LIKE '%%' ESCAPE '\'); args=('%%', '%%')
