[2016-11-28 14:13:13] DEBUG [django.db.backends:89] (0.005) 
            SELECT name, type FROM sqlite_master
            WHERE type in ('table', 'view') AND NOT name='sqlite_sequence'
            ORDER BY name; args=None
[2016-11-28 14:13:13] DEBUG [django.db.backends:89] (0.000) SELECT "django_migrations"."app", "django_migrations"."name" FROM "django_migrations"; args=()
[2016-11-28 14:14:05] WARNING [django.request:182] Not Found: /
[2016-11-28 14:14:06] DEBUG [django.template:927] Exception while resolving variable 'name' in template 'unknown'.
Traceback (most recent call last):
  File "F:\asciacion\proyectoAnalisis\ve_asociacion\lib\site-packages\django\core\handlers\base.py", line 134, in get_response
    resolver_match = resolver.resolve(request.path_info)
  File "F:\asciacion\proyectoAnalisis\ve_asociacion\lib\site-packages\django\core\urlresolvers.py", line 404, in resolve
    raise Resolver404({'tried': tried, 'path': new_path})
django.core.urlresolvers.Resolver404: {'tried': [[<RegexURLResolver <RegexURLPattern list> (admin:admin) ^admin/>], [<RegexURLResolver <module 'django.contrib.admindocs.urls' from 'F:\\asciacion\\proyectoAnalisis\\ve_asociacion\\lib\\site-packages\\django\\contrib\\admindocs\\urls.py'> (None:None) ^admin/doc/>], [<RegexURLResolver <module 'rest_framework.urls' from 'F:\\asciacion\\proyectoAnalisis\\ve_asociacion\\lib\\site-packages\\rest_framework\\urls.py'> (rest_framework:rest_framework) ^api-auth/>], [<RegexURLResolver <module 'oauth2_provider.urls' from 'F:\\asciacion\\proyectoAnalisis\\ve_asociacion\\lib\\site-packages\\oauth2_provider\\urls.py'> (None:oauth2_provider) ^o/>], [<RegexURLResolver <module 'ioteca_service_apps.auths_api.urls' from 'F:\\asciacion\\proyectoAnalisis\\ioteca_service\\ioteca_service_apps\\auths_api\\urls.py'> (None:None) ^api/auths/>], [<RegexURLResolver <module 'ioteca_service_apps.catalogo_api.urls' from 'F:\\asciacion\\proyectoAnalisis\\ioteca_service\\ioteca_service_apps\\catalogo_api\\urls.py'> (None:None) ^api/catalogo/>], [<RegexURLResolver <module 'ioteca_service_apps.eventos_api.urls' from 'F:\\asciacion\\proyectoAnalisis\\ioteca_service\\ioteca_service_apps\\eventos_api\\urls.py'> (None:None) ^api/eventos/>]], 'path': ''}

During handling of the above exception, another exception occurred:

Traceback (most recent call last):
  File "F:\asciacion\proyectoAnalisis\ve_asociacion\lib\site-packages\django\template\base.py", line 883, in _resolve_lookup
    current = current[bit]
TypeError: 'RegexURLResolver' object is not subscriptable

During handling of the above exception, another exception occurred:

Traceback (most recent call last):
  File "F:\asciacion\proyectoAnalisis\ve_asociacion\lib\site-packages\django\template\base.py", line 891, in _resolve_lookup
    current = getattr(current, bit)
AttributeError: 'RegexURLResolver' object has no attribute 'name'

During handling of the above exception, another exception occurred:

Traceback (most recent call last):
  File "F:\asciacion\proyectoAnalisis\ve_asociacion\lib\site-packages\django\template\base.py", line 898, in _resolve_lookup
    current = current[int(bit)]
ValueError: invalid literal for int() with base 10: 'name'

During handling of the above exception, another exception occurred:

Traceback (most recent call last):
  File "F:\asciacion\proyectoAnalisis\ve_asociacion\lib\site-packages\django\template\base.py", line 905, in _resolve_lookup
    (bit, current))  # missing attribute
django.template.base.VariableDoesNotExist: Failed lookup for key [name] in '<RegexURLResolver <RegexURLPattern list> (admin:admin) ^admin/>'
[2016-11-28 14:14:06] DEBUG [django.template:927] Exception while resolving variable 'name' in template 'unknown'.
Traceback (most recent call last):
  File "F:\asciacion\proyectoAnalisis\ve_asociacion\lib\site-packages\django\core\handlers\base.py", line 134, in get_response
    resolver_match = resolver.resolve(request.path_info)
  File "F:\asciacion\proyectoAnalisis\ve_asociacion\lib\site-packages\django\core\urlresolvers.py", line 404, in resolve
    raise Resolver404({'tried': tried, 'path': new_path})
django.core.urlresolvers.Resolver404: {'tried': [[<RegexURLResolver <RegexURLPattern list> (admin:admin) ^admin/>], [<RegexURLResolver <module 'django.contrib.admindocs.urls' from 'F:\\asciacion\\proyectoAnalisis\\ve_asociacion\\lib\\site-packages\\django\\contrib\\admindocs\\urls.py'> (None:None) ^admin/doc/>], [<RegexURLResolver <module 'rest_framework.urls' from 'F:\\asciacion\\proyectoAnalisis\\ve_asociacion\\lib\\site-packages\\rest_framework\\urls.py'> (rest_framework:rest_framework) ^api-auth/>], [<RegexURLResolver <module 'oauth2_provider.urls' from 'F:\\asciacion\\proyectoAnalisis\\ve_asociacion\\lib\\site-packages\\oauth2_provider\\urls.py'> (None:oauth2_provider) ^o/>], [<RegexURLResolver <module 'ioteca_service_apps.auths_api.urls' from 'F:\\asciacion\\proyectoAnalisis\\ioteca_service\\ioteca_service_apps\\auths_api\\urls.py'> (None:None) ^api/auths/>], [<RegexURLResolver <module 'ioteca_service_apps.catalogo_api.urls' from 'F:\\asciacion\\proyectoAnalisis\\ioteca_service\\ioteca_service_apps\\catalogo_api\\urls.py'> (None:None) ^api/catalogo/>], [<RegexURLResolver <module 'ioteca_service_apps.eventos_api.urls' from 'F:\\asciacion\\proyectoAnalisis\\ioteca_service\\ioteca_service_apps\\eventos_api\\urls.py'> (None:None) ^api/eventos/>]], 'path': ''}

During handling of the above exception, another exception occurred:

Traceback (most recent call last):
  File "F:\asciacion\proyectoAnalisis\ve_asociacion\lib\site-packages\django\template\base.py", line 883, in _resolve_lookup
    current = current[bit]
TypeError: 'RegexURLResolver' object is not subscriptable

During handling of the above exception, another exception occurred:

Traceback (most recent call last):
  File "F:\asciacion\proyectoAnalisis\ve_asociacion\lib\site-packages\django\template\base.py", line 891, in _resolve_lookup
    current = getattr(current, bit)
AttributeError: 'RegexURLResolver' object has no attribute 'name'

During handling of the above exception, another exception occurred:

Traceback (most recent call last):
  File "F:\asciacion\proyectoAnalisis\ve_asociacion\lib\site-packages\django\template\base.py", line 898, in _resolve_lookup
    current = current[int(bit)]
ValueError: invalid literal for int() with base 10: 'name'

During handling of the above exception, another exception occurred:

Traceback (most recent call last):
  File "F:\asciacion\proyectoAnalisis\ve_asociacion\lib\site-packages\django\template\base.py", line 905, in _resolve_lookup
    (bit, current))  # missing attribute
django.template.base.VariableDoesNotExist: Failed lookup for key [name] in "<RegexURLResolver <module 'django.contrib.admindocs.urls' from 'F:\\\\asciacion\\\\proyectoAnalisis\\\\ve_asociacion\\\\lib\\\\site-packages\\\\django\\\\contrib\\\\admindocs\\\\urls.py'> (None:None) ^admin/doc/>"
[2016-11-28 14:14:06] DEBUG [django.template:927] Exception while resolving variable 'name' in template 'unknown'.
Traceback (most recent call last):
  File "F:\asciacion\proyectoAnalisis\ve_asociacion\lib\site-packages\django\core\handlers\base.py", line 134, in get_response
    resolver_match = resolver.resolve(request.path_info)
  File "F:\asciacion\proyectoAnalisis\ve_asociacion\lib\site-packages\django\core\urlresolvers.py", line 404, in resolve
    raise Resolver404({'tried': tried, 'path': new_path})
django.core.urlresolvers.Resolver404: {'tried': [[<RegexURLResolver <RegexURLPattern list> (admin:admin) ^admin/>], [<RegexURLResolver <module 'django.contrib.admindocs.urls' from 'F:\\asciacion\\proyectoAnalisis\\ve_asociacion\\lib\\site-packages\\django\\contrib\\admindocs\\urls.py'> (None:None) ^admin/doc/>], [<RegexURLResolver <module 'rest_framework.urls' from 'F:\\asciacion\\proyectoAnalisis\\ve_asociacion\\lib\\site-packages\\rest_framework\\urls.py'> (rest_framework:rest_framework) ^api-auth/>], [<RegexURLResolver <module 'oauth2_provider.urls' from 'F:\\asciacion\\proyectoAnalisis\\ve_asociacion\\lib\\site-packages\\oauth2_provider\\urls.py'> (None:oauth2_provider) ^o/>], [<RegexURLResolver <module 'ioteca_service_apps.auths_api.urls' from 'F:\\asciacion\\proyectoAnalisis\\ioteca_service\\ioteca_service_apps\\auths_api\\urls.py'> (None:None) ^api/auths/>], [<RegexURLResolver <module 'ioteca_service_apps.catalogo_api.urls' from 'F:\\asciacion\\proyectoAnalisis\\ioteca_service\\ioteca_service_apps\\catalogo_api\\urls.py'> (None:None) ^api/catalogo/>], [<RegexURLResolver <module 'ioteca_service_apps.eventos_api.urls' from 'F:\\asciacion\\proyectoAnalisis\\ioteca_service\\ioteca_service_apps\\eventos_api\\urls.py'> (None:None) ^api/eventos/>]], 'path': ''}

During handling of the above exception, another exception occurred:

Traceback (most recent call last):
  File "F:\asciacion\proyectoAnalisis\ve_asociacion\lib\site-packages\django\template\base.py", line 883, in _resolve_lookup
    current = current[bit]
TypeError: 'RegexURLResolver' object is not subscriptable

During handling of the above exception, another exception occurred:

Traceback (most recent call last):
  File "F:\asciacion\proyectoAnalisis\ve_asociacion\lib\site-packages\django\template\base.py", line 891, in _resolve_lookup
    current = getattr(current, bit)
AttributeError: 'RegexURLResolver' object has no attribute 'name'

During handling of the above exception, another exception occurred:

Traceback (most recent call last):
  File "F:\asciacion\proyectoAnalisis\ve_asociacion\lib\site-packages\django\template\base.py", line 898, in _resolve_lookup
    current = current[int(bit)]
ValueError: invalid literal for int() with base 10: 'name'

During handling of the above exception, another exception occurred:

Traceback (most recent call last):
  File "F:\asciacion\proyectoAnalisis\ve_asociacion\lib\site-packages\django\template\base.py", line 905, in _resolve_lookup
    (bit, current))  # missing attribute
django.template.base.VariableDoesNotExist: Failed lookup for key [name] in "<RegexURLResolver <module 'rest_framework.urls' from 'F:\\\\asciacion\\\\proyectoAnalisis\\\\ve_asociacion\\\\lib\\\\site-packages\\\\rest_framework\\\\urls.py'> (rest_framework:rest_framework) ^api-auth/>"
[2016-11-28 14:14:06] DEBUG [django.template:927] Exception while resolving variable 'name' in template 'unknown'.
Traceback (most recent call last):
  File "F:\asciacion\proyectoAnalisis\ve_asociacion\lib\site-packages\django\core\handlers\base.py", line 134, in get_response
    resolver_match = resolver.resolve(request.path_info)
  File "F:\asciacion\proyectoAnalisis\ve_asociacion\lib\site-packages\django\core\urlresolvers.py", line 404, in resolve
    raise Resolver404({'tried': tried, 'path': new_path})
django.core.urlresolvers.Resolver404: {'tried': [[<RegexURLResolver <RegexURLPattern list> (admin:admin) ^admin/>], [<RegexURLResolver <module 'django.contrib.admindocs.urls' from 'F:\\asciacion\\proyectoAnalisis\\ve_asociacion\\lib\\site-packages\\django\\contrib\\admindocs\\urls.py'> (None:None) ^admin/doc/>], [<RegexURLResolver <module 'rest_framework.urls' from 'F:\\asciacion\\proyectoAnalisis\\ve_asociacion\\lib\\site-packages\\rest_framework\\urls.py'> (rest_framework:rest_framework) ^api-auth/>], [<RegexURLResolver <module 'oauth2_provider.urls' from 'F:\\asciacion\\proyectoAnalisis\\ve_asociacion\\lib\\site-packages\\oauth2_provider\\urls.py'> (None:oauth2_provider) ^o/>], [<RegexURLResolver <module 'ioteca_service_apps.auths_api.urls' from 'F:\\asciacion\\proyectoAnalisis\\ioteca_service\\ioteca_service_apps\\auths_api\\urls.py'> (None:None) ^api/auths/>], [<RegexURLResolver <module 'ioteca_service_apps.catalogo_api.urls' from 'F:\\asciacion\\proyectoAnalisis\\ioteca_service\\ioteca_service_apps\\catalogo_api\\urls.py'> (None:None) ^api/catalogo/>], [<RegexURLResolver <module 'ioteca_service_apps.eventos_api.urls' from 'F:\\asciacion\\proyectoAnalisis\\ioteca_service\\ioteca_service_apps\\eventos_api\\urls.py'> (None:None) ^api/eventos/>]], 'path': ''}

During handling of the above exception, another exception occurred:

Traceback (most recent call last):
  File "F:\asciacion\proyectoAnalisis\ve_asociacion\lib\site-packages\django\template\base.py", line 883, in _resolve_lookup
    current = current[bit]
TypeError: 'RegexURLResolver' object is not subscriptable

During handling of the above exception, another exception occurred:

Traceback (most recent call last):
  File "F:\asciacion\proyectoAnalisis\ve_asociacion\lib\site-packages\django\template\base.py", line 891, in _resolve_lookup
    current = getattr(current, bit)
AttributeError: 'RegexURLResolver' object has no attribute 'name'

During handling of the above exception, another exception occurred:

Traceback (most recent call last):
  File "F:\asciacion\proyectoAnalisis\ve_asociacion\lib\site-packages\django\template\base.py", line 898, in _resolve_lookup
    current = current[int(bit)]
ValueError: invalid literal for int() with base 10: 'name'

During handling of the above exception, another exception occurred:

Traceback (most recent call last):
  File "F:\asciacion\proyectoAnalisis\ve_asociacion\lib\site-packages\django\template\base.py", line 905, in _resolve_lookup
    (bit, current))  # missing attribute
django.template.base.VariableDoesNotExist: Failed lookup for key [name] in "<RegexURLResolver <module 'oauth2_provider.urls' from 'F:\\\\asciacion\\\\proyectoAnalisis\\\\ve_asociacion\\\\lib\\\\site-packages\\\\oauth2_provider\\\\urls.py'> (None:oauth2_provider) ^o/>"
[2016-11-28 14:14:06] DEBUG [django.template:927] Exception while resolving variable 'name' in template 'unknown'.
Traceback (most recent call last):
  File "F:\asciacion\proyectoAnalisis\ve_asociacion\lib\site-packages\django\core\handlers\base.py", line 134, in get_response
    resolver_match = resolver.resolve(request.path_info)
  File "F:\asciacion\proyectoAnalisis\ve_asociacion\lib\site-packages\django\core\urlresolvers.py", line 404, in resolve
    raise Resolver404({'tried': tried, 'path': new_path})
django.core.urlresolvers.Resolver404: {'tried': [[<RegexURLResolver <RegexURLPattern list> (admin:admin) ^admin/>], [<RegexURLResolver <module 'django.contrib.admindocs.urls' from 'F:\\asciacion\\proyectoAnalisis\\ve_asociacion\\lib\\site-packages\\django\\contrib\\admindocs\\urls.py'> (None:None) ^admin/doc/>], [<RegexURLResolver <module 'rest_framework.urls' from 'F:\\asciacion\\proyectoAnalisis\\ve_asociacion\\lib\\site-packages\\rest_framework\\urls.py'> (rest_framework:rest_framework) ^api-auth/>], [<RegexURLResolver <module 'oauth2_provider.urls' from 'F:\\asciacion\\proyectoAnalisis\\ve_asociacion\\lib\\site-packages\\oauth2_provider\\urls.py'> (None:oauth2_provider) ^o/>], [<RegexURLResolver <module 'ioteca_service_apps.auths_api.urls' from 'F:\\asciacion\\proyectoAnalisis\\ioteca_service\\ioteca_service_apps\\auths_api\\urls.py'> (None:None) ^api/auths/>], [<RegexURLResolver <module 'ioteca_service_apps.catalogo_api.urls' from 'F:\\asciacion\\proyectoAnalisis\\ioteca_service\\ioteca_service_apps\\catalogo_api\\urls.py'> (None:None) ^api/catalogo/>], [<RegexURLResolver <module 'ioteca_service_apps.eventos_api.urls' from 'F:\\asciacion\\proyectoAnalisis\\ioteca_service\\ioteca_service_apps\\eventos_api\\urls.py'> (None:None) ^api/eventos/>]], 'path': ''}

During handling of the above exception, another exception occurred:

Traceback (most recent call last):
  File "F:\asciacion\proyectoAnalisis\ve_asociacion\lib\site-packages\django\template\base.py", line 883, in _resolve_lookup
    current = current[bit]
TypeError: 'RegexURLResolver' object is not subscriptable

During handling of the above exception, another exception occurred:

Traceback (most recent call last):
  File "F:\asciacion\proyectoAnalisis\ve_asociacion\lib\site-packages\django\template\base.py", line 891, in _resolve_lookup
    current = getattr(current, bit)
AttributeError: 'RegexURLResolver' object has no attribute 'name'

During handling of the above exception, another exception occurred:

Traceback (most recent call last):
  File "F:\asciacion\proyectoAnalisis\ve_asociacion\lib\site-packages\django\template\base.py", line 898, in _resolve_lookup
    current = current[int(bit)]
ValueError: invalid literal for int() with base 10: 'name'

During handling of the above exception, another exception occurred:

Traceback (most recent call last):
  File "F:\asciacion\proyectoAnalisis\ve_asociacion\lib\site-packages\django\template\base.py", line 905, in _resolve_lookup
    (bit, current))  # missing attribute
django.template.base.VariableDoesNotExist: Failed lookup for key [name] in "<RegexURLResolver <module 'ioteca_service_apps.auths_api.urls' from 'F:\\\\asciacion\\\\proyectoAnalisis\\\\ioteca_service\\\\ioteca_service_apps\\\\auths_api\\\\urls.py'> (None:None) ^api/auths/>"
[2016-11-28 14:14:06] DEBUG [django.template:927] Exception while resolving variable 'name' in template 'unknown'.
Traceback (most recent call last):
  File "F:\asciacion\proyectoAnalisis\ve_asociacion\lib\site-packages\django\core\handlers\base.py", line 134, in get_response
    resolver_match = resolver.resolve(request.path_info)
  File "F:\asciacion\proyectoAnalisis\ve_asociacion\lib\site-packages\django\core\urlresolvers.py", line 404, in resolve
    raise Resolver404({'tried': tried, 'path': new_path})
django.core.urlresolvers.Resolver404: {'tried': [[<RegexURLResolver <RegexURLPattern list> (admin:admin) ^admin/>], [<RegexURLResolver <module 'django.contrib.admindocs.urls' from 'F:\\asciacion\\proyectoAnalisis\\ve_asociacion\\lib\\site-packages\\django\\contrib\\admindocs\\urls.py'> (None:None) ^admin/doc/>], [<RegexURLResolver <module 'rest_framework.urls' from 'F:\\asciacion\\proyectoAnalisis\\ve_asociacion\\lib\\site-packages\\rest_framework\\urls.py'> (rest_framework:rest_framework) ^api-auth/>], [<RegexURLResolver <module 'oauth2_provider.urls' from 'F:\\asciacion\\proyectoAnalisis\\ve_asociacion\\lib\\site-packages\\oauth2_provider\\urls.py'> (None:oauth2_provider) ^o/>], [<RegexURLResolver <module 'ioteca_service_apps.auths_api.urls' from 'F:\\asciacion\\proyectoAnalisis\\ioteca_service\\ioteca_service_apps\\auths_api\\urls.py'> (None:None) ^api/auths/>], [<RegexURLResolver <module 'ioteca_service_apps.catalogo_api.urls' from 'F:\\asciacion\\proyectoAnalisis\\ioteca_service\\ioteca_service_apps\\catalogo_api\\urls.py'> (None:None) ^api/catalogo/>], [<RegexURLResolver <module 'ioteca_service_apps.eventos_api.urls' from 'F:\\asciacion\\proyectoAnalisis\\ioteca_service\\ioteca_service_apps\\eventos_api\\urls.py'> (None:None) ^api/eventos/>]], 'path': ''}

During handling of the above exception, another exception occurred:

Traceback (most recent call last):
  File "F:\asciacion\proyectoAnalisis\ve_asociacion\lib\site-packages\django\template\base.py", line 883, in _resolve_lookup
    current = current[bit]
TypeError: 'RegexURLResolver' object is not subscriptable

During handling of the above exception, another exception occurred:

Traceback (most recent call last):
  File "F:\asciacion\proyectoAnalisis\ve_asociacion\lib\site-packages\django\template\base.py", line 891, in _resolve_lookup
    current = getattr(current, bit)
AttributeError: 'RegexURLResolver' object has no attribute 'name'

During handling of the above exception, another exception occurred:

Traceback (most recent call last):
  File "F:\asciacion\proyectoAnalisis\ve_asociacion\lib\site-packages\django\template\base.py", line 898, in _resolve_lookup
    current = current[int(bit)]
ValueError: invalid literal for int() with base 10: 'name'

During handling of the above exception, another exception occurred:

Traceback (most recent call last):
  File "F:\asciacion\proyectoAnalisis\ve_asociacion\lib\site-packages\django\template\base.py", line 905, in _resolve_lookup
    (bit, current))  # missing attribute
django.template.base.VariableDoesNotExist: Failed lookup for key [name] in "<RegexURLResolver <module 'ioteca_service_apps.catalogo_api.urls' from 'F:\\\\asciacion\\\\proyectoAnalisis\\\\ioteca_service\\\\ioteca_service_apps\\\\catalogo_api\\\\urls.py'> (None:None) ^api/catalogo/>"
[2016-11-28 14:14:06] DEBUG [django.template:927] Exception while resolving variable 'name' in template 'unknown'.
Traceback (most recent call last):
  File "F:\asciacion\proyectoAnalisis\ve_asociacion\lib\site-packages\django\core\handlers\base.py", line 134, in get_response
    resolver_match = resolver.resolve(request.path_info)
  File "F:\asciacion\proyectoAnalisis\ve_asociacion\lib\site-packages\django\core\urlresolvers.py", line 404, in resolve
    raise Resolver404({'tried': tried, 'path': new_path})
django.core.urlresolvers.Resolver404: {'tried': [[<RegexURLResolver <RegexURLPattern list> (admin:admin) ^admin/>], [<RegexURLResolver <module 'django.contrib.admindocs.urls' from 'F:\\asciacion\\proyectoAnalisis\\ve_asociacion\\lib\\site-packages\\django\\contrib\\admindocs\\urls.py'> (None:None) ^admin/doc/>], [<RegexURLResolver <module 'rest_framework.urls' from 'F:\\asciacion\\proyectoAnalisis\\ve_asociacion\\lib\\site-packages\\rest_framework\\urls.py'> (rest_framework:rest_framework) ^api-auth/>], [<RegexURLResolver <module 'oauth2_provider.urls' from 'F:\\asciacion\\proyectoAnalisis\\ve_asociacion\\lib\\site-packages\\oauth2_provider\\urls.py'> (None:oauth2_provider) ^o/>], [<RegexURLResolver <module 'ioteca_service_apps.auths_api.urls' from 'F:\\asciacion\\proyectoAnalisis\\ioteca_service\\ioteca_service_apps\\auths_api\\urls.py'> (None:None) ^api/auths/>], [<RegexURLResolver <module 'ioteca_service_apps.catalogo_api.urls' from 'F:\\asciacion\\proyectoAnalisis\\ioteca_service\\ioteca_service_apps\\catalogo_api\\urls.py'> (None:None) ^api/catalogo/>], [<RegexURLResolver <module 'ioteca_service_apps.eventos_api.urls' from 'F:\\asciacion\\proyectoAnalisis\\ioteca_service\\ioteca_service_apps\\eventos_api\\urls.py'> (None:None) ^api/eventos/>]], 'path': ''}

During handling of the above exception, another exception occurred:

Traceback (most recent call last):
  File "F:\asciacion\proyectoAnalisis\ve_asociacion\lib\site-packages\django\template\base.py", line 883, in _resolve_lookup
    current = current[bit]
TypeError: 'RegexURLResolver' object is not subscriptable

During handling of the above exception, another exception occurred:

Traceback (most recent call last):
  File "F:\asciacion\proyectoAnalisis\ve_asociacion\lib\site-packages\django\template\base.py", line 891, in _resolve_lookup
    current = getattr(current, bit)
AttributeError: 'RegexURLResolver' object has no attribute 'name'

During handling of the above exception, another exception occurred:

Traceback (most recent call last):
  File "F:\asciacion\proyectoAnalisis\ve_asociacion\lib\site-packages\django\template\base.py", line 898, in _resolve_lookup
    current = current[int(bit)]
ValueError: invalid literal for int() with base 10: 'name'

During handling of the above exception, another exception occurred:

Traceback (most recent call last):
  File "F:\asciacion\proyectoAnalisis\ve_asociacion\lib\site-packages\django\template\base.py", line 905, in _resolve_lookup
    (bit, current))  # missing attribute
django.template.base.VariableDoesNotExist: Failed lookup for key [name] in "<RegexURLResolver <module 'ioteca_service_apps.eventos_api.urls' from 'F:\\\\asciacion\\\\proyectoAnalisis\\\\ioteca_service\\\\ioteca_service_apps\\\\eventos_api\\\\urls.py'> (None:None) ^api/eventos/>"
[2016-11-28 14:14:06] WARNING [django.request:182] Not Found: /favicon.ico
[2016-11-28 14:14:06] DEBUG [django.template:927] Exception while resolving variable 'name' in template 'unknown'.
Traceback (most recent call last):
  File "F:\asciacion\proyectoAnalisis\ve_asociacion\lib\site-packages\django\core\handlers\base.py", line 134, in get_response
    resolver_match = resolver.resolve(request.path_info)
  File "F:\asciacion\proyectoAnalisis\ve_asociacion\lib\site-packages\django\core\urlresolvers.py", line 404, in resolve
    raise Resolver404({'tried': tried, 'path': new_path})
django.core.urlresolvers.Resolver404: {'tried': [[<RegexURLResolver <RegexURLPattern list> (admin:admin) ^admin/>], [<RegexURLResolver <module 'django.contrib.admindocs.urls' from 'F:\\asciacion\\proyectoAnalisis\\ve_asociacion\\lib\\site-packages\\django\\contrib\\admindocs\\urls.py'> (None:None) ^admin/doc/>], [<RegexURLResolver <module 'rest_framework.urls' from 'F:\\asciacion\\proyectoAnalisis\\ve_asociacion\\lib\\site-packages\\rest_framework\\urls.py'> (rest_framework:rest_framework) ^api-auth/>], [<RegexURLResolver <module 'oauth2_provider.urls' from 'F:\\asciacion\\proyectoAnalisis\\ve_asociacion\\lib\\site-packages\\oauth2_provider\\urls.py'> (None:oauth2_provider) ^o/>], [<RegexURLResolver <module 'ioteca_service_apps.auths_api.urls' from 'F:\\asciacion\\proyectoAnalisis\\ioteca_service\\ioteca_service_apps\\auths_api\\urls.py'> (None:None) ^api/auths/>], [<RegexURLResolver <module 'ioteca_service_apps.catalogo_api.urls' from 'F:\\asciacion\\proyectoAnalisis\\ioteca_service\\ioteca_service_apps\\catalogo_api\\urls.py'> (None:None) ^api/catalogo/>], [<RegexURLResolver <module 'ioteca_service_apps.eventos_api.urls' from 'F:\\asciacion\\proyectoAnalisis\\ioteca_service\\ioteca_service_apps\\eventos_api\\urls.py'> (None:None) ^api/eventos/>]], 'path': 'favicon.ico'}

During handling of the above exception, another exception occurred:

Traceback (most recent call last):
  File "F:\asciacion\proyectoAnalisis\ve_asociacion\lib\site-packages\django\template\base.py", line 883, in _resolve_lookup
    current = current[bit]
TypeError: 'RegexURLResolver' object is not subscriptable

During handling of the above exception, another exception occurred:

Traceback (most recent call last):
  File "F:\asciacion\proyectoAnalisis\ve_asociacion\lib\site-packages\django\template\base.py", line 891, in _resolve_lookup
    current = getattr(current, bit)
AttributeError: 'RegexURLResolver' object has no attribute 'name'

During handling of the above exception, another exception occurred:

Traceback (most recent call last):
  File "F:\asciacion\proyectoAnalisis\ve_asociacion\lib\site-packages\django\template\base.py", line 898, in _resolve_lookup
    current = current[int(bit)]
ValueError: invalid literal for int() with base 10: 'name'

During handling of the above exception, another exception occurred:

Traceback (most recent call last):
  File "F:\asciacion\proyectoAnalisis\ve_asociacion\lib\site-packages\django\template\base.py", line 905, in _resolve_lookup
    (bit, current))  # missing attribute
django.template.base.VariableDoesNotExist: Failed lookup for key [name] in '<RegexURLResolver <RegexURLPattern list> (admin:admin) ^admin/>'
[2016-11-28 14:14:06] DEBUG [django.template:927] Exception while resolving variable 'name' in template 'unknown'.
Traceback (most recent call last):
  File "F:\asciacion\proyectoAnalisis\ve_asociacion\lib\site-packages\django\core\handlers\base.py", line 134, in get_response
    resolver_match = resolver.resolve(request.path_info)
  File "F:\asciacion\proyectoAnalisis\ve_asociacion\lib\site-packages\django\core\urlresolvers.py", line 404, in resolve
    raise Resolver404({'tried': tried, 'path': new_path})
django.core.urlresolvers.Resolver404: {'tried': [[<RegexURLResolver <RegexURLPattern list> (admin:admin) ^admin/>], [<RegexURLResolver <module 'django.contrib.admindocs.urls' from 'F:\\asciacion\\proyectoAnalisis\\ve_asociacion\\lib\\site-packages\\django\\contrib\\admindocs\\urls.py'> (None:None) ^admin/doc/>], [<RegexURLResolver <module 'rest_framework.urls' from 'F:\\asciacion\\proyectoAnalisis\\ve_asociacion\\lib\\site-packages\\rest_framework\\urls.py'> (rest_framework:rest_framework) ^api-auth/>], [<RegexURLResolver <module 'oauth2_provider.urls' from 'F:\\asciacion\\proyectoAnalisis\\ve_asociacion\\lib\\site-packages\\oauth2_provider\\urls.py'> (None:oauth2_provider) ^o/>], [<RegexURLResolver <module 'ioteca_service_apps.auths_api.urls' from 'F:\\asciacion\\proyectoAnalisis\\ioteca_service\\ioteca_service_apps\\auths_api\\urls.py'> (None:None) ^api/auths/>], [<RegexURLResolver <module 'ioteca_service_apps.catalogo_api.urls' from 'F:\\asciacion\\proyectoAnalisis\\ioteca_service\\ioteca_service_apps\\catalogo_api\\urls.py'> (None:None) ^api/catalogo/>], [<RegexURLResolver <module 'ioteca_service_apps.eventos_api.urls' from 'F:\\asciacion\\proyectoAnalisis\\ioteca_service\\ioteca_service_apps\\eventos_api\\urls.py'> (None:None) ^api/eventos/>]], 'path': 'favicon.ico'}

During handling of the above exception, another exception occurred:

Traceback (most recent call last):
  File "F:\asciacion\proyectoAnalisis\ve_asociacion\lib\site-packages\django\template\base.py", line 883, in _resolve_lookup
    current = current[bit]
TypeError: 'RegexURLResolver' object is not subscriptable

During handling of the above exception, another exception occurred:

Traceback (most recent call last):
  File "F:\asciacion\proyectoAnalisis\ve_asociacion\lib\site-packages\django\template\base.py", line 891, in _resolve_lookup
    current = getattr(current, bit)
AttributeError: 'RegexURLResolver' object has no attribute 'name'

During handling of the above exception, another exception occurred:

Traceback (most recent call last):
  File "F:\asciacion\proyectoAnalisis\ve_asociacion\lib\site-packages\django\template\base.py", line 898, in _resolve_lookup
    current = current[int(bit)]
ValueError: invalid literal for int() with base 10: 'name'

During handling of the above exception, another exception occurred:

Traceback (most recent call last):
  File "F:\asciacion\proyectoAnalisis\ve_asociacion\lib\site-packages\django\template\base.py", line 905, in _resolve_lookup
    (bit, current))  # missing attribute
django.template.base.VariableDoesNotExist: Failed lookup for key [name] in "<RegexURLResolver <module 'django.contrib.admindocs.urls' from 'F:\\\\asciacion\\\\proyectoAnalisis\\\\ve_asociacion\\\\lib\\\\site-packages\\\\django\\\\contrib\\\\admindocs\\\\urls.py'> (None:None) ^admin/doc/>"
[2016-11-28 14:14:06] DEBUG [django.template:927] Exception while resolving variable 'name' in template 'unknown'.
Traceback (most recent call last):
  File "F:\asciacion\proyectoAnalisis\ve_asociacion\lib\site-packages\django\core\handlers\base.py", line 134, in get_response
    resolver_match = resolver.resolve(request.path_info)
  File "F:\asciacion\proyectoAnalisis\ve_asociacion\lib\site-packages\django\core\urlresolvers.py", line 404, in resolve
    raise Resolver404({'tried': tried, 'path': new_path})
django.core.urlresolvers.Resolver404: {'tried': [[<RegexURLResolver <RegexURLPattern list> (admin:admin) ^admin/>], [<RegexURLResolver <module 'django.contrib.admindocs.urls' from 'F:\\asciacion\\proyectoAnalisis\\ve_asociacion\\lib\\site-packages\\django\\contrib\\admindocs\\urls.py'> (None:None) ^admin/doc/>], [<RegexURLResolver <module 'rest_framework.urls' from 'F:\\asciacion\\proyectoAnalisis\\ve_asociacion\\lib\\site-packages\\rest_framework\\urls.py'> (rest_framework:rest_framework) ^api-auth/>], [<RegexURLResolver <module 'oauth2_provider.urls' from 'F:\\asciacion\\proyectoAnalisis\\ve_asociacion\\lib\\site-packages\\oauth2_provider\\urls.py'> (None:oauth2_provider) ^o/>], [<RegexURLResolver <module 'ioteca_service_apps.auths_api.urls' from 'F:\\asciacion\\proyectoAnalisis\\ioteca_service\\ioteca_service_apps\\auths_api\\urls.py'> (None:None) ^api/auths/>], [<RegexURLResolver <module 'ioteca_service_apps.catalogo_api.urls' from 'F:\\asciacion\\proyectoAnalisis\\ioteca_service\\ioteca_service_apps\\catalogo_api\\urls.py'> (None:None) ^api/catalogo/>], [<RegexURLResolver <module 'ioteca_service_apps.eventos_api.urls' from 'F:\\asciacion\\proyectoAnalisis\\ioteca_service\\ioteca_service_apps\\eventos_api\\urls.py'> (None:None) ^api/eventos/>]], 'path': 'favicon.ico'}

During handling of the above exception, another exception occurred:

Traceback (most recent call last):
  File "F:\asciacion\proyectoAnalisis\ve_asociacion\lib\site-packages\django\template\base.py", line 883, in _resolve_lookup
    current = current[bit]
TypeError: 'RegexURLResolver' object is not subscriptable

During handling of the above exception, another exception occurred:

Traceback (most recent call last):
  File "F:\asciacion\proyectoAnalisis\ve_asociacion\lib\site-packages\django\template\base.py", line 891, in _resolve_lookup
    current = getattr(current, bit)
AttributeError: 'RegexURLResolver' object has no attribute 'name'

During handling of the above exception, another exception occurred:

Traceback (most recent call last):
  File "F:\asciacion\proyectoAnalisis\ve_asociacion\lib\site-packages\django\template\base.py", line 898, in _resolve_lookup
    current = current[int(bit)]
ValueError: invalid literal for int() with base 10: 'name'

During handling of the above exception, another exception occurred:

Traceback (most recent call last):
  File "F:\asciacion\proyectoAnalisis\ve_asociacion\lib\site-packages\django\template\base.py", line 905, in _resolve_lookup
    (bit, current))  # missing attribute
django.template.base.VariableDoesNotExist: Failed lookup for key [name] in "<RegexURLResolver <module 'rest_framework.urls' from 'F:\\\\asciacion\\\\proyectoAnalisis\\\\ve_asociacion\\\\lib\\\\site-packages\\\\rest_framework\\\\urls.py'> (rest_framework:rest_framework) ^api-auth/>"
[2016-11-28 14:14:06] DEBUG [django.template:927] Exception while resolving variable 'name' in template 'unknown'.
Traceback (most recent call last):
  File "F:\asciacion\proyectoAnalisis\ve_asociacion\lib\site-packages\django\core\handlers\base.py", line 134, in get_response
    resolver_match = resolver.resolve(request.path_info)
  File "F:\asciacion\proyectoAnalisis\ve_asociacion\lib\site-packages\django\core\urlresolvers.py", line 404, in resolve
    raise Resolver404({'tried': tried, 'path': new_path})
django.core.urlresolvers.Resolver404: {'tried': [[<RegexURLResolver <RegexURLPattern list> (admin:admin) ^admin/>], [<RegexURLResolver <module 'django.contrib.admindocs.urls' from 'F:\\asciacion\\proyectoAnalisis\\ve_asociacion\\lib\\site-packages\\django\\contrib\\admindocs\\urls.py'> (None:None) ^admin/doc/>], [<RegexURLResolver <module 'rest_framework.urls' from 'F:\\asciacion\\proyectoAnalisis\\ve_asociacion\\lib\\site-packages\\rest_framework\\urls.py'> (rest_framework:rest_framework) ^api-auth/>], [<RegexURLResolver <module 'oauth2_provider.urls' from 'F:\\asciacion\\proyectoAnalisis\\ve_asociacion\\lib\\site-packages\\oauth2_provider\\urls.py'> (None:oauth2_provider) ^o/>], [<RegexURLResolver <module 'ioteca_service_apps.auths_api.urls' from 'F:\\asciacion\\proyectoAnalisis\\ioteca_service\\ioteca_service_apps\\auths_api\\urls.py'> (None:None) ^api/auths/>], [<RegexURLResolver <module 'ioteca_service_apps.catalogo_api.urls' from 'F:\\asciacion\\proyectoAnalisis\\ioteca_service\\ioteca_service_apps\\catalogo_api\\urls.py'> (None:None) ^api/catalogo/>], [<RegexURLResolver <module 'ioteca_service_apps.eventos_api.urls' from 'F:\\asciacion\\proyectoAnalisis\\ioteca_service\\ioteca_service_apps\\eventos_api\\urls.py'> (None:None) ^api/eventos/>]], 'path': 'favicon.ico'}

During handling of the above exception, another exception occurred:

Traceback (most recent call last):
  File "F:\asciacion\proyectoAnalisis\ve_asociacion\lib\site-packages\django\template\base.py", line 883, in _resolve_lookup
    current = current[bit]
TypeError: 'RegexURLResolver' object is not subscriptable

During handling of the above exception, another exception occurred:

Traceback (most recent call last):
  File "F:\asciacion\proyectoAnalisis\ve_asociacion\lib\site-packages\django\template\base.py", line 891, in _resolve_lookup
    current = getattr(current, bit)
AttributeError: 'RegexURLResolver' object has no attribute 'name'

During handling of the above exception, another exception occurred:

Traceback (most recent call last):
  File "F:\asciacion\proyectoAnalisis\ve_asociacion\lib\site-packages\django\template\base.py", line 898, in _resolve_lookup
    current = current[int(bit)]
ValueError: invalid literal for int() with base 10: 'name'

During handling of the above exception, another exception occurred:

Traceback (most recent call last):
  File "F:\asciacion\proyectoAnalisis\ve_asociacion\lib\site-packages\django\template\base.py", line 905, in _resolve_lookup
    (bit, current))  # missing attribute
django.template.base.VariableDoesNotExist: Failed lookup for key [name] in "<RegexURLResolver <module 'oauth2_provider.urls' from 'F:\\\\asciacion\\\\proyectoAnalisis\\\\ve_asociacion\\\\lib\\\\site-packages\\\\oauth2_provider\\\\urls.py'> (None:oauth2_provider) ^o/>"
[2016-11-28 14:14:06] DEBUG [django.template:927] Exception while resolving variable 'name' in template 'unknown'.
Traceback (most recent call last):
  File "F:\asciacion\proyectoAnalisis\ve_asociacion\lib\site-packages\django\core\handlers\base.py", line 134, in get_response
    resolver_match = resolver.resolve(request.path_info)
  File "F:\asciacion\proyectoAnalisis\ve_asociacion\lib\site-packages\django\core\urlresolvers.py", line 404, in resolve
    raise Resolver404({'tried': tried, 'path': new_path})
django.core.urlresolvers.Resolver404: {'tried': [[<RegexURLResolver <RegexURLPattern list> (admin:admin) ^admin/>], [<RegexURLResolver <module 'django.contrib.admindocs.urls' from 'F:\\asciacion\\proyectoAnalisis\\ve_asociacion\\lib\\site-packages\\django\\contrib\\admindocs\\urls.py'> (None:None) ^admin/doc/>], [<RegexURLResolver <module 'rest_framework.urls' from 'F:\\asciacion\\proyectoAnalisis\\ve_asociacion\\lib\\site-packages\\rest_framework\\urls.py'> (rest_framework:rest_framework) ^api-auth/>], [<RegexURLResolver <module 'oauth2_provider.urls' from 'F:\\asciacion\\proyectoAnalisis\\ve_asociacion\\lib\\site-packages\\oauth2_provider\\urls.py'> (None:oauth2_provider) ^o/>], [<RegexURLResolver <module 'ioteca_service_apps.auths_api.urls' from 'F:\\asciacion\\proyectoAnalisis\\ioteca_service\\ioteca_service_apps\\auths_api\\urls.py'> (None:None) ^api/auths/>], [<RegexURLResolver <module 'ioteca_service_apps.catalogo_api.urls' from 'F:\\asciacion\\proyectoAnalisis\\ioteca_service\\ioteca_service_apps\\catalogo_api\\urls.py'> (None:None) ^api/catalogo/>], [<RegexURLResolver <module 'ioteca_service_apps.eventos_api.urls' from 'F:\\asciacion\\proyectoAnalisis\\ioteca_service\\ioteca_service_apps\\eventos_api\\urls.py'> (None:None) ^api/eventos/>]], 'path': 'favicon.ico'}

During handling of the above exception, another exception occurred:

Traceback (most recent call last):
  File "F:\asciacion\proyectoAnalisis\ve_asociacion\lib\site-packages\django\template\base.py", line 883, in _resolve_lookup
    current = current[bit]
TypeError: 'RegexURLResolver' object is not subscriptable

During handling of the above exception, another exception occurred:

Traceback (most recent call last):
  File "F:\asciacion\proyectoAnalisis\ve_asociacion\lib\site-packages\django\template\base.py", line 891, in _resolve_lookup
    current = getattr(current, bit)
AttributeError: 'RegexURLResolver' object has no attribute 'name'

During handling of the above exception, another exception occurred:

Traceback (most recent call last):
  File "F:\asciacion\proyectoAnalisis\ve_asociacion\lib\site-packages\django\template\base.py", line 898, in _resolve_lookup
    current = current[int(bit)]
ValueError: invalid literal for int() with base 10: 'name'

During handling of the above exception, another exception occurred:

Traceback (most recent call last):
  File "F:\asciacion\proyectoAnalisis\ve_asociacion\lib\site-packages\django\template\base.py", line 905, in _resolve_lookup
    (bit, current))  # missing attribute
django.template.base.VariableDoesNotExist: Failed lookup for key [name] in "<RegexURLResolver <module 'ioteca_service_apps.auths_api.urls' from 'F:\\\\asciacion\\\\proyectoAnalisis\\\\ioteca_service\\\\ioteca_service_apps\\\\auths_api\\\\urls.py'> (None:None) ^api/auths/>"
[2016-11-28 14:14:06] DEBUG [django.template:927] Exception while resolving variable 'name' in template 'unknown'.
Traceback (most recent call last):
  File "F:\asciacion\proyectoAnalisis\ve_asociacion\lib\site-packages\django\core\handlers\base.py", line 134, in get_response
    resolver_match = resolver.resolve(request.path_info)
  File "F:\asciacion\proyectoAnalisis\ve_asociacion\lib\site-packages\django\core\urlresolvers.py", line 404, in resolve
    raise Resolver404({'tried': tried, 'path': new_path})
django.core.urlresolvers.Resolver404: {'tried': [[<RegexURLResolver <RegexURLPattern list> (admin:admin) ^admin/>], [<RegexURLResolver <module 'django.contrib.admindocs.urls' from 'F:\\asciacion\\proyectoAnalisis\\ve_asociacion\\lib\\site-packages\\django\\contrib\\admindocs\\urls.py'> (None:None) ^admin/doc/>], [<RegexURLResolver <module 'rest_framework.urls' from 'F:\\asciacion\\proyectoAnalisis\\ve_asociacion\\lib\\site-packages\\rest_framework\\urls.py'> (rest_framework:rest_framework) ^api-auth/>], [<RegexURLResolver <module 'oauth2_provider.urls' from 'F:\\asciacion\\proyectoAnalisis\\ve_asociacion\\lib\\site-packages\\oauth2_provider\\urls.py'> (None:oauth2_provider) ^o/>], [<RegexURLResolver <module 'ioteca_service_apps.auths_api.urls' from 'F:\\asciacion\\proyectoAnalisis\\ioteca_service\\ioteca_service_apps\\auths_api\\urls.py'> (None:None) ^api/auths/>], [<RegexURLResolver <module 'ioteca_service_apps.catalogo_api.urls' from 'F:\\asciacion\\proyectoAnalisis\\ioteca_service\\ioteca_service_apps\\catalogo_api\\urls.py'> (None:None) ^api/catalogo/>], [<RegexURLResolver <module 'ioteca_service_apps.eventos_api.urls' from 'F:\\asciacion\\proyectoAnalisis\\ioteca_service\\ioteca_service_apps\\eventos_api\\urls.py'> (None:None) ^api/eventos/>]], 'path': 'favicon.ico'}

During handling of the above exception, another exception occurred:

Traceback (most recent call last):
  File "F:\asciacion\proyectoAnalisis\ve_asociacion\lib\site-packages\django\template\base.py", line 883, in _resolve_lookup
    current = current[bit]
TypeError: 'RegexURLResolver' object is not subscriptable

During handling of the above exception, another exception occurred:

Traceback (most recent call last):
  File "F:\asciacion\proyectoAnalisis\ve_asociacion\lib\site-packages\django\template\base.py", line 891, in _resolve_lookup
    current = getattr(current, bit)
AttributeError: 'RegexURLResolver' object has no attribute 'name'

During handling of the above exception, another exception occurred:

Traceback (most recent call last):
  File "F:\asciacion\proyectoAnalisis\ve_asociacion\lib\site-packages\django\template\base.py", line 898, in _resolve_lookup
    current = current[int(bit)]
ValueError: invalid literal for int() with base 10: 'name'

During handling of the above exception, another exception occurred:

Traceback (most recent call last):
  File "F:\asciacion\proyectoAnalisis\ve_asociacion\lib\site-packages\django\template\base.py", line 905, in _resolve_lookup
    (bit, current))  # missing attribute
django.template.base.VariableDoesNotExist: Failed lookup for key [name] in "<RegexURLResolver <module 'ioteca_service_apps.catalogo_api.urls' from 'F:\\\\asciacion\\\\proyectoAnalisis\\\\ioteca_service\\\\ioteca_service_apps\\\\catalogo_api\\\\urls.py'> (None:None) ^api/catalogo/>"
[2016-11-28 14:14:06] DEBUG [django.template:927] Exception while resolving variable 'name' in template 'unknown'.
Traceback (most recent call last):
  File "F:\asciacion\proyectoAnalisis\ve_asociacion\lib\site-packages\django\core\handlers\base.py", line 134, in get_response
    resolver_match = resolver.resolve(request.path_info)
  File "F:\asciacion\proyectoAnalisis\ve_asociacion\lib\site-packages\django\core\urlresolvers.py", line 404, in resolve
    raise Resolver404({'tried': tried, 'path': new_path})
django.core.urlresolvers.Resolver404: {'tried': [[<RegexURLResolver <RegexURLPattern list> (admin:admin) ^admin/>], [<RegexURLResolver <module 'django.contrib.admindocs.urls' from 'F:\\asciacion\\proyectoAnalisis\\ve_asociacion\\lib\\site-packages\\django\\contrib\\admindocs\\urls.py'> (None:None) ^admin/doc/>], [<RegexURLResolver <module 'rest_framework.urls' from 'F:\\asciacion\\proyectoAnalisis\\ve_asociacion\\lib\\site-packages\\rest_framework\\urls.py'> (rest_framework:rest_framework) ^api-auth/>], [<RegexURLResolver <module 'oauth2_provider.urls' from 'F:\\asciacion\\proyectoAnalisis\\ve_asociacion\\lib\\site-packages\\oauth2_provider\\urls.py'> (None:oauth2_provider) ^o/>], [<RegexURLResolver <module 'ioteca_service_apps.auths_api.urls' from 'F:\\asciacion\\proyectoAnalisis\\ioteca_service\\ioteca_service_apps\\auths_api\\urls.py'> (None:None) ^api/auths/>], [<RegexURLResolver <module 'ioteca_service_apps.catalogo_api.urls' from 'F:\\asciacion\\proyectoAnalisis\\ioteca_service\\ioteca_service_apps\\catalogo_api\\urls.py'> (None:None) ^api/catalogo/>], [<RegexURLResolver <module 'ioteca_service_apps.eventos_api.urls' from 'F:\\asciacion\\proyectoAnalisis\\ioteca_service\\ioteca_service_apps\\eventos_api\\urls.py'> (None:None) ^api/eventos/>]], 'path': 'favicon.ico'}

During handling of the above exception, another exception occurred:

Traceback (most recent call last):
  File "F:\asciacion\proyectoAnalisis\ve_asociacion\lib\site-packages\django\template\base.py", line 883, in _resolve_lookup
    current = current[bit]
TypeError: 'RegexURLResolver' object is not subscriptable

During handling of the above exception, another exception occurred:

Traceback (most recent call last):
  File "F:\asciacion\proyectoAnalisis\ve_asociacion\lib\site-packages\django\template\base.py", line 891, in _resolve_lookup
    current = getattr(current, bit)
AttributeError: 'RegexURLResolver' object has no attribute 'name'

During handling of the above exception, another exception occurred:

Traceback (most recent call last):
  File "F:\asciacion\proyectoAnalisis\ve_asociacion\lib\site-packages\django\template\base.py", line 898, in _resolve_lookup
    current = current[int(bit)]
ValueError: invalid literal for int() with base 10: 'name'

During handling of the above exception, another exception occurred:

Traceback (most recent call last):
  File "F:\asciacion\proyectoAnalisis\ve_asociacion\lib\site-packages\django\template\base.py", line 905, in _resolve_lookup
    (bit, current))  # missing attribute
django.template.base.VariableDoesNotExist: Failed lookup for key [name] in "<RegexURLResolver <module 'ioteca_service_apps.eventos_api.urls' from 'F:\\\\asciacion\\\\proyectoAnalisis\\\\ioteca_service\\\\ioteca_service_apps\\\\eventos_api\\\\urls.py'> (None:None) ^api/eventos/>"
[2016-11-28 14:14:27] DEBUG [django.db.backends:89] (0.002) SELECT "auths_user"."password", "auths_user"."last_login", "auths_user"."is_superuser", "auths_user"."username", "auths_user"."first_name", "auths_user"."last_name", "auths_user"."email", "auths_user"."is_staff", "auths_user"."is_active", "auths_user"."date_joined", "auths_user"."id", "auths_user"."last_hierarchy_id", "auths_user"."last_module_id", "auths_user"."person_id", "auths_user"."updated_at", "auths_user"."registered_by" FROM "auths_user" WHERE "auths_user"."username" IS NULL; args=()
[2016-11-28 14:14:27] DEBUG [django.db.backends:89] (0.007) SELECT "auths_user"."password", "auths_user"."last_login", "auths_user"."is_superuser", "auths_user"."username", "auths_user"."first_name", "auths_user"."last_name", "auths_user"."email", "auths_user"."is_staff", "auths_user"."is_active", "auths_user"."date_joined", "auths_user"."id", "auths_user"."last_hierarchy_id", "auths_user"."last_module_id", "auths_user"."person_id", "auths_user"."updated_at", "auths_user"."registered_by" FROM "auths_user" WHERE "auths_user"."username" IS NULL; args=()
[2016-11-28 14:14:27] DEBUG [django.db.backends:89] (0.003) SELECT "oauth2_provider_accesstoken"."id", "oauth2_provider_accesstoken"."user_id", "oauth2_provider_accesstoken"."token", "oauth2_provider_accesstoken"."application_id", "oauth2_provider_accesstoken"."expires", "oauth2_provider_accesstoken"."scope", "auths_user"."password", "auths_user"."last_login", "auths_user"."is_superuser", "auths_user"."username", "auths_user"."first_name", "auths_user"."last_name", "auths_user"."email", "auths_user"."is_staff", "auths_user"."is_active", "auths_user"."date_joined", "auths_user"."id", "auths_user"."last_hierarchy_id", "auths_user"."last_module_id", "auths_user"."person_id", "auths_user"."updated_at", "auths_user"."registered_by", "oauth2_provider_application"."id", "oauth2_provider_application"."client_id", "oauth2_provider_application"."user_id", "oauth2_provider_application"."redirect_uris", "oauth2_provider_application"."client_type", "oauth2_provider_application"."authorization_grant_type", "oauth2_provider_application"."client_secret", "oauth2_provider_application"."name", "oauth2_provider_application"."skip_authorization" FROM "oauth2_provider_accesstoken" LEFT OUTER JOIN "auths_user" ON ("oauth2_provider_accesstoken"."user_id" = "auths_user"."id") INNER JOIN "oauth2_provider_application" ON ("oauth2_provider_accesstoken"."application_id" = "oauth2_provider_application"."id") WHERE "oauth2_provider_accesstoken"."token" = '81jZOfUorOBqXlVY6NasW0BGJWhFxP'; args=('81jZOfUorOBqXlVY6NasW0BGJWhFxP',)
[2016-11-28 14:14:27] DEBUG [django.db.backends:89] (0.003) SELECT "oauth2_provider_accesstoken"."id", "oauth2_provider_accesstoken"."user_id", "oauth2_provider_accesstoken"."token", "oauth2_provider_accesstoken"."application_id", "oauth2_provider_accesstoken"."expires", "oauth2_provider_accesstoken"."scope", "auths_user"."password", "auths_user"."last_login", "auths_user"."is_superuser", "auths_user"."username", "auths_user"."first_name", "auths_user"."last_name", "auths_user"."email", "auths_user"."is_staff", "auths_user"."is_active", "auths_user"."date_joined", "auths_user"."id", "auths_user"."last_hierarchy_id", "auths_user"."last_module_id", "auths_user"."person_id", "auths_user"."updated_at", "auths_user"."registered_by", "oauth2_provider_application"."id", "oauth2_provider_application"."client_id", "oauth2_provider_application"."user_id", "oauth2_provider_application"."redirect_uris", "oauth2_provider_application"."client_type", "oauth2_provider_application"."authorization_grant_type", "oauth2_provider_application"."client_secret", "oauth2_provider_application"."name", "oauth2_provider_application"."skip_authorization" FROM "oauth2_provider_accesstoken" LEFT OUTER JOIN "auths_user" ON ("oauth2_provider_accesstoken"."user_id" = "auths_user"."id") INNER JOIN "oauth2_provider_application" ON ("oauth2_provider_accesstoken"."application_id" = "oauth2_provider_application"."id") WHERE "oauth2_provider_accesstoken"."token" = '81jZOfUorOBqXlVY6NasW0BGJWhFxP'; args=('81jZOfUorOBqXlVY6NasW0BGJWhFxP',)
[2016-11-28 14:14:39] DEBUG [django.db.backends:89] (0.001) SELECT "django_session"."session_key", "django_session"."session_data", "django_session"."expire_date" FROM "django_session" WHERE ("django_session"."expire_date" > '2016-11-28 19:14:39.504902' AND "django_session"."session_key" = 'wsveqz6q73oljk5h9dsgyxvg5jdv4y6o'); args=('2016-11-28 19:14:39.504902', 'wsveqz6q73oljk5h9dsgyxvg5jdv4y6o')
[2016-11-28 14:14:39] DEBUG [django.template:927] Exception while resolving variable 'is_popup' in template 'admin/login.html'.
Traceback (most recent call last):
  File "F:\asciacion\proyectoAnalisis\ve_asociacion\lib\site-packages\django\template\base.py", line 883, in _resolve_lookup
    current = current[bit]
  File "F:\asciacion\proyectoAnalisis\ve_asociacion\lib\site-packages\django\template\context.py", line 77, in __getitem__
    raise KeyError(key)
KeyError: 'is_popup'

During handling of the above exception, another exception occurred:

Traceback (most recent call last):
  File "F:\asciacion\proyectoAnalisis\ve_asociacion\lib\site-packages\django\template\base.py", line 889, in _resolve_lookup
    if isinstance(current, BaseContext) and getattr(type(current), bit):
AttributeError: type object 'RequestContext' has no attribute 'is_popup'

During handling of the above exception, another exception occurred:

Traceback (most recent call last):
  File "F:\asciacion\proyectoAnalisis\ve_asociacion\lib\site-packages\django\template\base.py", line 898, in _resolve_lookup
    current = current[int(bit)]
ValueError: invalid literal for int() with base 10: 'is_popup'

During handling of the above exception, another exception occurred:

Traceback (most recent call last):
  File "F:\asciacion\proyectoAnalisis\ve_asociacion\lib\site-packages\django\template\base.py", line 905, in _resolve_lookup
    (bit, current))  # missing attribute
django.template.base.VariableDoesNotExist: Failed lookup for key [is_popup] in "[{'False': False, 'True': True, 'None': None}, {'user': <SimpleLazyObject: <django.contrib.auth.models.AnonymousUser object at 0x000001B53573F6D8>>, 'DEFAULT_MESSAGE_LEVELS': {'WARNING': 30, 'DEBUG': 10, 'SUCCESS': 25, 'INFO': 20, 'ERROR': 40}, 'perms': <django.contrib.auth.context_processors.PermWrapper object at 0x000001B535759A58>, 'csrf_token': <SimpleLazyObject: <function csrf.<locals>._get_val at 0x000001B53556A488>>, 'messages': <django.contrib.messages.storage.fallback.FallbackStorage object at 0x000001B53573F780>, 'request': <WSGIRequest: GET '/admin/login/?next=/admin/'>}, {}, {'site': <django.contrib.sites.requests.RequestSite object at 0x000001B53573FA58>, 'form': <AdminAuthenticationForm bound=False, valid=Unknown, fields=(username;password)>, 'next': '/admin/', 'LANGUAGE_CODE': 'en-us', 'app_path': '/admin/login/?next=/admin/', 'title': 'Log in', 'site_name': 'localhost:9000', 'site_url': '/', 'available_apps': [], 'has_permission': False, 'site_title': <django.utils.functional.lazy.<locals>.__proxy__ object at 0x000001B534363278>, 'site_header': <django.utils.functional.lazy.<locals>.__proxy__ object at 0x000001B534363320>, 'LANGUAGE_BIDI': False}]"
[2016-11-28 14:14:39] DEBUG [django.template:927] Exception while resolving variable 'is_popup' in template 'admin/login.html'.
Traceback (most recent call last):
  File "F:\asciacion\proyectoAnalisis\ve_asociacion\lib\site-packages\django\template\base.py", line 883, in _resolve_lookup
    current = current[bit]
  File "F:\asciacion\proyectoAnalisis\ve_asociacion\lib\site-packages\django\template\context.py", line 77, in __getitem__
    raise KeyError(key)
KeyError: 'is_popup'

During handling of the above exception, another exception occurred:

Traceback (most recent call last):
  File "F:\asciacion\proyectoAnalisis\ve_asociacion\lib\site-packages\django\template\base.py", line 889, in _resolve_lookup
    if isinstance(current, BaseContext) and getattr(type(current), bit):
AttributeError: type object 'RequestContext' has no attribute 'is_popup'

During handling of the above exception, another exception occurred:

Traceback (most recent call last):
  File "F:\asciacion\proyectoAnalisis\ve_asociacion\lib\site-packages\django\template\base.py", line 898, in _resolve_lookup
    current = current[int(bit)]
ValueError: invalid literal for int() with base 10: 'is_popup'

During handling of the above exception, another exception occurred:

Traceback (most recent call last):
  File "F:\asciacion\proyectoAnalisis\ve_asociacion\lib\site-packages\django\template\base.py", line 905, in _resolve_lookup
    (bit, current))  # missing attribute
django.template.base.VariableDoesNotExist: Failed lookup for key [is_popup] in "[{'False': False, 'True': True, 'None': None}, {'user': <SimpleLazyObject: <django.contrib.auth.models.AnonymousUser object at 0x000001B53573F6D8>>, 'DEFAULT_MESSAGE_LEVELS': {'WARNING': 30, 'DEBUG': 10, 'SUCCESS': 25, 'INFO': 20, 'ERROR': 40}, 'perms': <django.contrib.auth.context_processors.PermWrapper object at 0x000001B535759A58>, 'csrf_token': <SimpleLazyObject: <function csrf.<locals>._get_val at 0x000001B53556A488>>, 'messages': <django.contrib.messages.storage.fallback.FallbackStorage object at 0x000001B53573F780>, 'request': <WSGIRequest: GET '/admin/login/?next=/admin/'>}, {}, {'site': <django.contrib.sites.requests.RequestSite object at 0x000001B53573FA58>, 'form': <AdminAuthenticationForm bound=False, valid=Unknown, fields=(username;password)>, 'next': '/admin/', 'LANGUAGE_CODE': 'en-us', 'app_path': '/admin/login/?next=/admin/', 'title': 'Log in', 'site_name': 'localhost:9000', 'site_url': '/', 'available_apps': [], 'has_permission': False, 'site_title': <django.utils.functional.lazy.<locals>.__proxy__ object at 0x000001B534363278>, 'site_header': <django.utils.functional.lazy.<locals>.__proxy__ object at 0x000001B534363320>, 'LANGUAGE_BIDI': False}]"
[2016-11-28 14:14:42] DEBUG [django.db.backends:89] (0.002) SELECT "auths_user"."password", "auths_user"."last_login", "auths_user"."is_superuser", "auths_user"."username", "auths_user"."first_name", "auths_user"."last_name", "auths_user"."email", "auths_user"."is_staff", "auths_user"."is_active", "auths_user"."date_joined", "auths_user"."id", "auths_user"."last_hierarchy_id", "auths_user"."last_module_id", "auths_user"."person_id", "auths_user"."updated_at", "auths_user"."registered_by" FROM "auths_user" WHERE "auths_user"."username" = 'admin'; args=('admin',)
[2016-11-28 14:14:42] DEBUG [django.db.backends:89] (0.000) SELECT (1) AS "a" FROM "django_session" WHERE "django_session"."session_key" = 'rl3i6i5da7gib8gwgc01szjk12ram4pm' LIMIT 1; args=('rl3i6i5da7gib8gwgc01szjk12ram4pm',)
[2016-11-28 14:14:42] DEBUG [django.db.backends:89] (0.000) BEGIN; args=None
[2016-11-28 14:14:42] DEBUG [django.db.backends:89] (0.043) INSERT INTO "django_session" ("session_key", "session_data", "expire_date") SELECT 'rl3i6i5da7gib8gwgc01szjk12ram4pm', 'MWM0OGIyODQ4NzI4MzRhZjAyMjIxNmY1YzZlNzUwYmUzNTU2OWFjMTp7fQ==', '2016-12-12 19:14:42.128375'; args=('rl3i6i5da7gib8gwgc01szjk12ram4pm', 'MWM0OGIyODQ4NzI4MzRhZjAyMjIxNmY1YzZlNzUwYmUzNTU2OWFjMTp7fQ==', '2016-12-12 19:14:42.128375')
[2016-11-28 14:14:42] DEBUG [django.db.backends:89] (0.000) SELECT "django_session"."session_key", "django_session"."session_data", "django_session"."expire_date" FROM "django_session" WHERE "django_session"."session_key" = 'rl3i6i5da7gib8gwgc01szjk12ram4pm'; args=('rl3i6i5da7gib8gwgc01szjk12ram4pm',)
[2016-11-28 14:14:42] DEBUG [django.db.backends:89] (0.000) BEGIN; args=None
[2016-11-28 14:14:42] DEBUG [django.db.backends:89] (0.051) DELETE FROM "django_session" WHERE "django_session"."session_key" IN ('rl3i6i5da7gib8gwgc01szjk12ram4pm'); args=('rl3i6i5da7gib8gwgc01szjk12ram4pm',)
[2016-11-28 14:14:42] DEBUG [django.db.backends:89] (0.000) BEGIN; args=None
[2016-11-28 14:14:42] DEBUG [django.db.backends:89] (0.001) UPDATE "auths_user" SET "last_login" = '2016-11-28 19:14:42.558984' WHERE "auths_user"."id" = '98c929be19fb4598b30233dd1ddbfcfd'; args=('2016-11-28 19:14:42.558984', '98c929be19fb4598b30233dd1ddbfcfd')
[2016-11-28 14:14:42] DEBUG [django.db.backends:89] (0.000) BEGIN; args=None
[2016-11-28 14:14:42] DEBUG [django.db.backends:89] (0.000) UPDATE "django_session" SET "session_data" = 'MmQ4ZjkwN2IzN2ViMTU2ZWFhZWYwNTIyZDI3NzM3MTBiMTI4NzEwZDp7Il9hdXRoX3VzZXJfaGFzaCI6Ijg3ZmM3NWRhMjRkYWVjMjdmMGUxMTc5ODYxMzYyYzFhMDliZWI2YTEiLCJfYXV0aF91c2VyX2lkIjoiOThjOTI5YmUtMTlmYi00NTk4LWIzMDItMzNkZDFkZGJmY2ZkIiwiX2F1dGhfdXNlcl9iYWNrZW5kIjoiZGphbmdvLmNvbnRyaWIuYXV0aC5iYWNrZW5kcy5Nb2RlbEJhY2tlbmQifQ==', "expire_date" = '2016-12-12 19:14:42.736445' WHERE "django_session"."session_key" = 'rl3i6i5da7gib8gwgc01szjk12ram4pm'; args=('MmQ4ZjkwN2IzN2ViMTU2ZWFhZWYwNTIyZDI3NzM3MTBiMTI4NzEwZDp7Il9hdXRoX3VzZXJfaGFzaCI6Ijg3ZmM3NWRhMjRkYWVjMjdmMGUxMTc5ODYxMzYyYzFhMDliZWI2YTEiLCJfYXV0aF91c2VyX2lkIjoiOThjOTI5YmUtMTlmYi00NTk4LWIzMDItMzNkZDFkZGJmY2ZkIiwiX2F1dGhfdXNlcl9iYWNrZW5kIjoiZGphbmdvLmNvbnRyaWIuYXV0aC5iYWNrZW5kcy5Nb2RlbEJhY2tlbmQifQ==', '2016-12-12 19:14:42.736445', 'rl3i6i5da7gib8gwgc01szjk12ram4pm')
[2016-11-28 14:14:42] DEBUG [django.db.backends:89] (0.001) INSERT INTO "django_session" ("session_key", "session_data", "expire_date") SELECT 'rl3i6i5da7gib8gwgc01szjk12ram4pm', 'MmQ4ZjkwN2IzN2ViMTU2ZWFhZWYwNTIyZDI3NzM3MTBiMTI4NzEwZDp7Il9hdXRoX3VzZXJfaGFzaCI6Ijg3ZmM3NWRhMjRkYWVjMjdmMGUxMTc5ODYxMzYyYzFhMDliZWI2YTEiLCJfYXV0aF91c2VyX2lkIjoiOThjOTI5YmUtMTlmYi00NTk4LWIzMDItMzNkZDFkZGJmY2ZkIiwiX2F1dGhfdXNlcl9iYWNrZW5kIjoiZGphbmdvLmNvbnRyaWIuYXV0aC5iYWNrZW5kcy5Nb2RlbEJhY2tlbmQifQ==', '2016-12-12 19:14:42.736445'; args=('rl3i6i5da7gib8gwgc01szjk12ram4pm', 'MmQ4ZjkwN2IzN2ViMTU2ZWFhZWYwNTIyZDI3NzM3MTBiMTI4NzEwZDp7Il9hdXRoX3VzZXJfaGFzaCI6Ijg3ZmM3NWRhMjRkYWVjMjdmMGUxMTc5ODYxMzYyYzFhMDliZWI2YTEiLCJfYXV0aF91c2VyX2lkIjoiOThjOTI5YmUtMTlmYi00NTk4LWIzMDItMzNkZDFkZGJmY2ZkIiwiX2F1dGhfdXNlcl9iYWNrZW5kIjoiZGphbmdvLmNvbnRyaWIuYXV0aC5iYWNrZW5kcy5Nb2RlbEJhY2tlbmQifQ==', '2016-12-12 19:14:42.736445')
[2016-11-28 14:14:42] DEBUG [django.db.backends:89] (0.001) SELECT "django_session"."session_key", "django_session"."session_data", "django_session"."expire_date" FROM "django_session" WHERE ("django_session"."expire_date" > '2016-11-28 19:14:42.833988' AND "django_session"."session_key" = 'rl3i6i5da7gib8gwgc01szjk12ram4pm'); args=('2016-11-28 19:14:42.833988', 'rl3i6i5da7gib8gwgc01szjk12ram4pm')
[2016-11-28 14:14:42] DEBUG [django.db.backends:89] (0.000) SELECT "auths_user"."password", "auths_user"."last_login", "auths_user"."is_superuser", "auths_user"."username", "auths_user"."first_name", "auths_user"."last_name", "auths_user"."email", "auths_user"."is_staff", "auths_user"."is_active", "auths_user"."date_joined", "auths_user"."id", "auths_user"."last_hierarchy_id", "auths_user"."last_module_id", "auths_user"."person_id", "auths_user"."updated_at", "auths_user"."registered_by" FROM "auths_user" WHERE "auths_user"."id" = '98c929be19fb4598b30233dd1ddbfcfd'; args=('98c929be19fb4598b30233dd1ddbfcfd',)
[2016-11-28 14:14:42] DEBUG [django.template:927] Exception while resolving variable 'is_popup' in template 'admin/index.html'.
Traceback (most recent call last):
  File "F:\asciacion\proyectoAnalisis\ve_asociacion\lib\site-packages\django\template\base.py", line 883, in _resolve_lookup
    current = current[bit]
  File "F:\asciacion\proyectoAnalisis\ve_asociacion\lib\site-packages\django\template\context.py", line 77, in __getitem__
    raise KeyError(key)
KeyError: 'is_popup'

During handling of the above exception, another exception occurred:

Traceback (most recent call last):
  File "F:\asciacion\proyectoAnalisis\ve_asociacion\lib\site-packages\django\template\base.py", line 889, in _resolve_lookup
    if isinstance(current, BaseContext) and getattr(type(current), bit):
AttributeError: type object 'RequestContext' has no attribute 'is_popup'

During handling of the above exception, another exception occurred:

Traceback (most recent call last):
  File "F:\asciacion\proyectoAnalisis\ve_asociacion\lib\site-packages\django\template\base.py", line 898, in _resolve_lookup
    current = current[int(bit)]
ValueError: invalid literal for int() with base 10: 'is_popup'

During handling of the above exception, another exception occurred:

Traceback (most recent call last):
  File "F:\asciacion\proyectoAnalisis\ve_asociacion\lib\site-packages\django\template\base.py", line 905, in _resolve_lookup
    (bit, current))  # missing attribute
django.template.base.VariableDoesNotExist: Failed lookup for key [is_popup] in "[{'False': False, 'True': True, 'None': None}, {'user': <SimpleLazyObject: <User: admin>>, 'DEFAULT_MESSAGE_LEVELS': {'WARNING': 30, 'DEBUG': 10, 'SUCCESS': 25, 'INFO': 20, 'ERROR': 40}, 'perms': <django.contrib.auth.context_processors.PermWrapper object at 0x000001B535773E80>, 'csrf_token': <SimpleLazyObject: <function csrf.<locals>._get_val at 0x000001B53565E488>>, 'messages': <django.contrib.messages.storage.fallback.FallbackStorage object at 0x000001B53578AE48>, 'request': <WSGIRequest: GET '/admin/'>}, {}, {'title': <django.utils.functional.lazy.<locals>.__proxy__ object at 0x000001B534363780>, 'site_url': '/', 'available_apps': [{'name': 'Asociacion', 'app_label': 'asociacion', 'has_module_perms': True, 'app_url': '/admin/asociacion/', 'models': [{'add_url': '/admin/asociacion/lote/add/', 'admin_url': '/admin/asociacion/lote/', 'name': 'Lotes', 'object_name': 'Lote', 'perms': {'delete': True, 'add': True, 'change': True}}, {'add_url': '/admin/asociacion/manzana/add/', 'admin_url': '/admin/asociacion/manzana/', 'name': 'Manzanas', 'object_name': 'Manzana', 'perms': {'delete': True, 'add': True, 'change': True}}, {'add_url': '/admin/asociacion/sociolote/add/', 'admin_url': '/admin/asociacion/sociolote/', 'name': 'Relacion de socio a lotes', 'object_name': 'SocioLote', 'perms': {'delete': True, 'add': True, 'change': True}}, {'add_url': '/admin/asociacion/socio/add/', 'admin_url': '/admin/asociacion/socio/', 'name': 'Socios', 'object_name': 'Socio', 'perms': {'delete': True, 'add': True, 'change': True}}]}, {'name': <django.utils.functional.lazy.<locals>.__proxy__ object at 0x000001B534363DD8>, 'app_label': 'auth', 'has_module_perms': True, 'app_url': '/admin/auth/', 'models': [{'add_url': '/admin/auth/group/add/', 'admin_url': '/admin/auth/group/', 'name': <django.utils.functional.lazy.<locals>.__proxy__ object at 0x000001B535759128>, 'object_name': 'Group', 'perms': {'delete': True, 'add': True, 'change': True}}, {'add_url': '/admin/auth/permission/add/', 'admin_url': '/admin/auth/permission/', 'name': <django.utils.functional.lazy.<locals>.__proxy__ object at 0x000001B5357590F0>, 'object_name': 'Permission', 'perms': {'delete': True, 'add': True, 'change': True}}]}, {'name': 'Auths', 'app_label': 'auths', 'has_module_perms': True, 'app_url': '/admin/auths/', 'models': [{'add_url': '/admin/auths/hierarchytype/add/', 'admin_url': '/admin/auths/hierarchytype/', 'name': <django.utils.functional.lazy.<locals>.__proxy__ object at 0x000001B53578A550>, 'object_name': 'HierarchyType', 'perms': {'delete': True, 'add': True, 'change': True}}, {'add_url': '/admin/auths/hierarchy/add/', 'admin_url': '/admin/auths/hierarchy/', 'name': <django.utils.functional.lazy.<locals>.__proxy__ object at 0x000001B5356CE3C8>, 'object_name': 'Hierarchy', 'perms': {'delete': True, 'add': True, 'change': True}}, {'add_url': '/admin/auths/menu/add/', 'admin_url': '/admin/auths/menu/', 'name': <django.utils.functional.lazy.<locals>.__proxy__ object at 0x000001B53578A6A0>, 'object_name': 'Menu', 'perms': {'delete': True, 'add': True, 'change': True}}, {'add_url': '/admin/auths/person/add/', 'admin_url': '/admin/auths/person/', 'name': <django.utils.functional.lazy.<locals>.__proxy__ object at 0x000001B535759A20>, 'object_name': 'Person', 'perms': {'delete': True, 'add': True, 'change': True}}, {'add_url': '/admin/auths/userhierarchygroup/add/', 'admin_url': '/admin/auths/userhierarchygroup/', 'name': <django.utils.functional.lazy.<locals>.__proxy__ object at 0x000001B5357599E8>, 'object_name': 'UserHierarchyGroup', 'perms': {'delete': True, 'add': True, 'change': True}}, {'add_url': '/admin/auths/userhierarchypermission/add/', 'admin_url': '/admin/auths/userhierarchypermission/', 'name': <django.utils.functional.lazy.<locals>.__proxy__ object at 0x000001B535759208>, 'object_name': 'UserHierarchyPermission', 'perms': {'delete': True, 'add': True, 'change': True}}, {'add_url': '/admin/auths/user/add/', 'admin_url': '/admin/auths/user/', 'name': <django.utils.functional.lazy.<locals>.__proxy__ object at 0x000001B535759198>, 'object_name': 'User', 'perms': {'delete': True, 'add': True, 'change': True}}]}, {'name': 'Catalogo', 'app_label': 'catalogo', 'has_module_perms': True, 'app_url': '/admin/catalogo/', 'models': [{'add_url': '/admin/catalogo/autor/add/', 'admin_url': '/admin/catalogo/autor/', 'name': 'Autores', 'object_name': 'Autor', 'perms': {'delete': True, 'add': True, 'change': True}}, {'add_url': '/admin/catalogo/categoria/add/', 'admin_url': '/admin/catalogo/categoria/', 'name': 'Categorias', 'object_name': 'Categoria', 'perms': {'delete': True, 'add': True, 'change': True}}, {'add_url': '/admin/catalogo/libro/add/', 'admin_url': '/admin/catalogo/libro/', 'name': 'Libros', 'object_name': 'Libro', 'perms': {'delete': True, 'add': True, 'change': True}}]}, {'name': <django.utils.functional.lazy.<locals>.__proxy__ object at 0x000001B53436B518>, 'app_label': 'contenttypes', 'has_module_perms': True, 'app_url': '/admin/contenttypes/', 'models': [{'add_url': '/admin/contenttypes/contenttype/add/', 'admin_url': '/admin/contenttypes/contenttype/', 'name': <django.utils.functional.lazy.<locals>.__proxy__ object at 0x000001B5357590B8>, 'object_name': 'ContentType', 'perms': {'delete': True, 'add': True, 'change': True}}]}, {'name': 'Django OAuth Toolkit', 'app_label': 'oauth2_provider', 'has_module_perms': True, 'app_url': '/admin/oauth2_provider/', 'models': [{'add_url': '/admin/oauth2_provider/accesstoken/add/', 'admin_url': '/admin/oauth2_provider/accesstoken/', 'name': <django.utils.functional.lazy.<locals>.__proxy__ object at 0x000001B53572EDA0>, 'object_name': 'AccessToken', 'perms': {'delete': True, 'add': True, 'change': True}}, {'add_url': '/admin/oauth2_provider/application/add/', 'admin_url': '/admin/oauth2_provider/application/', 'name': <django.utils.functional.lazy.<locals>.__proxy__ object at 0x000001B53578A5F8>, 'object_name': 'Application', 'perms': {'delete': True, 'add': True, 'change': True}}, {'add_url': '/admin/oauth2_provider/grant/add/', 'admin_url': '/admin/oauth2_provider/grant/', 'name': <django.utils.functional.lazy.<locals>.__proxy__ object at 0x000001B535759160>, 'object_name': 'Grant', 'perms': {'delete': True, 'add': True, 'change': True}}, {'add_url': '/admin/oauth2_provider/refreshtoken/add/', 'admin_url': '/admin/oauth2_provider/refreshtoken/', 'name': <django.utils.functional.lazy.<locals>.__proxy__ object at 0x000001B5357591D0>, 'object_name': 'RefreshToken', 'perms': {'delete': True, 'add': True, 'change': True}}]}, {'name': 'Eventos', 'app_label': 'eventos', 'has_module_perms': True, 'app_url': '/admin/eventos/', 'models': [{'add_url': '/admin/eventos/asistencia/add/', 'admin_url': '/admin/eventos/asistencia/', 'name': 'Asistencias', 'object_name': 'Asistencia', 'perms': {'delete': True, 'add': True, 'change': True}}, {'add_url': '/admin/eventos/evento/add/', 'admin_url': '/admin/eventos/evento/', 'name': 'Eventos', 'object_name': 'Evento', 'perms': {'delete': True, 'add': True, 'change': True}}, {'add_url': '/admin/eventos/inasistencia/add/', 'admin_url': '/admin/eventos/inasistencia/', 'name': 'Inasistencias', 'object_name': 'Inasistencia', 'perms': {'delete': True, 'add': True, 'change': True}}]}, {'name': 'Pagos', 'app_label': 'pagos', 'has_module_perms': True, 'app_url': '/admin/pagos/', 'models': [{'add_url': '/admin/pagos/pago/add/', 'admin_url': '/admin/pagos/pago/', 'name': 'Pagos', 'object_name': 'Pago', 'perms': {'delete': True, 'add': True, 'change': True}}, {'add_url': '/admin/pagos/periodo/add/', 'admin_url': '/admin/pagos/periodo/', 'name': 'Periodos', 'object_name': 'Periodo', 'perms': {'delete': True, 'add': True, 'change': True}}]}], 'LANGUAGE_CODE': 'en-us', 'has_permission': True, 'site_title': <django.utils.functional.lazy.<locals>.__proxy__ object at 0x000001B534363278>, 'site_header': <django.utils.functional.lazy.<locals>.__proxy__ object at 0x000001B534363320>, 'LANGUAGE_BIDI': False, 'app_list': [{'name': 'Asociacion', 'app_label': 'asociacion', 'has_module_perms': True, 'app_url': '/admin/asociacion/', 'models': [{'add_url': '/admin/asociacion/lote/add/', 'admin_url': '/admin/asociacion/lote/', 'name': 'Lotes', 'object_name': 'Lote', 'perms': {'delete': True, 'add': True, 'change': True}}, {'add_url': '/admin/asociacion/manzana/add/', 'admin_url': '/admin/asociacion/manzana/', 'name': 'Manzanas', 'object_name': 'Manzana', 'perms': {'delete': True, 'add': True, 'change': True}}, {'add_url': '/admin/asociacion/sociolote/add/', 'admin_url': '/admin/asociacion/sociolote/', 'name': 'Relacion de socio a lotes', 'object_name': 'SocioLote', 'perms': {'delete': True, 'add': True, 'change': True}}, {'add_url': '/admin/asociacion/socio/add/', 'admin_url': '/admin/asociacion/socio/', 'name': 'Socios', 'object_name': 'Socio', 'perms': {'delete': True, 'add': True, 'change': True}}]}, {'name': <django.utils.functional.lazy.<locals>.__proxy__ object at 0x000001B534363DD8>, 'app_label': 'auth', 'has_module_perms': True, 'app_url': '/admin/auth/', 'models': [{'add_url': '/admin/auth/group/add/', 'admin_url': '/admin/auth/group/', 'name': <django.utils.functional.lazy.<locals>.__proxy__ object at 0x000001B53578A4E0>, 'object_name': 'Group', 'perms': {'delete': True, 'add': True, 'change': True}}, {'add_url': '/admin/auth/permission/add/', 'admin_url': '/admin/auth/permission/', 'name': <django.utils.functional.lazy.<locals>.__proxy__ object at 0x000001B53578AF28>, 'object_name': 'Permission', 'perms': {'delete': True, 'add': True, 'change': True}}]}, {'name': 'Auths', 'app_label': 'auths', 'has_module_perms': True, 'app_url': '/admin/auths/', 'models': [{'add_url': '/admin/auths/hierarchytype/add/', 'admin_url': '/admin/auths/hierarchytype/', 'name': <django.utils.functional.lazy.<locals>.__proxy__ object at 0x000001B53578AC18>, 'object_name': 'HierarchyType', 'perms': {'delete': True, 'add': True, 'change': True}}, {'add_url': '/admin/auths/hierarchy/add/', 'admin_url': '/admin/auths/hierarchy/', 'name': <django.utils.functional.lazy.<locals>.__proxy__ object at 0x000001B53578A390>, 'object_name': 'Hierarchy', 'perms': {'delete': True, 'add': True, 'change': True}}, {'add_url': '/admin/auths/menu/add/', 'admin_url': '/admin/auths/menu/', 'name': <django.utils.functional.lazy.<locals>.__proxy__ object at 0x000001B53578AA58>, 'object_name': 'Menu', 'perms': {'delete': True, 'add': True, 'change': True}}, {'add_url': '/admin/auths/person/add/', 'admin_url': '/admin/auths/person/', 'name': <django.utils.functional.lazy.<locals>.__proxy__ object at 0x000001B53578A2B0>, 'object_name': 'Person', 'perms': {'delete': True, 'add': True, 'change': True}}, {'add_url': '/admin/auths/userhierarchygroup/add/', 'admin_url': '/admin/auths/userhierarchygroup/', 'name': <django.utils.functional.lazy.<locals>.__proxy__ object at 0x000001B53578A358>, 'object_name': 'UserHierarchyGroup', 'perms': {'delete': True, 'add': True, 'change': True}}, {'add_url': '/admin/auths/userhierarchypermission/add/', 'admin_url': '/admin/auths/userhierarchypermission/', 'name': <django.utils.functional.lazy.<locals>.__proxy__ object at 0x000001B53578A9B0>, 'object_name': 'UserHierarchyPermission', 'perms': {'delete': True, 'add': True, 'change': True}}, {'add_url': '/admin/auths/user/add/', 'admin_url': '/admin/auths/user/', 'name': <django.utils.functional.lazy.<locals>.__proxy__ object at 0x000001B53578A4A8>, 'object_name': 'User', 'perms': {'delete': True, 'add': True, 'change': True}}]}, {'name': 'Catalogo', 'app_label': 'catalogo', 'has_module_perms': True, 'app_url': '/admin/catalogo/', 'models': [{'add_url': '/admin/catalogo/autor/add/', 'admin_url': '/admin/catalogo/autor/', 'name': 'Autores', 'object_name': 'Autor', 'perms': {'delete': True, 'add': True, 'change': True}}, {'add_url': '/admin/catalogo/categoria/add/', 'admin_url': '/admin/catalogo/categoria/', 'name': 'Categorias', 'object_name': 'Categoria', 'perms': {'delete': True, 'add': True, 'change': True}}, {'add_url': '/admin/catalogo/libro/add/', 'admin_url': '/admin/catalogo/libro/', 'name': 'Libros', 'object_name': 'Libro', 'perms': {'delete': True, 'add': True, 'change': True}}]}, {'name': <django.utils.functional.lazy.<locals>.__proxy__ object at 0x000001B53436B518>, 'app_label': 'contenttypes', 'has_module_perms': True, 'app_url': '/admin/contenttypes/', 'models': [{'add_url': '/admin/contenttypes/contenttype/add/', 'admin_url': '/admin/contenttypes/contenttype/', 'name': <django.utils.functional.lazy.<locals>.__proxy__ object at 0x000001B53578AC88>, 'object_name': 'ContentType', 'perms': {'delete': True, 'add': True, 'change': True}}]}, {'name': 'Django OAuth Toolkit', 'app_label': 'oauth2_provider', 'has_module_perms': True, 'app_url': '/admin/oauth2_provider/', 'models': [{'add_url': '/admin/oauth2_provider/accesstoken/add/', 'admin_url': '/admin/oauth2_provider/accesstoken/', 'name': <django.utils.functional.lazy.<locals>.__proxy__ object at 0x000001B53578AC50>, 'object_name': 'AccessToken', 'perms': {'delete': True, 'add': True, 'change': True}}, {'add_url': '/admin/oauth2_provider/application/add/', 'admin_url': '/admin/oauth2_provider/application/', 'name': <django.utils.functional.lazy.<locals>.__proxy__ object at 0x000001B53578ACF8>, 'object_name': 'Application', 'perms': {'delete': True, 'add': True, 'change': True}}, {'add_url': '/admin/oauth2_provider/grant/add/', 'admin_url': '/admin/oauth2_provider/grant/', 'name': <django.utils.functional.lazy.<locals>.__proxy__ object at 0x000001B53578A9E8>, 'object_name': 'Grant', 'perms': {'delete': True, 'add': True, 'change': True}}, {'add_url': '/admin/oauth2_provider/refreshtoken/add/', 'admin_url': '/admin/oauth2_provider/refreshtoken/', 'name': <django.utils.functional.lazy.<locals>.__proxy__ object at 0x000001B53578A940>, 'object_name': 'RefreshToken', 'perms': {'delete': True, 'add': True, 'change': True}}]}, {'name': 'Eventos', 'app_label': 'eventos', 'has_module_perms': True, 'app_url': '/admin/eventos/', 'models': [{'add_url': '/admin/eventos/asistencia/add/', 'admin_url': '/admin/eventos/asistencia/', 'name': 'Asistencias', 'object_name': 'Asistencia', 'perms': {'delete': True, 'add': True, 'change': True}}, {'add_url': '/admin/eventos/evento/add/', 'admin_url': '/admin/eventos/evento/', 'name': 'Eventos', 'object_name': 'Evento', 'perms': {'delete': True, 'add': True, 'change': True}}, {'add_url': '/admin/eventos/inasistencia/add/', 'admin_url': '/admin/eventos/inasistencia/', 'name': 'Inasistencias', 'object_name': 'Inasistencia', 'perms': {'delete': True, 'add': True, 'change': True}}]}, {'name': 'Pagos', 'app_label': 'pagos', 'has_module_perms': True, 'app_url': '/admin/pagos/', 'models': [{'add_url': '/admin/pagos/pago/add/', 'admin_url': '/admin/pagos/pago/', 'name': 'Pagos', 'object_name': 'Pago', 'perms': {'delete': True, 'add': True, 'change': True}}, {'add_url': '/admin/pagos/periodo/add/', 'admin_url': '/admin/pagos/periodo/', 'name': 'Periodos', 'object_name': 'Periodo', 'perms': {'delete': True, 'add': True, 'change': True}}]}]}]"
[2016-11-28 14:14:42] DEBUG [django.template:927] Exception while resolving variable 'is_popup' in template 'admin/index.html'.
Traceback (most recent call last):
  File "F:\asciacion\proyectoAnalisis\ve_asociacion\lib\site-packages\django\template\base.py", line 883, in _resolve_lookup
    current = current[bit]
  File "F:\asciacion\proyectoAnalisis\ve_asociacion\lib\site-packages\django\template\context.py", line 77, in __getitem__
    raise KeyError(key)
KeyError: 'is_popup'

During handling of the above exception, another exception occurred:

Traceback (most recent call last):
  File "F:\asciacion\proyectoAnalisis\ve_asociacion\lib\site-packages\django\template\base.py", line 889, in _resolve_lookup
    if isinstance(current, BaseContext) and getattr(type(current), bit):
AttributeError: type object 'RequestContext' has no attribute 'is_popup'

During handling of the above exception, another exception occurred:

Traceback (most recent call last):
  File "F:\asciacion\proyectoAnalisis\ve_asociacion\lib\site-packages\django\template\base.py", line 898, in _resolve_lookup
    current = current[int(bit)]
ValueError: invalid literal for int() with base 10: 'is_popup'

During handling of the above exception, another exception occurred:

Traceback (most recent call last):
  File "F:\asciacion\proyectoAnalisis\ve_asociacion\lib\site-packages\django\template\base.py", line 905, in _resolve_lookup
    (bit, current))  # missing attribute
django.template.base.VariableDoesNotExist: Failed lookup for key [is_popup] in "[{'False': False, 'True': True, 'None': None}, {'user': <SimpleLazyObject: <User: admin>>, 'DEFAULT_MESSAGE_LEVELS': {'WARNING': 30, 'DEBUG': 10, 'SUCCESS': 25, 'INFO': 20, 'ERROR': 40}, 'perms': <django.contrib.auth.context_processors.PermWrapper object at 0x000001B535773E80>, 'csrf_token': <SimpleLazyObject: <function csrf.<locals>._get_val at 0x000001B53565E488>>, 'messages': <django.contrib.messages.storage.fallback.FallbackStorage object at 0x000001B53578AE48>, 'request': <WSGIRequest: GET '/admin/'>}, {}, {'title': <django.utils.functional.lazy.<locals>.__proxy__ object at 0x000001B534363780>, 'site_url': '/', 'available_apps': [{'name': 'Asociacion', 'app_label': 'asociacion', 'has_module_perms': True, 'app_url': '/admin/asociacion/', 'models': [{'add_url': '/admin/asociacion/lote/add/', 'admin_url': '/admin/asociacion/lote/', 'name': 'Lotes', 'object_name': 'Lote', 'perms': {'delete': True, 'add': True, 'change': True}}, {'add_url': '/admin/asociacion/manzana/add/', 'admin_url': '/admin/asociacion/manzana/', 'name': 'Manzanas', 'object_name': 'Manzana', 'perms': {'delete': True, 'add': True, 'change': True}}, {'add_url': '/admin/asociacion/sociolote/add/', 'admin_url': '/admin/asociacion/sociolote/', 'name': 'Relacion de socio a lotes', 'object_name': 'SocioLote', 'perms': {'delete': True, 'add': True, 'change': True}}, {'add_url': '/admin/asociacion/socio/add/', 'admin_url': '/admin/asociacion/socio/', 'name': 'Socios', 'object_name': 'Socio', 'perms': {'delete': True, 'add': True, 'change': True}}]}, {'name': <django.utils.functional.lazy.<locals>.__proxy__ object at 0x000001B534363DD8>, 'app_label': 'auth', 'has_module_perms': True, 'app_url': '/admin/auth/', 'models': [{'add_url': '/admin/auth/group/add/', 'admin_url': '/admin/auth/group/', 'name': <django.utils.functional.lazy.<locals>.__proxy__ object at 0x000001B535759128>, 'object_name': 'Group', 'perms': {'delete': True, 'add': True, 'change': True}}, {'add_url': '/admin/auth/permission/add/', 'admin_url': '/admin/auth/permission/', 'name': <django.utils.functional.lazy.<locals>.__proxy__ object at 0x000001B5357590F0>, 'object_name': 'Permission', 'perms': {'delete': True, 'add': True, 'change': True}}]}, {'name': 'Auths', 'app_label': 'auths', 'has_module_perms': True, 'app_url': '/admin/auths/', 'models': [{'add_url': '/admin/auths/hierarchytype/add/', 'admin_url': '/admin/auths/hierarchytype/', 'name': <django.utils.functional.lazy.<locals>.__proxy__ object at 0x000001B53578A550>, 'object_name': 'HierarchyType', 'perms': {'delete': True, 'add': True, 'change': True}}, {'add_url': '/admin/auths/hierarchy/add/', 'admin_url': '/admin/auths/hierarchy/', 'name': <django.utils.functional.lazy.<locals>.__proxy__ object at 0x000001B5356CE3C8>, 'object_name': 'Hierarchy', 'perms': {'delete': True, 'add': True, 'change': True}}, {'add_url': '/admin/auths/menu/add/', 'admin_url': '/admin/auths/menu/', 'name': <django.utils.functional.lazy.<locals>.__proxy__ object at 0x000001B53578A6A0>, 'object_name': 'Menu', 'perms': {'delete': True, 'add': True, 'change': True}}, {'add_url': '/admin/auths/person/add/', 'admin_url': '/admin/auths/person/', 'name': <django.utils.functional.lazy.<locals>.__proxy__ object at 0x000001B535759A20>, 'object_name': 'Person', 'perms': {'delete': True, 'add': True, 'change': True}}, {'add_url': '/admin/auths/userhierarchygroup/add/', 'admin_url': '/admin/auths/userhierarchygroup/', 'name': <django.utils.functional.lazy.<locals>.__proxy__ object at 0x000001B5357599E8>, 'object_name': 'UserHierarchyGroup', 'perms': {'delete': True, 'add': True, 'change': True}}, {'add_url': '/admin/auths/userhierarchypermission/add/', 'admin_url': '/admin/auths/userhierarchypermission/', 'name': <django.utils.functional.lazy.<locals>.__proxy__ object at 0x000001B535759208>, 'object_name': 'UserHierarchyPermission', 'perms': {'delete': True, 'add': True, 'change': True}}, {'add_url': '/admin/auths/user/add/', 'admin_url': '/admin/auths/user/', 'name': <django.utils.functional.lazy.<locals>.__proxy__ object at 0x000001B535759198>, 'object_name': 'User', 'perms': {'delete': True, 'add': True, 'change': True}}]}, {'name': 'Catalogo', 'app_label': 'catalogo', 'has_module_perms': True, 'app_url': '/admin/catalogo/', 'models': [{'add_url': '/admin/catalogo/autor/add/', 'admin_url': '/admin/catalogo/autor/', 'name': 'Autores', 'object_name': 'Autor', 'perms': {'delete': True, 'add': True, 'change': True}}, {'add_url': '/admin/catalogo/categoria/add/', 'admin_url': '/admin/catalogo/categoria/', 'name': 'Categorias', 'object_name': 'Categoria', 'perms': {'delete': True, 'add': True, 'change': True}}, {'add_url': '/admin/catalogo/libro/add/', 'admin_url': '/admin/catalogo/libro/', 'name': 'Libros', 'object_name': 'Libro', 'perms': {'delete': True, 'add': True, 'change': True}}]}, {'name': <django.utils.functional.lazy.<locals>.__proxy__ object at 0x000001B53436B518>, 'app_label': 'contenttypes', 'has_module_perms': True, 'app_url': '/admin/contenttypes/', 'models': [{'add_url': '/admin/contenttypes/contenttype/add/', 'admin_url': '/admin/contenttypes/contenttype/', 'name': <django.utils.functional.lazy.<locals>.__proxy__ object at 0x000001B5357590B8>, 'object_name': 'ContentType', 'perms': {'delete': True, 'add': True, 'change': True}}]}, {'name': 'Django OAuth Toolkit', 'app_label': 'oauth2_provider', 'has_module_perms': True, 'app_url': '/admin/oauth2_provider/', 'models': [{'add_url': '/admin/oauth2_provider/accesstoken/add/', 'admin_url': '/admin/oauth2_provider/accesstoken/', 'name': <django.utils.functional.lazy.<locals>.__proxy__ object at 0x000001B53572EDA0>, 'object_name': 'AccessToken', 'perms': {'delete': True, 'add': True, 'change': True}}, {'add_url': '/admin/oauth2_provider/application/add/', 'admin_url': '/admin/oauth2_provider/application/', 'name': <django.utils.functional.lazy.<locals>.__proxy__ object at 0x000001B53578A5F8>, 'object_name': 'Application', 'perms': {'delete': True, 'add': True, 'change': True}}, {'add_url': '/admin/oauth2_provider/grant/add/', 'admin_url': '/admin/oauth2_provider/grant/', 'name': <django.utils.functional.lazy.<locals>.__proxy__ object at 0x000001B535759160>, 'object_name': 'Grant', 'perms': {'delete': True, 'add': True, 'change': True}}, {'add_url': '/admin/oauth2_provider/refreshtoken/add/', 'admin_url': '/admin/oauth2_provider/refreshtoken/', 'name': <django.utils.functional.lazy.<locals>.__proxy__ object at 0x000001B5357591D0>, 'object_name': 'RefreshToken', 'perms': {'delete': True, 'add': True, 'change': True}}]}, {'name': 'Eventos', 'app_label': 'eventos', 'has_module_perms': True, 'app_url': '/admin/eventos/', 'models': [{'add_url': '/admin/eventos/asistencia/add/', 'admin_url': '/admin/eventos/asistencia/', 'name': 'Asistencias', 'object_name': 'Asistencia', 'perms': {'delete': True, 'add': True, 'change': True}}, {'add_url': '/admin/eventos/evento/add/', 'admin_url': '/admin/eventos/evento/', 'name': 'Eventos', 'object_name': 'Evento', 'perms': {'delete': True, 'add': True, 'change': True}}, {'add_url': '/admin/eventos/inasistencia/add/', 'admin_url': '/admin/eventos/inasistencia/', 'name': 'Inasistencias', 'object_name': 'Inasistencia', 'perms': {'delete': True, 'add': True, 'change': True}}]}, {'name': 'Pagos', 'app_label': 'pagos', 'has_module_perms': True, 'app_url': '/admin/pagos/', 'models': [{'add_url': '/admin/pagos/pago/add/', 'admin_url': '/admin/pagos/pago/', 'name': 'Pagos', 'object_name': 'Pago', 'perms': {'delete': True, 'add': True, 'change': True}}, {'add_url': '/admin/pagos/periodo/add/', 'admin_url': '/admin/pagos/periodo/', 'name': 'Periodos', 'object_name': 'Periodo', 'perms': {'delete': True, 'add': True, 'change': True}}]}], 'LANGUAGE_CODE': 'en-us', 'has_permission': True, 'site_title': <django.utils.functional.lazy.<locals>.__proxy__ object at 0x000001B534363278>, 'site_header': <django.utils.functional.lazy.<locals>.__proxy__ object at 0x000001B534363320>, 'LANGUAGE_BIDI': False, 'app_list': [{'name': 'Asociacion', 'app_label': 'asociacion', 'has_module_perms': True, 'app_url': '/admin/asociacion/', 'models': [{'add_url': '/admin/asociacion/lote/add/', 'admin_url': '/admin/asociacion/lote/', 'name': 'Lotes', 'object_name': 'Lote', 'perms': {'delete': True, 'add': True, 'change': True}}, {'add_url': '/admin/asociacion/manzana/add/', 'admin_url': '/admin/asociacion/manzana/', 'name': 'Manzanas', 'object_name': 'Manzana', 'perms': {'delete': True, 'add': True, 'change': True}}, {'add_url': '/admin/asociacion/sociolote/add/', 'admin_url': '/admin/asociacion/sociolote/', 'name': 'Relacion de socio a lotes', 'object_name': 'SocioLote', 'perms': {'delete': True, 'add': True, 'change': True}}, {'add_url': '/admin/asociacion/socio/add/', 'admin_url': '/admin/asociacion/socio/', 'name': 'Socios', 'object_name': 'Socio', 'perms': {'delete': True, 'add': True, 'change': True}}]}, {'name': <django.utils.functional.lazy.<locals>.__proxy__ object at 0x000001B534363DD8>, 'app_label': 'auth', 'has_module_perms': True, 'app_url': '/admin/auth/', 'models': [{'add_url': '/admin/auth/group/add/', 'admin_url': '/admin/auth/group/', 'name': <django.utils.functional.lazy.<locals>.__proxy__ object at 0x000001B53578A4E0>, 'object_name': 'Group', 'perms': {'delete': True, 'add': True, 'change': True}}, {'add_url': '/admin/auth/permission/add/', 'admin_url': '/admin/auth/permission/', 'name': <django.utils.functional.lazy.<locals>.__proxy__ object at 0x000001B53578AF28>, 'object_name': 'Permission', 'perms': {'delete': True, 'add': True, 'change': True}}]}, {'name': 'Auths', 'app_label': 'auths', 'has_module_perms': True, 'app_url': '/admin/auths/', 'models': [{'add_url': '/admin/auths/hierarchytype/add/', 'admin_url': '/admin/auths/hierarchytype/', 'name': <django.utils.functional.lazy.<locals>.__proxy__ object at 0x000001B53578AC18>, 'object_name': 'HierarchyType', 'perms': {'delete': True, 'add': True, 'change': True}}, {'add_url': '/admin/auths/hierarchy/add/', 'admin_url': '/admin/auths/hierarchy/', 'name': <django.utils.functional.lazy.<locals>.__proxy__ object at 0x000001B53578A390>, 'object_name': 'Hierarchy', 'perms': {'delete': True, 'add': True, 'change': True}}, {'add_url': '/admin/auths/menu/add/', 'admin_url': '/admin/auths/menu/', 'name': <django.utils.functional.lazy.<locals>.__proxy__ object at 0x000001B53578AA58>, 'object_name': 'Menu', 'perms': {'delete': True, 'add': True, 'change': True}}, {'add_url': '/admin/auths/person/add/', 'admin_url': '/admin/auths/person/', 'name': <django.utils.functional.lazy.<locals>.__proxy__ object at 0x000001B53578A2B0>, 'object_name': 'Person', 'perms': {'delete': True, 'add': True, 'change': True}}, {'add_url': '/admin/auths/userhierarchygroup/add/', 'admin_url': '/admin/auths/userhierarchygroup/', 'name': <django.utils.functional.lazy.<locals>.__proxy__ object at 0x000001B53578A358>, 'object_name': 'UserHierarchyGroup', 'perms': {'delete': True, 'add': True, 'change': True}}, {'add_url': '/admin/auths/userhierarchypermission/add/', 'admin_url': '/admin/auths/userhierarchypermission/', 'name': <django.utils.functional.lazy.<locals>.__proxy__ object at 0x000001B53578A9B0>, 'object_name': 'UserHierarchyPermission', 'perms': {'delete': True, 'add': True, 'change': True}}, {'add_url': '/admin/auths/user/add/', 'admin_url': '/admin/auths/user/', 'name': <django.utils.functional.lazy.<locals>.__proxy__ object at 0x000001B53578A4A8>, 'object_name': 'User', 'perms': {'delete': True, 'add': True, 'change': True}}]}, {'name': 'Catalogo', 'app_label': 'catalogo', 'has_module_perms': True, 'app_url': '/admin/catalogo/', 'models': [{'add_url': '/admin/catalogo/autor/add/', 'admin_url': '/admin/catalogo/autor/', 'name': 'Autores', 'object_name': 'Autor', 'perms': {'delete': True, 'add': True, 'change': True}}, {'add_url': '/admin/catalogo/categoria/add/', 'admin_url': '/admin/catalogo/categoria/', 'name': 'Categorias', 'object_name': 'Categoria', 'perms': {'delete': True, 'add': True, 'change': True}}, {'add_url': '/admin/catalogo/libro/add/', 'admin_url': '/admin/catalogo/libro/', 'name': 'Libros', 'object_name': 'Libro', 'perms': {'delete': True, 'add': True, 'change': True}}]}, {'name': <django.utils.functional.lazy.<locals>.__proxy__ object at 0x000001B53436B518>, 'app_label': 'contenttypes', 'has_module_perms': True, 'app_url': '/admin/contenttypes/', 'models': [{'add_url': '/admin/contenttypes/contenttype/add/', 'admin_url': '/admin/contenttypes/contenttype/', 'name': <django.utils.functional.lazy.<locals>.__proxy__ object at 0x000001B53578AC88>, 'object_name': 'ContentType', 'perms': {'delete': True, 'add': True, 'change': True}}]}, {'name': 'Django OAuth Toolkit', 'app_label': 'oauth2_provider', 'has_module_perms': True, 'app_url': '/admin/oauth2_provider/', 'models': [{'add_url': '/admin/oauth2_provider/accesstoken/add/', 'admin_url': '/admin/oauth2_provider/accesstoken/', 'name': <django.utils.functional.lazy.<locals>.__proxy__ object at 0x000001B53578AC50>, 'object_name': 'AccessToken', 'perms': {'delete': True, 'add': True, 'change': True}}, {'add_url': '/admin/oauth2_provider/application/add/', 'admin_url': '/admin/oauth2_provider/application/', 'name': <django.utils.functional.lazy.<locals>.__proxy__ object at 0x000001B53578ACF8>, 'object_name': 'Application', 'perms': {'delete': True, 'add': True, 'change': True}}, {'add_url': '/admin/oauth2_provider/grant/add/', 'admin_url': '/admin/oauth2_provider/grant/', 'name': <django.utils.functional.lazy.<locals>.__proxy__ object at 0x000001B53578A9E8>, 'object_name': 'Grant', 'perms': {'delete': True, 'add': True, 'change': True}}, {'add_url': '/admin/oauth2_provider/refreshtoken/add/', 'admin_url': '/admin/oauth2_provider/refreshtoken/', 'name': <django.utils.functional.lazy.<locals>.__proxy__ object at 0x000001B53578A940>, 'object_name': 'RefreshToken', 'perms': {'delete': True, 'add': True, 'change': True}}]}, {'name': 'Eventos', 'app_label': 'eventos', 'has_module_perms': True, 'app_url': '/admin/eventos/', 'models': [{'add_url': '/admin/eventos/asistencia/add/', 'admin_url': '/admin/eventos/asistencia/', 'name': 'Asistencias', 'object_name': 'Asistencia', 'perms': {'delete': True, 'add': True, 'change': True}}, {'add_url': '/admin/eventos/evento/add/', 'admin_url': '/admin/eventos/evento/', 'name': 'Eventos', 'object_name': 'Evento', 'perms': {'delete': True, 'add': True, 'change': True}}, {'add_url': '/admin/eventos/inasistencia/add/', 'admin_url': '/admin/eventos/inasistencia/', 'name': 'Inasistencias', 'object_name': 'Inasistencia', 'perms': {'delete': True, 'add': True, 'change': True}}]}, {'name': 'Pagos', 'app_label': 'pagos', 'has_module_perms': True, 'app_url': '/admin/pagos/', 'models': [{'add_url': '/admin/pagos/pago/add/', 'admin_url': '/admin/pagos/pago/', 'name': 'Pagos', 'object_name': 'Pago', 'perms': {'delete': True, 'add': True, 'change': True}}, {'add_url': '/admin/pagos/periodo/add/', 'admin_url': '/admin/pagos/periodo/', 'name': 'Periodos', 'object_name': 'Periodo', 'perms': {'delete': True, 'add': True, 'change': True}}]}]}]"
[2016-11-28 14:14:42] DEBUG [django.db.backends:89] (0.000) SELECT "django_admin_log"."id", "django_admin_log"."action_time", "django_admin_log"."user_id", "django_admin_log"."content_type_id", "django_admin_log"."object_id", "django_admin_log"."object_repr", "django_admin_log"."action_flag", "django_admin_log"."change_message", "auths_user"."password", "auths_user"."last_login", "auths_user"."is_superuser", "auths_user"."username", "auths_user"."first_name", "auths_user"."last_name", "auths_user"."email", "auths_user"."is_staff", "auths_user"."is_active", "auths_user"."date_joined", "auths_user"."id", "auths_user"."last_hierarchy_id", "auths_user"."last_module_id", "auths_user"."person_id", "auths_user"."updated_at", "auths_user"."registered_by", "django_content_type"."id", "django_content_type"."app_label", "django_content_type"."model" FROM "django_admin_log" INNER JOIN "auths_user" ON ("django_admin_log"."user_id" = "auths_user"."id") LEFT OUTER JOIN "django_content_type" ON ("django_admin_log"."content_type_id" = "django_content_type"."id") WHERE "django_admin_log"."user_id" = '98c929be19fb4598b30233dd1ddbfcfd' ORDER BY "django_admin_log"."action_time" DESC LIMIT 10; args=('98c929be19fb4598b30233dd1ddbfcfd',)
[2016-11-28 14:14:53] DEBUG [django.db.backends:89] (0.001) SELECT "oauth2_provider_application"."id", "oauth2_provider_application"."client_id", "oauth2_provider_application"."user_id", "oauth2_provider_application"."redirect_uris", "oauth2_provider_application"."client_type", "oauth2_provider_application"."authorization_grant_type", "oauth2_provider_application"."client_secret", "oauth2_provider_application"."name", "oauth2_provider_application"."skip_authorization" FROM "oauth2_provider_application" WHERE "oauth2_provider_application"."client_id" = '1mDR3zdKmNxeMHoqSJfOfX4JBwSvw93zRK2GaZ61'; args=('1mDR3zdKmNxeMHoqSJfOfX4JBwSvw93zRK2GaZ61',)
[2016-11-28 14:14:53] DEBUG [django.db.backends:89] (0.001) SELECT "auths_user"."password", "auths_user"."last_login", "auths_user"."is_superuser", "auths_user"."username", "auths_user"."first_name", "auths_user"."last_name", "auths_user"."email", "auths_user"."is_staff", "auths_user"."is_active", "auths_user"."date_joined", "auths_user"."id", "auths_user"."last_hierarchy_id", "auths_user"."last_module_id", "auths_user"."person_id", "auths_user"."updated_at", "auths_user"."registered_by" FROM "auths_user" WHERE "auths_user"."username" = 'admin'; args=('admin',)
[2016-11-28 14:14:53] DEBUG [django.db.backends:89] (0.000) BEGIN; args=None
[2016-11-28 14:14:53] DEBUG [django.db.backends:89] (0.034) INSERT INTO "oauth2_provider_accesstoken" ("user_id", "token", "application_id", "expires", "scope") VALUES ('98c929be19fb4598b30233dd1ddbfcfd', 'qmf9QfErONF5S17cVTqYwPYJ7evE0U', 1, '2016-11-29 05:14:53.626194', 'write read'); args=['98c929be19fb4598b30233dd1ddbfcfd', 'qmf9QfErONF5S17cVTqYwPYJ7evE0U', 1, '2016-11-29 05:14:53.626194', 'write read']
[2016-11-28 14:14:53] DEBUG [django.db.backends:89] (0.000) BEGIN; args=None
[2016-11-28 14:14:53] DEBUG [django.db.backends:89] (0.002) INSERT INTO "oauth2_provider_refreshtoken" ("user_id", "token", "application_id", "access_token_id") VALUES ('98c929be19fb4598b30233dd1ddbfcfd', 'bnM6siEt3tXEhI4jipsVI7oFL6VtdI', 1, 39); args=['98c929be19fb4598b30233dd1ddbfcfd', 'bnM6siEt3tXEhI4jipsVI7oFL6VtdI', 1, 39]
[2016-11-28 14:14:54] DEBUG [django.db.backends:89] (0.001) SELECT "auths_user"."password", "auths_user"."last_login", "auths_user"."is_superuser", "auths_user"."username", "auths_user"."first_name", "auths_user"."last_name", "auths_user"."email", "auths_user"."is_staff", "auths_user"."is_active", "auths_user"."date_joined", "auths_user"."id", "auths_user"."last_hierarchy_id", "auths_user"."last_module_id", "auths_user"."person_id", "auths_user"."updated_at", "auths_user"."registered_by" FROM "auths_user" WHERE "auths_user"."username" IS NULL; args=()
[2016-11-28 14:14:54] DEBUG [django.db.backends:89] (0.002) SELECT "oauth2_provider_accesstoken"."id", "oauth2_provider_accesstoken"."user_id", "oauth2_provider_accesstoken"."token", "oauth2_provider_accesstoken"."application_id", "oauth2_provider_accesstoken"."expires", "oauth2_provider_accesstoken"."scope", "auths_user"."password", "auths_user"."last_login", "auths_user"."is_superuser", "auths_user"."username", "auths_user"."first_name", "auths_user"."last_name", "auths_user"."email", "auths_user"."is_staff", "auths_user"."is_active", "auths_user"."date_joined", "auths_user"."id", "auths_user"."last_hierarchy_id", "auths_user"."last_module_id", "auths_user"."person_id", "auths_user"."updated_at", "auths_user"."registered_by", "oauth2_provider_application"."id", "oauth2_provider_application"."client_id", "oauth2_provider_application"."user_id", "oauth2_provider_application"."redirect_uris", "oauth2_provider_application"."client_type", "oauth2_provider_application"."authorization_grant_type", "oauth2_provider_application"."client_secret", "oauth2_provider_application"."name", "oauth2_provider_application"."skip_authorization" FROM "oauth2_provider_accesstoken" LEFT OUTER JOIN "auths_user" ON ("oauth2_provider_accesstoken"."user_id" = "auths_user"."id") INNER JOIN "oauth2_provider_application" ON ("oauth2_provider_accesstoken"."application_id" = "oauth2_provider_application"."id") WHERE "oauth2_provider_accesstoken"."token" = 'qmf9QfErONF5S17cVTqYwPYJ7evE0U'; args=('qmf9QfErONF5S17cVTqYwPYJ7evE0U',)
[2016-11-28 14:14:54] DEBUG [django.db.backends:89] (0.003) SELECT "auths_user"."password", "auths_user"."last_login", "auths_user"."is_superuser", "auths_user"."username", "auths_user"."first_name", "auths_user"."last_name", "auths_user"."email", "auths_user"."is_staff", "auths_user"."is_active", "auths_user"."date_joined", "auths_user"."id", "auths_user"."last_hierarchy_id", "auths_user"."last_module_id", "auths_user"."person_id", "auths_user"."updated_at", "auths_user"."registered_by" FROM "auths_user" WHERE "auths_user"."username" IS NULL; args=()
[2016-11-28 14:14:54] DEBUG [django.db.backends:89] (0.002) SELECT "oauth2_provider_accesstoken"."id", "oauth2_provider_accesstoken"."user_id", "oauth2_provider_accesstoken"."token", "oauth2_provider_accesstoken"."application_id", "oauth2_provider_accesstoken"."expires", "oauth2_provider_accesstoken"."scope", "auths_user"."password", "auths_user"."last_login", "auths_user"."is_superuser", "auths_user"."username", "auths_user"."first_name", "auths_user"."last_name", "auths_user"."email", "auths_user"."is_staff", "auths_user"."is_active", "auths_user"."date_joined", "auths_user"."id", "auths_user"."last_hierarchy_id", "auths_user"."last_module_id", "auths_user"."person_id", "auths_user"."updated_at", "auths_user"."registered_by", "oauth2_provider_application"."id", "oauth2_provider_application"."client_id", "oauth2_provider_application"."user_id", "oauth2_provider_application"."redirect_uris", "oauth2_provider_application"."client_type", "oauth2_provider_application"."authorization_grant_type", "oauth2_provider_application"."client_secret", "oauth2_provider_application"."name", "oauth2_provider_application"."skip_authorization" FROM "oauth2_provider_accesstoken" LEFT OUTER JOIN "auths_user" ON ("oauth2_provider_accesstoken"."user_id" = "auths_user"."id") INNER JOIN "oauth2_provider_application" ON ("oauth2_provider_accesstoken"."application_id" = "oauth2_provider_application"."id") WHERE "oauth2_provider_accesstoken"."token" = 'qmf9QfErONF5S17cVTqYwPYJ7evE0U'; args=('qmf9QfErONF5S17cVTqYwPYJ7evE0U',)
[2016-11-28 14:14:54] DEBUG [django.db.backends:89] (0.003) SELECT "auth_group"."id", "auth_group"."name" FROM "auth_group" INNER JOIN "auths_user_groups" ON ("auth_group"."id" = "auths_user_groups"."group_id") WHERE "auths_user_groups"."user_id" = '98c929be19fb4598b30233dd1ddbfcfd'; args=('98c929be19fb4598b30233dd1ddbfcfd',)
[2016-11-28 14:14:54] DEBUG [django.db.backends:89] (0.001) SELECT "auth_permission"."id", "auth_permission"."name", "auth_permission"."content_type_id", "auth_permission"."codename" FROM "auth_permission" INNER JOIN "auths_user_user_permissions" ON ("auth_permission"."id" = "auths_user_user_permissions"."permission_id") INNER JOIN "django_content_type" ON ("auth_permission"."content_type_id" = "django_content_type"."id") WHERE "auths_user_user_permissions"."user_id" = '98c929be19fb4598b30233dd1ddbfcfd' ORDER BY "django_content_type"."app_label" ASC, "django_content_type"."model" ASC, "auth_permission"."codename" ASC; args=('98c929be19fb4598b30233dd1ddbfcfd',)
[2016-11-28 14:14:54] DEBUG [django.db.backends:89] (0.000) SELECT "auths_menu"."id" FROM "auths_menu" WHERE ("auths_menu"."id" IS NOT NULL AND "auths_menu"."is_active" = 1 AND "auths_menu"."module" = 'BACKEND') ORDER BY "auths_menu"."pos" ASC; args=(True, 'BACKEND')
[2016-11-28 14:14:54] DEBUG [django.db.backends:89] (0.001) SELECT DISTINCT "auths_menu"."id", "auths_menu"."module", "auths_menu"."state", "auths_menu"."title", "auths_menu"."url", "auths_menu"."template_url", "auths_menu"."pos", "auths_menu"."icon", "auths_menu"."is_active", "auths_menu"."is_abstract", "auths_menu"."description", "auths_menu"."permission_id", "auths_menu"."parent_id", "auths_menu"."created_at", "auths_menu"."updated_at", "auths_menu"."registered_by" FROM "auths_menu" INNER JOIN "auths_menu" T2 ON ("auths_menu"."id" = T2."parent_id") WHERE ("auths_menu"."is_active" = 1 AND "auths_menu"."module" = 'BACKEND' AND T2."id" IN ('b479e020c80844478293cf7e1320fa5b', '89e73f9bfbde41d3aa4e612f2a2d2d00')) ORDER BY "auths_menu"."pos" ASC; args=(True, 'BACKEND', 'b479e020c80844478293cf7e1320fa5b', '89e73f9bfbde41d3aa4e612f2a2d2d00')
[2016-11-28 14:14:54] DEBUG [django.db.backends:89] (0.001) SELECT "auths_menu"."id", "auths_menu"."module", "auths_menu"."state", "auths_menu"."title", "auths_menu"."url", "auths_menu"."template_url", "auths_menu"."pos", "auths_menu"."icon", "auths_menu"."is_active", "auths_menu"."is_abstract", "auths_menu"."description", "auths_menu"."permission_id", "auths_menu"."parent_id", "auths_menu"."created_at", "auths_menu"."updated_at", "auths_menu"."registered_by" FROM "auths_menu" WHERE ("auths_menu"."id" IS NOT NULL AND "auths_menu"."is_active" = 1 AND "auths_menu"."module" = 'BACKEND' AND "auths_menu"."parent_id" = 'b479e020c80844478293cf7e1320fa5b') ORDER BY "auths_menu"."pos" ASC; args=(True, 'BACKEND', 'b479e020c80844478293cf7e1320fa5b')
[2016-11-28 14:14:54] DEBUG [django.db.backends:89] (0.001) SELECT "auths_menu"."id", "auths_menu"."module", "auths_menu"."state", "auths_menu"."title", "auths_menu"."url", "auths_menu"."template_url", "auths_menu"."pos", "auths_menu"."icon", "auths_menu"."is_active", "auths_menu"."is_abstract", "auths_menu"."description", "auths_menu"."permission_id", "auths_menu"."parent_id", "auths_menu"."created_at", "auths_menu"."updated_at", "auths_menu"."registered_by" FROM "auths_menu" WHERE "auths_menu"."id" = 'b479e020c80844478293cf7e1320fa5b'; args=('b479e020c80844478293cf7e1320fa5b',)
[2016-11-28 14:14:54] DEBUG [django.db.backends:89] (0.000) SELECT (1) AS "a" FROM "django_session" WHERE "django_session"."session_key" = 'fvuy9tf3szgkb18x701058ec0oefghs1' LIMIT 1; args=('fvuy9tf3szgkb18x701058ec0oefghs1',)
[2016-11-28 14:14:54] DEBUG [django.db.backends:89] (0.000) BEGIN; args=None
[2016-11-28 14:14:54] DEBUG [django.db.backends:89] (0.001) INSERT INTO "django_session" ("session_key", "session_data", "expire_date") SELECT 'fvuy9tf3szgkb18x701058ec0oefghs1', 'ZWMyMmE2MTA1MzM3NDcxZTRmYzk5YzliZTNiYjg2ZTZkMjFlMTc0NTp7Il9zZXNzaW9uX2V4cGlyeSI6MzB9', '2016-11-28 19:15:24.704080'; args=('fvuy9tf3szgkb18x701058ec0oefghs1', 'ZWMyMmE2MTA1MzM3NDcxZTRmYzk5YzliZTNiYjg2ZTZkMjFlMTc0NTp7Il9zZXNzaW9uX2V4cGlyeSI6MzB9', '2016-11-28 19:15:24.704080')
[2016-11-28 14:14:59] DEBUG [django.db.backends:89] (0.002) SELECT "auths_user"."password", "auths_user"."last_login", "auths_user"."is_superuser", "auths_user"."username", "auths_user"."first_name", "auths_user"."last_name", "auths_user"."email", "auths_user"."is_staff", "auths_user"."is_active", "auths_user"."date_joined", "auths_user"."id", "auths_user"."last_hierarchy_id", "auths_user"."last_module_id", "auths_user"."person_id", "auths_user"."updated_at", "auths_user"."registered_by" FROM "auths_user" WHERE "auths_user"."username" IS NULL; args=()
[2016-11-28 14:14:59] DEBUG [django.db.backends:89] (0.001) SELECT "oauth2_provider_accesstoken"."id", "oauth2_provider_accesstoken"."user_id", "oauth2_provider_accesstoken"."token", "oauth2_provider_accesstoken"."application_id", "oauth2_provider_accesstoken"."expires", "oauth2_provider_accesstoken"."scope", "auths_user"."password", "auths_user"."last_login", "auths_user"."is_superuser", "auths_user"."username", "auths_user"."first_name", "auths_user"."last_name", "auths_user"."email", "auths_user"."is_staff", "auths_user"."is_active", "auths_user"."date_joined", "auths_user"."id", "auths_user"."last_hierarchy_id", "auths_user"."last_module_id", "auths_user"."person_id", "auths_user"."updated_at", "auths_user"."registered_by", "oauth2_provider_application"."id", "oauth2_provider_application"."client_id", "oauth2_provider_application"."user_id", "oauth2_provider_application"."redirect_uris", "oauth2_provider_application"."client_type", "oauth2_provider_application"."authorization_grant_type", "oauth2_provider_application"."client_secret", "oauth2_provider_application"."name", "oauth2_provider_application"."skip_authorization" FROM "oauth2_provider_accesstoken" LEFT OUTER JOIN "auths_user" ON ("oauth2_provider_accesstoken"."user_id" = "auths_user"."id") INNER JOIN "oauth2_provider_application" ON ("oauth2_provider_accesstoken"."application_id" = "oauth2_provider_application"."id") WHERE "oauth2_provider_accesstoken"."token" = 'qmf9QfErONF5S17cVTqYwPYJ7evE0U'; args=('qmf9QfErONF5S17cVTqYwPYJ7evE0U',)
[2016-11-28 14:14:59] DEBUG [django.db.backends:89] (0.001) SELECT "catalogo_categoria"."id", "catalogo_categoria"."nombre", "catalogo_categoria"."codigo", "catalogo_categoria"."estado" FROM "catalogo_categoria" WHERE ("catalogo_categoria"."codigo" LIKE '%%' ESCAPE '\' OR "catalogo_categoria"."nombre" LIKE '%%' ESCAPE '\'); args=('%%', '%%')
[2016-11-28 14:15:00] DEBUG [django.db.backends:89] (0.002) SELECT "auths_user"."password", "auths_user"."last_login", "auths_user"."is_superuser", "auths_user"."username", "auths_user"."first_name", "auths_user"."last_name", "auths_user"."email", "auths_user"."is_staff", "auths_user"."is_active", "auths_user"."date_joined", "auths_user"."id", "auths_user"."last_hierarchy_id", "auths_user"."last_module_id", "auths_user"."person_id", "auths_user"."updated_at", "auths_user"."registered_by" FROM "auths_user" WHERE "auths_user"."username" IS NULL; args=()
[2016-11-28 14:15:00] DEBUG [django.db.backends:89] (0.001) SELECT "oauth2_provider_accesstoken"."id", "oauth2_provider_accesstoken"."user_id", "oauth2_provider_accesstoken"."token", "oauth2_provider_accesstoken"."application_id", "oauth2_provider_accesstoken"."expires", "oauth2_provider_accesstoken"."scope", "auths_user"."password", "auths_user"."last_login", "auths_user"."is_superuser", "auths_user"."username", "auths_user"."first_name", "auths_user"."last_name", "auths_user"."email", "auths_user"."is_staff", "auths_user"."is_active", "auths_user"."date_joined", "auths_user"."id", "auths_user"."last_hierarchy_id", "auths_user"."last_module_id", "auths_user"."person_id", "auths_user"."updated_at", "auths_user"."registered_by", "oauth2_provider_application"."id", "oauth2_provider_application"."client_id", "oauth2_provider_application"."user_id", "oauth2_provider_application"."redirect_uris", "oauth2_provider_application"."client_type", "oauth2_provider_application"."authorization_grant_type", "oauth2_provider_application"."client_secret", "oauth2_provider_application"."name", "oauth2_provider_application"."skip_authorization" FROM "oauth2_provider_accesstoken" LEFT OUTER JOIN "auths_user" ON ("oauth2_provider_accesstoken"."user_id" = "auths_user"."id") INNER JOIN "oauth2_provider_application" ON ("oauth2_provider_accesstoken"."application_id" = "oauth2_provider_application"."id") WHERE "oauth2_provider_accesstoken"."token" = 'qmf9QfErONF5S17cVTqYwPYJ7evE0U'; args=('qmf9QfErONF5S17cVTqYwPYJ7evE0U',)
[2016-11-28 14:15:00] DEBUG [django.db.backends:89] (0.012) SELECT COUNT(*) AS "__count" FROM "catalogo_autor"; args=()
[2016-11-28 14:15:00] DEBUG [django.db.backends:89] (0.000) SELECT "catalogo_autor"."id", "catalogo_autor"."nombre", "catalogo_autor"."direccion", "catalogo_autor"."fecha_nac", "catalogo_autor"."created_at", "catalogo_autor"."updated_at" FROM "catalogo_autor" LIMIT 5; args=()
[2016-11-28 14:15:02] DEBUG [django.db.backends:89] (0.002) SELECT "auths_user"."password", "auths_user"."last_login", "auths_user"."is_superuser", "auths_user"."username", "auths_user"."first_name", "auths_user"."last_name", "auths_user"."email", "auths_user"."is_staff", "auths_user"."is_active", "auths_user"."date_joined", "auths_user"."id", "auths_user"."last_hierarchy_id", "auths_user"."last_module_id", "auths_user"."person_id", "auths_user"."updated_at", "auths_user"."registered_by" FROM "auths_user" WHERE "auths_user"."username" IS NULL; args=()
[2016-11-28 14:15:02] DEBUG [django.db.backends:89] (0.001) SELECT "oauth2_provider_accesstoken"."id", "oauth2_provider_accesstoken"."user_id", "oauth2_provider_accesstoken"."token", "oauth2_provider_accesstoken"."application_id", "oauth2_provider_accesstoken"."expires", "oauth2_provider_accesstoken"."scope", "auths_user"."password", "auths_user"."last_login", "auths_user"."is_superuser", "auths_user"."username", "auths_user"."first_name", "auths_user"."last_name", "auths_user"."email", "auths_user"."is_staff", "auths_user"."is_active", "auths_user"."date_joined", "auths_user"."id", "auths_user"."last_hierarchy_id", "auths_user"."last_module_id", "auths_user"."person_id", "auths_user"."updated_at", "auths_user"."registered_by", "oauth2_provider_application"."id", "oauth2_provider_application"."client_id", "oauth2_provider_application"."user_id", "oauth2_provider_application"."redirect_uris", "oauth2_provider_application"."client_type", "oauth2_provider_application"."authorization_grant_type", "oauth2_provider_application"."client_secret", "oauth2_provider_application"."name", "oauth2_provider_application"."skip_authorization" FROM "oauth2_provider_accesstoken" LEFT OUTER JOIN "auths_user" ON ("oauth2_provider_accesstoken"."user_id" = "auths_user"."id") INNER JOIN "oauth2_provider_application" ON ("oauth2_provider_accesstoken"."application_id" = "oauth2_provider_application"."id") WHERE "oauth2_provider_accesstoken"."token" = 'qmf9QfErONF5S17cVTqYwPYJ7evE0U'; args=('qmf9QfErONF5S17cVTqYwPYJ7evE0U',)
[2016-11-28 14:15:02] DEBUG [django.db.backends:89] (0.000) SELECT "catalogo_categoria"."id", "catalogo_categoria"."nombre", "catalogo_categoria"."codigo", "catalogo_categoria"."estado" FROM "catalogo_categoria" WHERE ("catalogo_categoria"."codigo" LIKE '%%' ESCAPE '\' OR "catalogo_categoria"."nombre" LIKE '%%' ESCAPE '\'); args=('%%', '%%')
[2016-11-28 14:15:04] DEBUG [django.db.backends:89] (0.001) SELECT "auths_user"."password", "auths_user"."last_login", "auths_user"."is_superuser", "auths_user"."username", "auths_user"."first_name", "auths_user"."last_name", "auths_user"."email", "auths_user"."is_staff", "auths_user"."is_active", "auths_user"."date_joined", "auths_user"."id", "auths_user"."last_hierarchy_id", "auths_user"."last_module_id", "auths_user"."person_id", "auths_user"."updated_at", "auths_user"."registered_by" FROM "auths_user" WHERE "auths_user"."username" IS NULL; args=()
[2016-11-28 14:15:04] DEBUG [django.db.backends:89] (0.001) SELECT "oauth2_provider_accesstoken"."id", "oauth2_provider_accesstoken"."user_id", "oauth2_provider_accesstoken"."token", "oauth2_provider_accesstoken"."application_id", "oauth2_provider_accesstoken"."expires", "oauth2_provider_accesstoken"."scope", "auths_user"."password", "auths_user"."last_login", "auths_user"."is_superuser", "auths_user"."username", "auths_user"."first_name", "auths_user"."last_name", "auths_user"."email", "auths_user"."is_staff", "auths_user"."is_active", "auths_user"."date_joined", "auths_user"."id", "auths_user"."last_hierarchy_id", "auths_user"."last_module_id", "auths_user"."person_id", "auths_user"."updated_at", "auths_user"."registered_by", "oauth2_provider_application"."id", "oauth2_provider_application"."client_id", "oauth2_provider_application"."user_id", "oauth2_provider_application"."redirect_uris", "oauth2_provider_application"."client_type", "oauth2_provider_application"."authorization_grant_type", "oauth2_provider_application"."client_secret", "oauth2_provider_application"."name", "oauth2_provider_application"."skip_authorization" FROM "oauth2_provider_accesstoken" LEFT OUTER JOIN "auths_user" ON ("oauth2_provider_accesstoken"."user_id" = "auths_user"."id") INNER JOIN "oauth2_provider_application" ON ("oauth2_provider_accesstoken"."application_id" = "oauth2_provider_application"."id") WHERE "oauth2_provider_accesstoken"."token" = 'qmf9QfErONF5S17cVTqYwPYJ7evE0U'; args=('qmf9QfErONF5S17cVTqYwPYJ7evE0U',)
[2016-11-28 14:15:04] DEBUG [django.db.backends:89] (0.000) SELECT "eventos_evento"."id", "eventos_evento"."creacion", "eventos_evento"."modificacion", "eventos_evento"."nombre", "eventos_evento"."fecha", "eventos_evento"."hora" FROM "eventos_evento"; args=()
[2016-11-28 15:39:21] DEBUG [django.db.backends:89] (0.002) 
            SELECT name, type FROM sqlite_master
            WHERE type in ('table', 'view') AND NOT name='sqlite_sequence'
            ORDER BY name; args=None
[2016-11-28 15:39:22] DEBUG [django.db.backends:89] (0.000) SELECT "django_migrations"."app", "django_migrations"."name" FROM "django_migrations"; args=()
